/var/spool/parastation/jobs/10090951: line 17: /p/project1/cesmtst/patakchiyousefi1/CODES-MS3/FORECASTSEAD/bashenv-train: No such file or directory
2024-07-26 10:15:59.068181: I tensorflow/core/common_runtime/gpu/gpu_device.cc:1613] Created device /job:localhost/replica:0/task:0/device:GPU:0 with 38364 MB memory:  -> device: 0, name: NVIDIA A100-SXM4-40GB, pci bus id: 0000:03:00.0, compute capability: 8.0
2024-07-26 10:15:59.069946: I tensorflow/core/common_runtime/gpu/gpu_device.cc:1613] Created device /job:localhost/replica:0/task:0/device:GPU:1 with 38364 MB memory:  -> device: 1, name: NVIDIA A100-SXM4-40GB, pci bus id: 0000:44:00.0, compute capability: 8.0
2024-07-26 10:15:59.071575: I tensorflow/core/common_runtime/gpu/gpu_device.cc:1613] Created device /job:localhost/replica:0/task:0/device:GPU:2 with 38364 MB memory:  -> device: 2, name: NVIDIA A100-SXM4-40GB, pci bus id: 0000:84:00.0, compute capability: 8.0
2024-07-26 10:15:59.074212: I tensorflow/core/common_runtime/gpu/gpu_device.cc:1613] Created device /job:localhost/replica:0/task:0/device:GPU:3 with 38364 MB memory:  -> device: 3, name: NVIDIA A100-SXM4-40GB, pci bus id: 0000:c4:00.0, compute capability: 8.0
2024-07-26 10:15:59.736065: I tensorflow/core/common_runtime/gpu/gpu_device.cc:1613] Created device /job:localhost/replica:0/task:0/device:GPU:0 with 38364 MB memory:  -> device: 0, name: NVIDIA A100-SXM4-40GB, pci bus id: 0000:03:00.0, compute capability: 8.0
2024-07-26 10:15:59.737715: I tensorflow/core/common_runtime/gpu/gpu_device.cc:1613] Created device /job:localhost/replica:0/task:0/device:GPU:1 with 38364 MB memory:  -> device: 1, name: NVIDIA A100-SXM4-40GB, pci bus id: 0000:44:00.0, compute capability: 8.0
2024-07-26 10:15:59.739491: I tensorflow/core/common_runtime/gpu/gpu_device.cc:1613] Created device /job:localhost/replica:0/task:0/device:GPU:2 with 38364 MB memory:  -> device: 2, name: NVIDIA A100-SXM4-40GB, pci bus id: 0000:84:00.0, compute capability: 8.0
2024-07-26 10:15:59.741143: I tensorflow/core/common_runtime/gpu/gpu_device.cc:1613] Created device /job:localhost/replica:0/task:0/device:GPU:3 with 38364 MB memory:  -> device: 3, name: NVIDIA A100-SXM4-40GB, pci bus id: 0000:c4:00.0, compute capability: 8.0
2024-07-26 10:16:00.195913: I tensorflow/core/common_runtime/gpu/gpu_device.cc:1613] Created device /job:localhost/replica:0/task:0/device:GPU:0 with 38364 MB memory:  -> device: 0, name: NVIDIA A100-SXM4-40GB, pci bus id: 0000:03:00.0, compute capability: 8.0
2024-07-26 10:16:00.198743: I tensorflow/core/common_runtime/gpu/gpu_device.cc:1613] Created device /job:localhost/replica:0/task:0/device:GPU:1 with 38364 MB memory:  -> device: 1, name: NVIDIA A100-SXM4-40GB, pci bus id: 0000:44:00.0, compute capability: 8.0
2024-07-26 10:16:00.203182: I tensorflow/core/common_runtime/gpu/gpu_device.cc:1613] Created device /job:localhost/replica:0/task:0/device:GPU:2 with 38364 MB memory:  -> device: 2, name: NVIDIA A100-SXM4-40GB, pci bus id: 0000:84:00.0, compute capability: 8.0
2024-07-26 10:16:00.205839: I tensorflow/core/common_runtime/gpu/gpu_device.cc:1613] Created device /job:localhost/replica:0/task:0/device:GPU:3 with 38364 MB memory:  -> device: 3, name: NVIDIA A100-SXM4-40GB, pci bus id: 0000:c4:00.0, compute capability: 8.0
2024-07-26 10:16:00.939704: I tensorflow/core/common_runtime/gpu/gpu_device.cc:1613] Created device /job:localhost/replica:0/task:0/device:GPU:0 with 38364 MB memory:  -> device: 0, name: NVIDIA A100-SXM4-40GB, pci bus id: 0000:03:00.0, compute capability: 8.0
2024-07-26 10:16:00.942335: I tensorflow/core/common_runtime/gpu/gpu_device.cc:1613] Created device /job:localhost/replica:0/task:0/device:GPU:1 with 38364 MB memory:  -> device: 1, name: NVIDIA A100-SXM4-40GB, pci bus id: 0000:44:00.0, compute capability: 8.0
2024-07-26 10:16:00.943802: I tensorflow/core/common_runtime/gpu/gpu_device.cc:1613] Created device /job:localhost/replica:0/task:0/device:GPU:2 with 38364 MB memory:  -> device: 2, name: NVIDIA A100-SXM4-40GB, pci bus id: 0000:84:00.0, compute capability: 8.0
2024-07-26 10:16:00.945443: I tensorflow/core/common_runtime/gpu/gpu_device.cc:1613] Created device /job:localhost/replica:0/task:0/device:GPU:3 with 38364 MB memory:  -> device: 3, name: NVIDIA A100-SXM4-40GB, pci bus id: 0000:c4:00.0, compute capability: 8.0
2024-07-26 10:16:01.537402: I tensorflow/core/common_runtime/gpu/gpu_device.cc:1613] Created device /job:localhost/replica:0/task:0/device:GPU:0 with 38364 MB memory:  -> device: 0, name: NVIDIA A100-SXM4-40GB, pci bus id: 0000:03:00.0, compute capability: 8.0
2024-07-26 10:16:01.539274: I tensorflow/core/common_runtime/gpu/gpu_device.cc:1613] Created device /job:localhost/replica:0/task:0/device:GPU:1 with 38364 MB memory:  -> device: 1, name: NVIDIA A100-SXM4-40GB, pci bus id: 0000:44:00.0, compute capability: 8.0
2024-07-26 10:16:01.540777: I tensorflow/core/common_runtime/gpu/gpu_device.cc:1613] Created device /job:localhost/replica:0/task:0/device:GPU:2 with 38364 MB memory:  -> device: 2, name: NVIDIA A100-SXM4-40GB, pci bus id: 0000:84:00.0, compute capability: 8.0
2024-07-26 10:16:01.542543: I tensorflow/core/common_runtime/gpu/gpu_device.cc:1613] Created device /job:localhost/replica:0/task:0/device:GPU:3 with 38364 MB memory:  -> device: 3, name: NVIDIA A100-SXM4-40GB, pci bus id: 0000:c4:00.0, compute capability: 8.0
Traceback (most recent call last):
  File "/p/project1/cesmtst/patakchiyousefi1/CODES-MS3/FORECASTLEAD/DL_TRAIN.py", line 97, in <module>
    model = func_train.UNET(xpixels, ypixels, n_channels, Filters, dropout, unet_type)
  File "/p/project1/cesmtst/patakchiyousefi1/CODES-MS3/FORECASTLEAD/func_train.py", line 201, in UNET
    p4 = tf.keras.layers.MaxPooling2D((2, 2))(c4)
  File "/p/software/juwelsbooster/stages/2023/software/TensorFlow/2.11.0-foss-2022a-CUDA-11.7/lib/python3.10/site-packages/keras/utils/traceback_utils.py", line 70, in error_handler
    raise e.with_traceback(filtered_tb) from None
  File "/p/software/juwelsbooster/stages/2023/software/TensorFlow/2.11.0-foss-2022a-CUDA-11.7/lib/python3.10/site-packages/tensorflow/python/framework/ops.py", line 1967, in _create_c_op
    raise ValueError(e.message)
ValueError: Exception encountered when calling layer "max_pooling2d_3" (type MaxPooling2D).

Negative dimension size caused by subtracting 2 from 1 for '{{node max_pooling2d_3/MaxPool}} = MaxPool[T=DT_FLOAT, data_format="NHWC", explicit_paddings=[], ksize=[1, 2, 2, 1], padding="VALID", strides=[1, 2, 2, 1]](Placeholder)' with input shapes: [?,1,3,512].

Call arguments received by layer "max_pooling2d_3" (type MaxPooling2D):
  • inputs=tf.Tensor(shape=(None, 1, 3, 512), dtype=float32)
2024-07-26 10:16:01.976394: I tensorflow/core/common_runtime/gpu/gpu_device.cc:1613] Created device /job:localhost/replica:0/task:0/device:GPU:0 with 38364 MB memory:  -> device: 0, name: NVIDIA A100-SXM4-40GB, pci bus id: 0000:03:00.0, compute capability: 8.0
2024-07-26 10:16:01.978087: I tensorflow/core/common_runtime/gpu/gpu_device.cc:1613] Created device /job:localhost/replica:0/task:0/device:GPU:1 with 38364 MB memory:  -> device: 1, name: NVIDIA A100-SXM4-40GB, pci bus id: 0000:44:00.0, compute capability: 8.0
2024-07-26 10:16:01.979699: I tensorflow/core/common_runtime/gpu/gpu_device.cc:1613] Created device /job:localhost/replica:0/task:0/device:GPU:2 with 38364 MB memory:  -> device: 2, name: NVIDIA A100-SXM4-40GB, pci bus id: 0000:84:00.0, compute capability: 8.0
2024-07-26 10:16:01.982945: I tensorflow/core/common_runtime/gpu/gpu_device.cc:1613] Created device /job:localhost/replica:0/task:0/device:GPU:3 with 38364 MB memory:  -> device: 3, name: NVIDIA A100-SXM4-40GB, pci bus id: 0000:c4:00.0, compute capability: 8.0
Traceback (most recent call last):
  File "/p/project1/cesmtst/patakchiyousefi1/CODES-MS3/FORECASTLEAD/DL_TRAIN.py", line 97, in <module>
    model = func_train.UNET(xpixels, ypixels, n_channels, Filters, dropout, unet_type)
  File "/p/project1/cesmtst/patakchiyousefi1/CODES-MS3/FORECASTLEAD/func_train.py", line 201, in UNET
    p4 = tf.keras.layers.MaxPooling2D((2, 2))(c4)
  File "/p/software/juwelsbooster/stages/2023/software/TensorFlow/2.11.0-foss-2022a-CUDA-11.7/lib/python3.10/site-packages/keras/utils/traceback_utils.py", line 70, in error_handler
    raise e.with_traceback(filtered_tb) from None
  File "/p/software/juwelsbooster/stages/2023/software/TensorFlow/2.11.0-foss-2022a-CUDA-11.7/lib/python3.10/site-packages/tensorflow/python/framework/ops.py", line 1967, in _create_c_op
    raise ValueError(e.message)
ValueError: Exception encountered when calling layer "max_pooling2d_3" (type MaxPooling2D).

Negative dimension size caused by subtracting 2 from 1 for '{{node max_pooling2d_3/MaxPool}} = MaxPool[T=DT_FLOAT, data_format="NHWC", explicit_paddings=[], ksize=[1, 2, 2, 1], padding="VALID", strides=[1, 2, 2, 1]](Placeholder)' with input shapes: [?,1,3,512].

Call arguments received by layer "max_pooling2d_3" (type MaxPooling2D):
  • inputs=tf.Tensor(shape=(None, 1, 3, 512), dtype=float32)
2024-07-26 10:16:02.799636: I tensorflow/core/common_runtime/gpu/gpu_device.cc:1613] Created device /job:localhost/replica:0/task:0/device:GPU:0 with 38364 MB memory:  -> device: 0, name: NVIDIA A100-SXM4-40GB, pci bus id: 0000:03:00.0, compute capability: 8.0
2024-07-26 10:16:02.801397: I tensorflow/core/common_runtime/gpu/gpu_device.cc:1613] Created device /job:localhost/replica:0/task:0/device:GPU:1 with 38364 MB memory:  -> device: 1, name: NVIDIA A100-SXM4-40GB, pci bus id: 0000:44:00.0, compute capability: 8.0
2024-07-26 10:16:02.802929: I tensorflow/core/common_runtime/gpu/gpu_device.cc:1613] Created device /job:localhost/replica:0/task:0/device:GPU:2 with 38364 MB memory:  -> device: 2, name: NVIDIA A100-SXM4-40GB, pci bus id: 0000:84:00.0, compute capability: 8.0
2024-07-26 10:16:02.804458: I tensorflow/core/common_runtime/gpu/gpu_device.cc:1613] Created device /job:localhost/replica:0/task:0/device:GPU:3 with 38364 MB memory:  -> device: 3, name: NVIDIA A100-SXM4-40GB, pci bus id: 0000:c4:00.0, compute capability: 8.0
Traceback (most recent call last):
  File "/p/project1/cesmtst/patakchiyousefi1/CODES-MS3/FORECASTLEAD/DL_TRAIN.py", line 97, in <module>
    model = func_train.UNET(xpixels, ypixels, n_channels, Filters, dropout, unet_type)
  File "/p/project1/cesmtst/patakchiyousefi1/CODES-MS3/FORECASTLEAD/func_train.py", line 201, in UNET
    p4 = tf.keras.layers.MaxPooling2D((2, 2))(c4)
  File "/p/software/juwelsbooster/stages/2023/software/TensorFlow/2.11.0-foss-2022a-CUDA-11.7/lib/python3.10/site-packages/keras/utils/traceback_utils.py", line 70, in error_handler
    raise e.with_traceback(filtered_tb) from None
  File "/p/software/juwelsbooster/stages/2023/software/TensorFlow/2.11.0-foss-2022a-CUDA-11.7/lib/python3.10/site-packages/tensorflow/python/framework/ops.py", line 1967, in _create_c_op
    raise ValueError(e.message)
ValueError: Exception encountered when calling layer "max_pooling2d_3" (type MaxPooling2D).

Negative dimension size caused by subtracting 2 from 1 for '{{node max_pooling2d_3/MaxPool}} = MaxPool[T=DT_FLOAT, data_format="NHWC", explicit_paddings=[], ksize=[1, 2, 2, 1], padding="VALID", strides=[1, 2, 2, 1]](Placeholder)' with input shapes: [?,1,3,512].

Call arguments received by layer "max_pooling2d_3" (type MaxPooling2D):
  • inputs=tf.Tensor(shape=(None, 1, 3, 512), dtype=float32)
srun: error: jwb0320: task 0: Exited with exit code 1
srun: Job 10090951 step creation temporarily disabled, retrying (Requested nodes are busy)
srun: Job 10090951 step creation temporarily disabled, retrying (Requested nodes are busy)
srun: Step created for job 10090951
Traceback (most recent call last):
  File "/p/project1/cesmtst/patakchiyousefi1/CODES-MS3/FORECASTLEAD/DL_TRAIN.py", line 97, in <module>
    model = func_train.UNET(xpixels, ypixels, n_channels, Filters, dropout, unet_type)
  File "/p/project1/cesmtst/patakchiyousefi1/CODES-MS3/FORECASTLEAD/func_train.py", line 201, in UNET
    p4 = tf.keras.layers.MaxPooling2D((2, 2))(c4)
  File "/p/software/juwelsbooster/stages/2023/software/TensorFlow/2.11.0-foss-2022a-CUDA-11.7/lib/python3.10/site-packages/keras/utils/traceback_utils.py", line 70, in error_handler
    raise e.with_traceback(filtered_tb) from None
  File "/p/software/juwelsbooster/stages/2023/software/TensorFlow/2.11.0-foss-2022a-CUDA-11.7/lib/python3.10/site-packages/tensorflow/python/framework/ops.py", line 1967, in _create_c_op
    raise ValueError(e.message)
ValueError: Exception encountered when calling layer "max_pooling2d_3" (type MaxPooling2D).

Negative dimension size caused by subtracting 2 from 1 for '{{node max_pooling2d_3/MaxPool}} = MaxPool[T=DT_FLOAT, data_format="NHWC", explicit_paddings=[], ksize=[1, 2, 2, 1], padding="VALID", strides=[1, 2, 2, 1]](Placeholder)' with input shapes: [?,1,3,512].

Call arguments received by layer "max_pooling2d_3" (type MaxPooling2D):
  • inputs=tf.Tensor(shape=(None, 1, 3, 512), dtype=float32)
2024-07-26 10:16:03.820763: I tensorflow/core/common_runtime/gpu/gpu_device.cc:1613] Created device /job:localhost/replica:0/task:0/device:GPU:0 with 38364 MB memory:  -> device: 0, name: NVIDIA A100-SXM4-40GB, pci bus id: 0000:03:00.0, compute capability: 8.0
2024-07-26 10:16:03.822472: I tensorflow/core/common_runtime/gpu/gpu_device.cc:1613] Created device /job:localhost/replica:0/task:0/device:GPU:1 with 38364 MB memory:  -> device: 1, name: NVIDIA A100-SXM4-40GB, pci bus id: 0000:44:00.0, compute capability: 8.0
2024-07-26 10:16:03.823977: I tensorflow/core/common_runtime/gpu/gpu_device.cc:1613] Created device /job:localhost/replica:0/task:0/device:GPU:2 with 38364 MB memory:  -> device: 2, name: NVIDIA A100-SXM4-40GB, pci bus id: 0000:84:00.0, compute capability: 8.0
2024-07-26 10:16:03.825609: I tensorflow/core/common_runtime/gpu/gpu_device.cc:1613] Created device /job:localhost/replica:0/task:0/device:GPU:3 with 38364 MB memory:  -> device: 3, name: NVIDIA A100-SXM4-40GB, pci bus id: 0000:c4:00.0, compute capability: 8.0
2024-07-26 10:16:04.199183: I tensorflow/core/common_runtime/gpu/gpu_device.cc:1613] Created device /job:localhost/replica:0/task:0/device:GPU:0 with 38364 MB memory:  -> device: 0, name: NVIDIA A100-SXM4-40GB, pci bus id: 0000:03:00.0, compute capability: 8.0
2024-07-26 10:16:04.201918: I tensorflow/core/common_runtime/gpu/gpu_device.cc:1613] Created device /job:localhost/replica:0/task:0/device:GPU:1 with 38364 MB memory:  -> device: 1, name: NVIDIA A100-SXM4-40GB, pci bus id: 0000:44:00.0, compute capability: 8.0
2024-07-26 10:16:04.203406: I tensorflow/core/common_runtime/gpu/gpu_device.cc:1613] Created device /job:localhost/replica:0/task:0/device:GPU:2 with 38364 MB memory:  -> device: 2, name: NVIDIA A100-SXM4-40GB, pci bus id: 0000:84:00.0, compute capability: 8.0
2024-07-26 10:16:04.206963: I tensorflow/core/common_runtime/gpu/gpu_device.cc:1613] Created device /job:localhost/replica:0/task:0/device:GPU:3 with 38364 MB memory:  -> device: 3, name: NVIDIA A100-SXM4-40GB, pci bus id: 0000:c4:00.0, compute capability: 8.0
Traceback (most recent call last):
  File "/p/project1/cesmtst/patakchiyousefi1/CODES-MS3/FORECASTLEAD/DL_TRAIN.py", line 97, in <module>
    model = func_train.UNET(xpixels, ypixels, n_channels, Filters, dropout, unet_type)
  File "/p/project1/cesmtst/patakchiyousefi1/CODES-MS3/FORECASTLEAD/func_train.py", line 201, in UNET
    p4 = tf.keras.layers.MaxPooling2D((2, 2))(c4)
  File "/p/software/juwelsbooster/stages/2023/software/TensorFlow/2.11.0-foss-2022a-CUDA-11.7/lib/python3.10/site-packages/keras/utils/traceback_utils.py", line 70, in error_handler
    raise e.with_traceback(filtered_tb) from None
  File "/p/software/juwelsbooster/stages/2023/software/TensorFlow/2.11.0-foss-2022a-CUDA-11.7/lib/python3.10/site-packages/tensorflow/python/framework/ops.py", line 1967, in _create_c_op
    raise ValueError(e.message)
ValueError: Exception encountered when calling layer "max_pooling2d_3" (type MaxPooling2D).

Negative dimension size caused by subtracting 2 from 1 for '{{node max_pooling2d_3/MaxPool}} = MaxPool[T=DT_FLOAT, data_format="NHWC", explicit_paddings=[], ksize=[1, 2, 2, 1], padding="VALID", strides=[1, 2, 2, 1]](Placeholder)' with input shapes: [?,1,3,512].

Call arguments received by layer "max_pooling2d_3" (type MaxPooling2D):
  • inputs=tf.Tensor(shape=(None, 1, 3, 512), dtype=float32)
srun: error: jwb0324: task 0: Exited with exit code 1
srun: Job 10090951 step creation temporarily disabled, retrying (Requested nodes are busy)
srun: Job 10090951 step creation still disabled, retrying (Requested nodes are busy)
srun: Job 10090951 step creation temporarily disabled, retrying (Requested nodes are busy)
srun: Step created for job 10090951
srun: error: jwb0344: task 0: Exited with exit code 1
srun: Job 10090951 step creation still disabled, retrying (Requested nodes are busy)
srun: Job 10090951 step creation still disabled, retrying (Requested nodes are busy)
srun: Step created for job 10090951
Traceback (most recent call last):
  File "/p/project1/cesmtst/patakchiyousefi1/CODES-MS3/FORECASTLEAD/DL_TRAIN.py", line 97, in <module>
    model = func_train.UNET(xpixels, ypixels, n_channels, Filters, dropout, unet_type)
  File "/p/project1/cesmtst/patakchiyousefi1/CODES-MS3/FORECASTLEAD/func_train.py", line 201, in UNET
    p4 = tf.keras.layers.MaxPooling2D((2, 2))(c4)
  File "/p/software/juwelsbooster/stages/2023/software/TensorFlow/2.11.0-foss-2022a-CUDA-11.7/lib/python3.10/site-packages/keras/utils/traceback_utils.py", line 70, in error_handler
    raise e.with_traceback(filtered_tb) from None
  File "/p/software/juwelsbooster/stages/2023/software/TensorFlow/2.11.0-foss-2022a-CUDA-11.7/lib/python3.10/site-packages/tensorflow/python/framework/ops.py", line 1967, in _create_c_op
    raise ValueError(e.message)
ValueError: Exception encountered when calling layer "max_pooling2d_3" (type MaxPooling2D).

Negative dimension size caused by subtracting 2 from 1 for '{{node max_pooling2d_3/MaxPool}} = MaxPool[T=DT_FLOAT, data_format="NHWC", explicit_paddings=[], ksize=[1, 2, 2, 1], padding="VALID", strides=[1, 2, 2, 1]](Placeholder)' with input shapes: [?,1,3,512].

Call arguments received by layer "max_pooling2d_3" (type MaxPooling2D):
  • inputs=tf.Tensor(shape=(None, 1, 3, 512), dtype=float32)
2024-07-26 10:16:05.059198: I tensorflow/core/common_runtime/gpu/gpu_device.cc:1613] Created device /job:localhost/replica:0/task:0/device:GPU:0 with 38364 MB memory:  -> device: 0, name: NVIDIA A100-SXM4-40GB, pci bus id: 0000:03:00.0, compute capability: 8.0
2024-07-26 10:16:05.062064: I tensorflow/core/common_runtime/gpu/gpu_device.cc:1613] Created device /job:localhost/replica:0/task:0/device:GPU:1 with 38364 MB memory:  -> device: 1, name: NVIDIA A100-SXM4-40GB, pci bus id: 0000:44:00.0, compute capability: 8.0
2024-07-26 10:16:05.063585: I tensorflow/core/common_runtime/gpu/gpu_device.cc:1613] Created device /job:localhost/replica:0/task:0/device:GPU:2 with 38364 MB memory:  -> device: 2, name: NVIDIA A100-SXM4-40GB, pci bus id: 0000:84:00.0, compute capability: 8.0
2024-07-26 10:16:05.065054: I tensorflow/core/common_runtime/gpu/gpu_device.cc:1613] Created device /job:localhost/replica:0/task:0/device:GPU:3 with 38364 MB memory:  -> device: 3, name: NVIDIA A100-SXM4-40GB, pci bus id: 0000:c4:00.0, compute capability: 8.0
srun: error: jwb0346: task 0: Exited with exit code 1
srun: Job 10090951 step creation still disabled, retrying (Requested nodes are busy)
srun: Job 10090951 step creation temporarily disabled, retrying (Requested nodes are busy)
srun: Job 10090951 step creation temporarily disabled, retrying (Requested nodes are busy)
srun: Step created for job 10090951
Traceback (most recent call last):
  File "/p/project1/cesmtst/patakchiyousefi1/CODES-MS3/FORECASTLEAD/DL_TRAIN.py", line 97, in <module>
    model = func_train.UNET(xpixels, ypixels, n_channels, Filters, dropout, unet_type)
  File "/p/project1/cesmtst/patakchiyousefi1/CODES-MS3/FORECASTLEAD/func_train.py", line 201, in UNET
    p4 = tf.keras.layers.MaxPooling2D((2, 2))(c4)
  File "/p/software/juwelsbooster/stages/2023/software/TensorFlow/2.11.0-foss-2022a-CUDA-11.7/lib/python3.10/site-packages/keras/utils/traceback_utils.py", line 70, in error_handler
    raise e.with_traceback(filtered_tb) from None
  File "/p/software/juwelsbooster/stages/2023/software/TensorFlow/2.11.0-foss-2022a-CUDA-11.7/lib/python3.10/site-packages/tensorflow/python/framework/ops.py", line 1967, in _create_c_op
    raise ValueError(e.message)
ValueError: Exception encountered when calling layer "max_pooling2d_3" (type MaxPooling2D).

Negative dimension size caused by subtracting 2 from 1 for '{{node max_pooling2d_3/MaxPool}} = MaxPool[T=DT_FLOAT, data_format="NHWC", explicit_paddings=[], ksize=[1, 2, 2, 1], padding="VALID", strides=[1, 2, 2, 1]](Placeholder)' with input shapes: [?,1,3,512].

Call arguments received by layer "max_pooling2d_3" (type MaxPooling2D):
  • inputs=tf.Tensor(shape=(None, 1, 3, 512), dtype=float32)
2024-07-26 10:16:05.658557: I tensorflow/core/common_runtime/gpu/gpu_device.cc:1613] Created device /job:localhost/replica:0/task:0/device:GPU:0 with 38364 MB memory:  -> device: 0, name: NVIDIA A100-SXM4-40GB, pci bus id: 0000:03:00.0, compute capability: 8.0
2024-07-26 10:16:05.661645: I tensorflow/core/common_runtime/gpu/gpu_device.cc:1613] Created device /job:localhost/replica:0/task:0/device:GPU:1 with 38364 MB memory:  -> device: 1, name: NVIDIA A100-SXM4-40GB, pci bus id: 0000:44:00.0, compute capability: 8.0
2024-07-26 10:16:05.663283: I tensorflow/core/common_runtime/gpu/gpu_device.cc:1613] Created device /job:localhost/replica:0/task:0/device:GPU:2 with 38364 MB memory:  -> device: 2, name: NVIDIA A100-SXM4-40GB, pci bus id: 0000:84:00.0, compute capability: 8.0
2024-07-26 10:16:05.664927: I tensorflow/core/common_runtime/gpu/gpu_device.cc:1613] Created device /job:localhost/replica:0/task:0/device:GPU:3 with 38364 MB memory:  -> device: 3, name: NVIDIA A100-SXM4-40GB, pci bus id: 0000:c4:00.0, compute capability: 8.0
srun: error: jwb0348: task 0: Exited with exit code 1
srun: Job 10090951 step creation still disabled, retrying (Requested nodes are busy)
srun: Job 10090951 step creation temporarily disabled, retrying (Requested nodes are busy)
srun: Job 10090951 step creation still disabled, retrying (Requested nodes are busy)
srun: Step created for job 10090951
srun: error: jwb0349: task 0: Exited with exit code 1
srun: Job 10090951 step creation still disabled, retrying (Requested nodes are busy)
srun: Job 10090951 step creation still disabled, retrying (Requested nodes are busy)
srun: Step created for job 10090951
Traceback (most recent call last):
  File "/p/project1/cesmtst/patakchiyousefi1/CODES-MS3/FORECASTLEAD/DL_TRAIN.py", line 97, in <module>
    model = func_train.UNET(xpixels, ypixels, n_channels, Filters, dropout, unet_type)
  File "/p/project1/cesmtst/patakchiyousefi1/CODES-MS3/FORECASTLEAD/func_train.py", line 201, in UNET
    p4 = tf.keras.layers.MaxPooling2D((2, 2))(c4)
  File "/p/software/juwelsbooster/stages/2023/software/TensorFlow/2.11.0-foss-2022a-CUDA-11.7/lib/python3.10/site-packages/keras/utils/traceback_utils.py", line 70, in error_handler
    raise e.with_traceback(filtered_tb) from None
  File "/p/software/juwelsbooster/stages/2023/software/TensorFlow/2.11.0-foss-2022a-CUDA-11.7/lib/python3.10/site-packages/tensorflow/python/framework/ops.py", line 1967, in _create_c_op
    raise ValueError(e.message)
ValueError: Exception encountered when calling layer "max_pooling2d_3" (type MaxPooling2D).

Negative dimension size caused by subtracting 2 from 1 for '{{node max_pooling2d_3/MaxPool}} = MaxPool[T=DT_FLOAT, data_format="NHWC", explicit_paddings=[], ksize=[1, 2, 2, 1], padding="VALID", strides=[1, 2, 2, 1]](Placeholder)' with input shapes: [?,1,3,512].

Call arguments received by layer "max_pooling2d_3" (type MaxPooling2D):
  • inputs=tf.Tensor(shape=(None, 1, 3, 512), dtype=float32)
Traceback (most recent call last):
  File "/p/project1/cesmtst/patakchiyousefi1/CODES-MS3/FORECASTLEAD/DL_TRAIN.py", line 97, in <module>
    model = func_train.UNET(xpixels, ypixels, n_channels, Filters, dropout, unet_type)
  File "/p/project1/cesmtst/patakchiyousefi1/CODES-MS3/FORECASTLEAD/func_train.py", line 201, in UNET
    p4 = tf.keras.layers.MaxPooling2D((2, 2))(c4)
  File "/p/software/juwelsbooster/stages/2023/software/TensorFlow/2.11.0-foss-2022a-CUDA-11.7/lib/python3.10/site-packages/keras/utils/traceback_utils.py", line 70, in error_handler
    raise e.with_traceback(filtered_tb) from None
  File "/p/software/juwelsbooster/stages/2023/software/TensorFlow/2.11.0-foss-2022a-CUDA-11.7/lib/python3.10/site-packages/tensorflow/python/framework/ops.py", line 1967, in _create_c_op
    raise ValueError(e.message)
ValueError: Exception encountered when calling layer "max_pooling2d_3" (type MaxPooling2D).

Negative dimension size caused by subtracting 2 from 1 for '{{node max_pooling2d_3/MaxPool}} = MaxPool[T=DT_FLOAT, data_format="NHWC", explicit_paddings=[], ksize=[1, 2, 2, 1], padding="VALID", strides=[1, 2, 2, 1]](Placeholder)' with input shapes: [?,1,3,512].

Call arguments received by layer "max_pooling2d_3" (type MaxPooling2D):
  • inputs=tf.Tensor(shape=(None, 1, 3, 512), dtype=float32)
srun: error: jwb0094: task 0: Exited with exit code 1
srun: Job 10090951 step creation still disabled, retrying (Requested nodes are busy)
srun: Job 10090951 step creation temporarily disabled, retrying (Requested nodes are busy)
srun: Job 10090951 step creation temporarily disabled, retrying (Requested nodes are busy)
srun: Step created for job 10090951
Traceback (most recent call last):
  File "/p/project1/cesmtst/patakchiyousefi1/CODES-MS3/FORECASTLEAD/DL_TRAIN.py", line 97, in <module>
    model = func_train.UNET(xpixels, ypixels, n_channels, Filters, dropout, unet_type)
  File "/p/project1/cesmtst/patakchiyousefi1/CODES-MS3/FORECASTLEAD/func_train.py", line 201, in UNET
    p4 = tf.keras.layers.MaxPooling2D((2, 2))(c4)
  File "/p/software/juwelsbooster/stages/2023/software/TensorFlow/2.11.0-foss-2022a-CUDA-11.7/lib/python3.10/site-packages/keras/utils/traceback_utils.py", line 70, in error_handler
    raise e.with_traceback(filtered_tb) from None
  File "/p/software/juwelsbooster/stages/2023/software/TensorFlow/2.11.0-foss-2022a-CUDA-11.7/lib/python3.10/site-packages/tensorflow/python/framework/ops.py", line 1967, in _create_c_op
    raise ValueError(e.message)
ValueError: Exception encountered when calling layer "max_pooling2d_3" (type MaxPooling2D).

Negative dimension size caused by subtracting 2 from 1 for '{{node max_pooling2d_3/MaxPool}} = MaxPool[T=DT_FLOAT, data_format="NHWC", explicit_paddings=[], ksize=[1, 2, 2, 1], padding="VALID", strides=[1, 2, 2, 1]](Placeholder)' with input shapes: [?,1,3,512].

Call arguments received by layer "max_pooling2d_3" (type MaxPooling2D):
  • inputs=tf.Tensor(shape=(None, 1, 3, 512), dtype=float32)
Traceback (most recent call last):
  File "/p/project1/cesmtst/patakchiyousefi1/CODES-MS3/FORECASTLEAD/DL_TRAIN.py", line 97, in <module>
    model = func_train.UNET(xpixels, ypixels, n_channels, Filters, dropout, unet_type)
  File "/p/project1/cesmtst/patakchiyousefi1/CODES-MS3/FORECASTLEAD/func_train.py", line 201, in UNET
    p4 = tf.keras.layers.MaxPooling2D((2, 2))(c4)
  File "/p/software/juwelsbooster/stages/2023/software/TensorFlow/2.11.0-foss-2022a-CUDA-11.7/lib/python3.10/site-packages/keras/utils/traceback_utils.py", line 70, in error_handler
    raise e.with_traceback(filtered_tb) from None
  File "/p/software/juwelsbooster/stages/2023/software/TensorFlow/2.11.0-foss-2022a-CUDA-11.7/lib/python3.10/site-packages/tensorflow/python/framework/ops.py", line 1967, in _create_c_op
    raise ValueError(e.message)
ValueError: Exception encountered when calling layer "max_pooling2d_3" (type MaxPooling2D).

Negative dimension size caused by subtracting 2 from 1 for '{{node max_pooling2d_3/MaxPool}} = MaxPool[T=DT_FLOAT, data_format="NHWC", explicit_paddings=[], ksize=[1, 2, 2, 1], padding="VALID", strides=[1, 2, 2, 1]](Placeholder)' with input shapes: [?,1,3,512].

Call arguments received by layer "max_pooling2d_3" (type MaxPooling2D):
  • inputs=tf.Tensor(shape=(None, 1, 3, 512), dtype=float32)
srun: error: jwb0095: task 0: Exited with exit code 1
srun: Job 10090951 step creation still disabled, retrying (Requested nodes are busy)
srun: Job 10090951 step creation temporarily disabled, retrying (Requested nodes are busy)
srun: Job 10090951 step creation temporarily disabled, retrying (Requested nodes are busy)
srun: Job 10090951 step creation still disabled, retrying (Requested nodes are busy)
srun: Step created for job 10090951
2024-07-26 10:16:08.817912: I tensorflow/core/common_runtime/gpu/gpu_device.cc:1613] Created device /job:localhost/replica:0/task:0/device:GPU:0 with 38364 MB memory:  -> device: 0, name: NVIDIA A100-SXM4-40GB, pci bus id: 0000:03:00.0, compute capability: 8.0
srun: error: jwb0130: task 0: Exited with exit code 1
srun: Job 10090951 step creation still disabled, retrying (Requested nodes are busy)
srun: Job 10090951 step creation still disabled, retrying (Requested nodes are busy)
srun: Job 10090951 step creation temporarily disabled, retrying (Requested nodes are busy)
srun: Job 10090951 step creation still disabled, retrying (Requested nodes are busy)
srun: Step created for job 10090951
2024-07-26 10:16:08.821223: I tensorflow/core/common_runtime/gpu/gpu_device.cc:1613] Created device /job:localhost/replica:0/task:0/device:GPU:1 with 38364 MB memory:  -> device: 1, name: NVIDIA A100-SXM4-40GB, pci bus id: 0000:44:00.0, compute capability: 8.0
2024-07-26 10:16:08.822875: I tensorflow/core/common_runtime/gpu/gpu_device.cc:1613] Created device /job:localhost/replica:0/task:0/device:GPU:2 with 38364 MB memory:  -> device: 2, name: NVIDIA A100-SXM4-40GB, pci bus id: 0000:84:00.0, compute capability: 8.0
2024-07-26 10:16:08.824466: I tensorflow/core/common_runtime/gpu/gpu_device.cc:1613] Created device /job:localhost/replica:0/task:0/device:GPU:3 with 38364 MB memory:  -> device: 3, name: NVIDIA A100-SXM4-40GB, pci bus id: 0000:c4:00.0, compute capability: 8.0
2024-07-26 10:16:09.163817: I tensorflow/core/common_runtime/gpu/gpu_device.cc:1613] Created device /job:localhost/replica:0/task:0/device:GPU:0 with 38364 MB memory:  -> device: 0, name: NVIDIA A100-SXM4-40GB, pci bus id: 0000:03:00.0, compute capability: 8.0
2024-07-26 10:16:09.165699: I tensorflow/core/common_runtime/gpu/gpu_device.cc:1613] Created device /job:localhost/replica:0/task:0/device:GPU:1 with 38364 MB memory:  -> device: 1, name: NVIDIA A100-SXM4-40GB, pci bus id: 0000:44:00.0, compute capability: 8.0
2024-07-26 10:16:09.168142: I tensorflow/core/common_runtime/gpu/gpu_device.cc:1613] Created device /job:localhost/replica:0/task:0/device:GPU:2 with 38364 MB memory:  -> device: 2, name: NVIDIA A100-SXM4-40GB, pci bus id: 0000:84:00.0, compute capability: 8.0
2024-07-26 10:16:09.170729: I tensorflow/core/common_runtime/gpu/gpu_device.cc:1613] Created device /job:localhost/replica:0/task:0/device:GPU:3 with 38364 MB memory:  -> device: 3, name: NVIDIA A100-SXM4-40GB, pci bus id: 0000:c4:00.0, compute capability: 8.0
2024-07-26 10:16:09.332911: I tensorflow/core/common_runtime/gpu/gpu_device.cc:1613] Created device /job:localhost/replica:0/task:0/device:GPU:0 with 38364 MB memory:  -> device: 0, name: NVIDIA A100-SXM4-40GB, pci bus id: 0000:03:00.0, compute capability: 8.0
2024-07-26 10:16:09.336233: I tensorflow/core/common_runtime/gpu/gpu_device.cc:1613] Created device /job:localhost/replica:0/task:0/device:GPU:1 with 38364 MB memory:  -> device: 1, name: NVIDIA A100-SXM4-40GB, pci bus id: 0000:44:00.0, compute capability: 8.0
2024-07-26 10:16:09.338704: I tensorflow/core/common_runtime/gpu/gpu_device.cc:1613] Created device /job:localhost/replica:0/task:0/device:GPU:2 with 38364 MB memory:  -> device: 2, name: NVIDIA A100-SXM4-40GB, pci bus id: 0000:84:00.0, compute capability: 8.0
2024-07-26 10:16:09.341109: I tensorflow/core/common_runtime/gpu/gpu_device.cc:1613] Created device /job:localhost/replica:0/task:0/device:GPU:3 with 38364 MB memory:  -> device: 3, name: NVIDIA A100-SXM4-40GB, pci bus id: 0000:c4:00.0, compute capability: 8.0
srun: error: jwb0131: task 0: Exited with exit code 1
srun: Job 10090951 step creation still disabled, retrying (Requested nodes are busy)
srun: Job 10090951 step creation still disabled, retrying (Requested nodes are busy)
srun: Job 10090951 step creation still disabled, retrying (Requested nodes are busy)
srun: Job 10090951 step creation temporarily disabled, retrying (Requested nodes are busy)
srun: Step created for job 10090951
2024-07-26 10:16:09.887701: I tensorflow/core/common_runtime/gpu/gpu_device.cc:1613] Created device /job:localhost/replica:0/task:0/device:GPU:0 with 38364 MB memory:  -> device: 0, name: NVIDIA A100-SXM4-40GB, pci bus id: 0000:03:00.0, compute capability: 8.0
2024-07-26 10:16:09.889391: I tensorflow/core/common_runtime/gpu/gpu_device.cc:1613] Created device /job:localhost/replica:0/task:0/device:GPU:1 with 38364 MB memory:  -> device: 1, name: NVIDIA A100-SXM4-40GB, pci bus id: 0000:44:00.0, compute capability: 8.0
2024-07-26 10:16:09.891796: I tensorflow/core/common_runtime/gpu/gpu_device.cc:1613] Created device /job:localhost/replica:0/task:0/device:GPU:2 with 38364 MB memory:  -> device: 2, name: NVIDIA A100-SXM4-40GB, pci bus id: 0000:84:00.0, compute capability: 8.0
2024-07-26 10:16:09.894627: I tensorflow/core/common_runtime/gpu/gpu_device.cc:1613] Created device /job:localhost/replica:0/task:0/device:GPU:3 with 38364 MB memory:  -> device: 3, name: NVIDIA A100-SXM4-40GB, pci bus id: 0000:c4:00.0, compute capability: 8.0
srun: error: jwb0315: task 0: Exited with exit code 1
srun: Job 10090951 step creation still disabled, retrying (Requested nodes are busy)
srun: Job 10090951 step creation still disabled, retrying (Requested nodes are busy)
srun: Job 10090951 step creation still disabled, retrying (Requested nodes are busy)
srun: Job 10090951 step creation temporarily disabled, retrying (Requested nodes are busy)
srun: Step created for job 10090951
2024-07-26 10:16:11.433199: I tensorflow/core/common_runtime/gpu/gpu_device.cc:1613] Created device /job:localhost/replica:0/task:0/device:GPU:0 with 38364 MB memory:  -> device: 0, name: NVIDIA A100-SXM4-40GB, pci bus id: 0000:03:00.0, compute capability: 8.0
2024-07-26 10:16:11.435912: I tensorflow/core/common_runtime/gpu/gpu_device.cc:1613] Created device /job:localhost/replica:0/task:0/device:GPU:1 with 38364 MB memory:  -> device: 1, name: NVIDIA A100-SXM4-40GB, pci bus id: 0000:44:00.0, compute capability: 8.0
2024-07-26 10:16:11.437383: I tensorflow/core/common_runtime/gpu/gpu_device.cc:1613] Created device /job:localhost/replica:0/task:0/device:GPU:2 with 38364 MB memory:  -> device: 2, name: NVIDIA A100-SXM4-40GB, pci bus id: 0000:84:00.0, compute capability: 8.0
2024-07-26 10:16:11.438825: I tensorflow/core/common_runtime/gpu/gpu_device.cc:1613] Created device /job:localhost/replica:0/task:0/device:GPU:3 with 38364 MB memory:  -> device: 3, name: NVIDIA A100-SXM4-40GB, pci bus id: 0000:c4:00.0, compute capability: 8.0
Traceback (most recent call last):
  File "/p/project1/cesmtst/patakchiyousefi1/CODES-MS3/FORECASTLEAD/DL_TRAIN.py", line 97, in <module>
    model = func_train.UNET(xpixels, ypixels, n_channels, Filters, dropout, unet_type)
  File "/p/project1/cesmtst/patakchiyousefi1/CODES-MS3/FORECASTLEAD/func_train.py", line 201, in UNET
    p4 = tf.keras.layers.MaxPooling2D((2, 2))(c4)
  File "/p/software/juwelsbooster/stages/2023/software/TensorFlow/2.11.0-foss-2022a-CUDA-11.7/lib/python3.10/site-packages/keras/utils/traceback_utils.py", line 70, in error_handler
    raise e.with_traceback(filtered_tb) from None
  File "/p/software/juwelsbooster/stages/2023/software/TensorFlow/2.11.0-foss-2022a-CUDA-11.7/lib/python3.10/site-packages/tensorflow/python/framework/ops.py", line 1967, in _create_c_op
    raise ValueError(e.message)
ValueError: Exception encountered when calling layer "max_pooling2d_3" (type MaxPooling2D).

Negative dimension size caused by subtracting 2 from 1 for '{{node max_pooling2d_3/MaxPool}} = MaxPool[T=DT_FLOAT, data_format="NHWC", explicit_paddings=[], ksize=[1, 2, 2, 1], padding="VALID", strides=[1, 2, 2, 1]](Placeholder)' with input shapes: [?,1,3,512].

Call arguments received by layer "max_pooling2d_3" (type MaxPooling2D):
  • inputs=tf.Tensor(shape=(None, 1, 3, 512), dtype=float32)
2024-07-26 10:16:11.632647: I tensorflow/core/common_runtime/gpu/gpu_device.cc:1613] Created device /job:localhost/replica:0/task:0/device:GPU:0 with 38364 MB memory:  -> device: 0, name: NVIDIA A100-SXM4-40GB, pci bus id: 0000:03:00.0, compute capability: 8.0
2024-07-26 10:16:11.635493: I tensorflow/core/common_runtime/gpu/gpu_device.cc:1613] Created device /job:localhost/replica:0/task:0/device:GPU:1 with 38364 MB memory:  -> device: 1, name: NVIDIA A100-SXM4-40GB, pci bus id: 0000:44:00.0, compute capability: 8.0
2024-07-26 10:16:11.636981: I tensorflow/core/common_runtime/gpu/gpu_device.cc:1613] Created device /job:localhost/replica:0/task:0/device:GPU:2 with 38364 MB memory:  -> device: 2, name: NVIDIA A100-SXM4-40GB, pci bus id: 0000:84:00.0, compute capability: 8.0
2024-07-26 10:16:11.638430: I tensorflow/core/common_runtime/gpu/gpu_device.cc:1613] Created device /job:localhost/replica:0/task:0/device:GPU:3 with 38364 MB memory:  -> device: 3, name: NVIDIA A100-SXM4-40GB, pci bus id: 0000:c4:00.0, compute capability: 8.0
Traceback (most recent call last):
  File "/p/project1/cesmtst/patakchiyousefi1/CODES-MS3/FORECASTLEAD/DL_TRAIN.py", line 97, in <module>
    model = func_train.UNET(xpixels, ypixels, n_channels, Filters, dropout, unet_type)
  File "/p/project1/cesmtst/patakchiyousefi1/CODES-MS3/FORECASTLEAD/func_train.py", line 201, in UNET
    p4 = tf.keras.layers.MaxPooling2D((2, 2))(c4)
  File "/p/software/juwelsbooster/stages/2023/software/TensorFlow/2.11.0-foss-2022a-CUDA-11.7/lib/python3.10/site-packages/keras/utils/traceback_utils.py", line 70, in error_handler
    raise e.with_traceback(filtered_tb) from None
  File "/p/software/juwelsbooster/stages/2023/software/TensorFlow/2.11.0-foss-2022a-CUDA-11.7/lib/python3.10/site-packages/tensorflow/python/framework/ops.py", line 1967, in _create_c_op
    raise ValueError(e.message)
ValueError: Exception encountered when calling layer "max_pooling2d_3" (type MaxPooling2D).

Negative dimension size caused by subtracting 2 from 1 for '{{node max_pooling2d_3/MaxPool}} = MaxPool[T=DT_FLOAT, data_format="NHWC", explicit_paddings=[], ksize=[1, 2, 2, 1], padding="VALID", strides=[1, 2, 2, 1]](Placeholder)' with input shapes: [?,1,3,512].

Call arguments received by layer "max_pooling2d_3" (type MaxPooling2D):
  • inputs=tf.Tensor(shape=(None, 1, 3, 512), dtype=float32)
2024-07-26 10:16:11.907857: I tensorflow/core/common_runtime/gpu/gpu_device.cc:1613] Created device /job:localhost/replica:0/task:0/device:GPU:0 with 38364 MB memory:  -> device: 0, name: NVIDIA A100-SXM4-40GB, pci bus id: 0000:03:00.0, compute capability: 8.0
2024-07-26 10:16:11.909912: I tensorflow/core/common_runtime/gpu/gpu_device.cc:1613] Created device /job:localhost/replica:0/task:0/device:GPU:1 with 38364 MB memory:  -> device: 1, name: NVIDIA A100-SXM4-40GB, pci bus id: 0000:44:00.0, compute capability: 8.0
2024-07-26 10:16:11.911550: I tensorflow/core/common_runtime/gpu/gpu_device.cc:1613] Created device /job:localhost/replica:0/task:0/device:GPU:2 with 38364 MB memory:  -> device: 2, name: NVIDIA A100-SXM4-40GB, pci bus id: 0000:84:00.0, compute capability: 8.0
2024-07-26 10:16:11.913080: I tensorflow/core/common_runtime/gpu/gpu_device.cc:1613] Created device /job:localhost/replica:0/task:0/device:GPU:3 with 38364 MB memory:  -> device: 3, name: NVIDIA A100-SXM4-40GB, pci bus id: 0000:c4:00.0, compute capability: 8.0
Traceback (most recent call last):
  File "/p/project1/cesmtst/patakchiyousefi1/CODES-MS3/FORECASTLEAD/DL_TRAIN.py", line 97, in <module>
    model = func_train.UNET(xpixels, ypixels, n_channels, Filters, dropout, unet_type)
  File "/p/project1/cesmtst/patakchiyousefi1/CODES-MS3/FORECASTLEAD/func_train.py", line 201, in UNET
    p4 = tf.keras.layers.MaxPooling2D((2, 2))(c4)
  File "/p/software/juwelsbooster/stages/2023/software/TensorFlow/2.11.0-foss-2022a-CUDA-11.7/lib/python3.10/site-packages/keras/utils/traceback_utils.py", line 70, in error_handler
    raise e.with_traceback(filtered_tb) from None
  File "/p/software/juwelsbooster/stages/2023/software/TensorFlow/2.11.0-foss-2022a-CUDA-11.7/lib/python3.10/site-packages/tensorflow/python/framework/ops.py", line 1967, in _create_c_op
    raise ValueError(e.message)
ValueError: Exception encountered when calling layer "max_pooling2d_3" (type MaxPooling2D).

Negative dimension size caused by subtracting 2 from 1 for '{{node max_pooling2d_3/MaxPool}} = MaxPool[T=DT_FLOAT, data_format="NHWC", explicit_paddings=[], ksize=[1, 2, 2, 1], padding="VALID", strides=[1, 2, 2, 1]](Placeholder)' with input shapes: [?,1,3,512].

Call arguments received by layer "max_pooling2d_3" (type MaxPooling2D):
  • inputs=tf.Tensor(shape=(None, 1, 3, 512), dtype=float32)
2024-07-26 10:16:12.127756: I tensorflow/core/common_runtime/gpu/gpu_device.cc:1613] Created device /job:localhost/replica:0/task:0/device:GPU:0 with 38364 MB memory:  -> device: 0, name: NVIDIA A100-SXM4-40GB, pci bus id: 0000:03:00.0, compute capability: 8.0
2024-07-26 10:16:12.129625: I tensorflow/core/common_runtime/gpu/gpu_device.cc:1613] Created device /job:localhost/replica:0/task:0/device:GPU:1 with 38364 MB memory:  -> device: 1, name: NVIDIA A100-SXM4-40GB, pci bus id: 0000:44:00.0, compute capability: 8.0
2024-07-26 10:16:12.131141: I tensorflow/core/common_runtime/gpu/gpu_device.cc:1613] Created device /job:localhost/replica:0/task:0/device:GPU:2 with 38364 MB memory:  -> device: 2, name: NVIDIA A100-SXM4-40GB, pci bus id: 0000:84:00.0, compute capability: 8.0
2024-07-26 10:16:12.133629: I tensorflow/core/common_runtime/gpu/gpu_device.cc:1613] Created device /job:localhost/replica:0/task:0/device:GPU:3 with 38364 MB memory:  -> device: 3, name: NVIDIA A100-SXM4-40GB, pci bus id: 0000:c4:00.0, compute capability: 8.0
2024-07-26 10:16:12.456158: I tensorflow/core/common_runtime/gpu/gpu_device.cc:1613] Created device /job:localhost/replica:0/task:0/device:GPU:0 with 38364 MB memory:  -> device: 0, name: NVIDIA A100-SXM4-40GB, pci bus id: 0000:03:00.0, compute capability: 8.0
2024-07-26 10:16:12.457907: I tensorflow/core/common_runtime/gpu/gpu_device.cc:1613] Created device /job:localhost/replica:0/task:0/device:GPU:1 with 38364 MB memory:  -> device: 1, name: NVIDIA A100-SXM4-40GB, pci bus id: 0000:44:00.0, compute capability: 8.0
2024-07-26 10:16:12.459395: I tensorflow/core/common_runtime/gpu/gpu_device.cc:1613] Created device /job:localhost/replica:0/task:0/device:GPU:2 with 38364 MB memory:  -> device: 2, name: NVIDIA A100-SXM4-40GB, pci bus id: 0000:84:00.0, compute capability: 8.0
2024-07-26 10:16:12.461026: I tensorflow/core/common_runtime/gpu/gpu_device.cc:1613] Created device /job:localhost/replica:0/task:0/device:GPU:3 with 38364 MB memory:  -> device: 3, name: NVIDIA A100-SXM4-40GB, pci bus id: 0000:c4:00.0, compute capability: 8.0
2024-07-26 10:16:12.552640: I tensorflow/core/common_runtime/gpu/gpu_device.cc:1613] Created device /job:localhost/replica:0/task:0/device:GPU:0 with 38364 MB memory:  -> device: 0, name: NVIDIA A100-SXM4-40GB, pci bus id: 0000:03:00.0, compute capability: 8.0
2024-07-26 10:16:12.554544: I tensorflow/core/common_runtime/gpu/gpu_device.cc:1613] Created device /job:localhost/replica:0/task:0/device:GPU:1 with 38364 MB memory:  -> device: 1, name: NVIDIA A100-SXM4-40GB, pci bus id: 0000:44:00.0, compute capability: 8.0
2024-07-26 10:16:12.556170: I tensorflow/core/common_runtime/gpu/gpu_device.cc:1613] Created device /job:localhost/replica:0/task:0/device:GPU:2 with 38364 MB memory:  -> device: 2, name: NVIDIA A100-SXM4-40GB, pci bus id: 0000:84:00.0, compute capability: 8.0
2024-07-26 10:16:12.558827: I tensorflow/core/common_runtime/gpu/gpu_device.cc:1613] Created device /job:localhost/replica:0/task:0/device:GPU:3 with 38364 MB memory:  -> device: 3, name: NVIDIA A100-SXM4-40GB, pci bus id: 0000:c4:00.0, compute capability: 8.0
Traceback (most recent call last):
  File "/p/project1/cesmtst/patakchiyousefi1/CODES-MS3/FORECASTLEAD/DL_TRAIN.py", line 97, in <module>
    model = func_train.UNET(xpixels, ypixels, n_channels, Filters, dropout, unet_type)
  File "/p/project1/cesmtst/patakchiyousefi1/CODES-MS3/FORECASTLEAD/func_train.py", line 201, in UNET
    p4 = tf.keras.layers.MaxPooling2D((2, 2))(c4)
  File "/p/software/juwelsbooster/stages/2023/software/TensorFlow/2.11.0-foss-2022a-CUDA-11.7/lib/python3.10/site-packages/keras/utils/traceback_utils.py", line 70, in error_handler
    raise e.with_traceback(filtered_tb) from None
  File "/p/software/juwelsbooster/stages/2023/software/TensorFlow/2.11.0-foss-2022a-CUDA-11.7/lib/python3.10/site-packages/tensorflow/python/framework/ops.py", line 1967, in _create_c_op
    raise ValueError(e.message)
ValueError: Exception encountered when calling layer "max_pooling2d_3" (type MaxPooling2D).

Negative dimension size caused by subtracting 2 from 1 for '{{node max_pooling2d_3/MaxPool}} = MaxPool[T=DT_FLOAT, data_format="NHWC", explicit_paddings=[], ksize=[1, 2, 2, 1], padding="VALID", strides=[1, 2, 2, 1]](Placeholder)' with input shapes: [?,1,3,512].

Call arguments received by layer "max_pooling2d_3" (type MaxPooling2D):
  • inputs=tf.Tensor(shape=(None, 1, 3, 512), dtype=float32)
2024-07-26 10:16:12.990882: I tensorflow/core/common_runtime/gpu/gpu_device.cc:1613] Created device /job:localhost/replica:0/task:0/device:GPU:0 with 38364 MB memory:  -> device: 0, name: NVIDIA A100-SXM4-40GB, pci bus id: 0000:03:00.0, compute capability: 8.0
2024-07-26 10:16:12.992799: I tensorflow/core/common_runtime/gpu/gpu_device.cc:1613] Created device /job:localhost/replica:0/task:0/device:GPU:1 with 38364 MB memory:  -> device: 1, name: NVIDIA A100-SXM4-40GB, pci bus id: 0000:44:00.0, compute capability: 8.0
2024-07-26 10:16:12.995937: I tensorflow/core/common_runtime/gpu/gpu_device.cc:1613] Created device /job:localhost/replica:0/task:0/device:GPU:2 with 38364 MB memory:  -> device: 2, name: NVIDIA A100-SXM4-40GB, pci bus id: 0000:84:00.0, compute capability: 8.0
2024-07-26 10:16:12.999289: I tensorflow/core/common_runtime/gpu/gpu_device.cc:1613] Created device /job:localhost/replica:0/task:0/device:GPU:3 with 38364 MB memory:  -> device: 3, name: NVIDIA A100-SXM4-40GB, pci bus id: 0000:c4:00.0, compute capability: 8.0
srun: error: jwb0996: task 0: Exited with exit code 1
srun: Job 10090951 step creation still disabled, retrying (Requested nodes are busy)
srun: Job 10090951 step creation still disabled, retrying (Requested nodes are busy)
srun: Job 10090951 step creation temporarily disabled, retrying (Requested nodes are busy)
srun: Job 10090951 step creation temporarily disabled, retrying (Requested nodes are busy)
srun: Job 10090951 step creation temporarily disabled, retrying (Requested nodes are busy)
srun: Job 10090951 step creation temporarily disabled, retrying (Requested nodes are busy)
srun: Job 10090951 step creation temporarily disabled, retrying (Requested nodes are busy)
srun: Job 10090951 step creation still disabled, retrying (Requested nodes are busy)
srun: Step created for job 10090951
2024-07-26 10:16:13.417954: I tensorflow/core/common_runtime/gpu/gpu_device.cc:1613] Created device /job:localhost/replica:0/task:0/device:GPU:0 with 38364 MB memory:  -> device: 0, name: NVIDIA A100-SXM4-40GB, pci bus id: 0000:03:00.0, compute capability: 8.0
2024-07-26 10:16:13.420855: I tensorflow/core/common_runtime/gpu/gpu_device.cc:1613] Created device /job:localhost/replica:0/task:0/device:GPU:1 with 38364 MB memory:  -> device: 1, name: NVIDIA A100-SXM4-40GB, pci bus id: 0000:44:00.0, compute capability: 8.0
2024-07-26 10:16:13.422482: I tensorflow/core/common_runtime/gpu/gpu_device.cc:1613] Created device /job:localhost/replica:0/task:0/device:GPU:2 with 38364 MB memory:  -> device: 2, name: NVIDIA A100-SXM4-40GB, pci bus id: 0000:84:00.0, compute capability: 8.0
2024-07-26 10:16:13.425713: I tensorflow/core/common_runtime/gpu/gpu_device.cc:1613] Created device /job:localhost/replica:0/task:0/device:GPU:3 with 38364 MB memory:  -> device: 3, name: NVIDIA A100-SXM4-40GB, pci bus id: 0000:c4:00.0, compute capability: 8.0
2024-07-26 10:16:13.543954: I tensorflow/core/common_runtime/gpu/gpu_device.cc:1613] Created device /job:localhost/replica:0/task:0/device:GPU:0 with 38364 MB memory:  -> device: 0, name: NVIDIA A100-SXM4-40GB, pci bus id: 0000:03:00.0, compute capability: 8.0
2024-07-26 10:16:13.545807: I tensorflow/core/common_runtime/gpu/gpu_device.cc:1613] Created device /job:localhost/replica:0/task:0/device:GPU:1 with 38364 MB memory:  -> device: 1, name: NVIDIA A100-SXM4-40GB, pci bus id: 0000:44:00.0, compute capability: 8.0
2024-07-26 10:16:13.547450: I tensorflow/core/common_runtime/gpu/gpu_device.cc:1613] Created device /job:localhost/replica:0/task:0/device:GPU:2 with 38364 MB memory:  -> device: 2, name: NVIDIA A100-SXM4-40GB, pci bus id: 0000:84:00.0, compute capability: 8.0
2024-07-26 10:16:13.548931: I tensorflow/core/common_runtime/gpu/gpu_device.cc:1613] Created device /job:localhost/replica:0/task:0/device:GPU:3 with 38364 MB memory:  -> device: 3, name: NVIDIA A100-SXM4-40GB, pci bus id: 0000:c4:00.0, compute capability: 8.0
srun: error: jwb0993: task 0: Exited with exit code 1
srun: Job 10090951 step creation still disabled, retrying (Requested nodes are busy)
srun: Job 10090951 step creation still disabled, retrying (Requested nodes are busy)
srun: Job 10090951 step creation still disabled, retrying (Requested nodes are busy)
srun: Job 10090951 step creation still disabled, retrying (Requested nodes are busy)
srun: Job 10090951 step creation still disabled, retrying (Requested nodes are busy)
srun: Job 10090951 step creation still disabled, retrying (Requested nodes are busy)
srun: Job 10090951 step creation still disabled, retrying (Requested nodes are busy)
srun: Job 10090951 step creation temporarily disabled, retrying (Requested nodes are busy)
srun: Step created for job 10090951
srun: error: jwb1002: task 0: Exited with exit code 1
srun: Job 10090951 step creation still disabled, retrying (Requested nodes are busy)
srun: Job 10090951 step creation still disabled, retrying (Requested nodes are busy)
srun: Job 10090951 step creation still disabled, retrying (Requested nodes are busy)
srun: Job 10090951 step creation still disabled, retrying (Requested nodes are busy)
srun: Job 10090951 step creation still disabled, retrying (Requested nodes are busy)
srun: Job 10090951 step creation still disabled, retrying (Requested nodes are busy)
srun: Job 10090951 step creation still disabled, retrying (Requested nodes are busy)
srun: Step created for job 10090951
2024-07-26 10:16:13.965551: I tensorflow/core/common_runtime/gpu/gpu_device.cc:1613] Created device /job:localhost/replica:0/task:0/device:GPU:0 with 38364 MB memory:  -> device: 0, name: NVIDIA A100-SXM4-40GB, pci bus id: 0000:03:00.0, compute capability: 8.0
2024-07-26 10:16:13.967322: I tensorflow/core/common_runtime/gpu/gpu_device.cc:1613] Created device /job:localhost/replica:0/task:0/device:GPU:1 with 38364 MB memory:  -> device: 1, name: NVIDIA A100-SXM4-40GB, pci bus id: 0000:44:00.0, compute capability: 8.0
2024-07-26 10:16:13.970162: I tensorflow/core/common_runtime/gpu/gpu_device.cc:1613] Created device /job:localhost/replica:0/task:0/device:GPU:2 with 38364 MB memory:  -> device: 2, name: NVIDIA A100-SXM4-40GB, pci bus id: 0000:84:00.0, compute capability: 8.0
2024-07-26 10:16:13.971667: I tensorflow/core/common_runtime/gpu/gpu_device.cc:1613] Created device /job:localhost/replica:0/task:0/device:GPU:3 with 38364 MB memory:  -> device: 3, name: NVIDIA A100-SXM4-40GB, pci bus id: 0000:c4:00.0, compute capability: 8.0
2024-07-26 10:16:14.136149: I tensorflow/core/common_runtime/gpu/gpu_device.cc:1613] Created device /job:localhost/replica:0/task:0/device:GPU:0 with 38364 MB memory:  -> device: 0, name: NVIDIA A100-SXM4-40GB, pci bus id: 0000:03:00.0, compute capability: 8.0
Traceback (most recent call last):
  File "/p/project1/cesmtst/patakchiyousefi1/CODES-MS3/FORECASTLEAD/DL_TRAIN.py", line 97, in <module>
    model = func_train.UNET(xpixels, ypixels, n_channels, Filters, dropout, unet_type)
  File "/p/project1/cesmtst/patakchiyousefi1/CODES-MS3/FORECASTLEAD/func_train.py", line 201, in UNET
    p4 = tf.keras.layers.MaxPooling2D((2, 2))(c4)
  File "/p/software/juwelsbooster/stages/2023/software/TensorFlow/2.11.0-foss-2022a-CUDA-11.7/lib/python3.10/site-packages/keras/utils/traceback_utils.py", line 70, in error_handler
    raise e.with_traceback(filtered_tb) from None
  File "/p/software/juwelsbooster/stages/2023/software/TensorFlow/2.11.0-foss-2022a-CUDA-11.7/lib/python3.10/site-packages/tensorflow/python/framework/ops.py", line 1967, in _create_c_op
    raise ValueError(e.message)
ValueError: Exception encountered when calling layer "max_pooling2d_3" (type MaxPooling2D).

Negative dimension size caused by subtracting 2 from 1 for '{{node max_pooling2d_3/MaxPool}} = MaxPool[T=DT_FLOAT, data_format="NHWC", explicit_paddings=[], ksize=[1, 2, 2, 1], padding="VALID", strides=[1, 2, 2, 1]](Placeholder)' with input shapes: [?,1,3,512].

Call arguments received by layer "max_pooling2d_3" (type MaxPooling2D):
  • inputs=tf.Tensor(shape=(None, 1, 3, 512), dtype=float32)
2024-07-26 10:16:14.139731: I tensorflow/core/common_runtime/gpu/gpu_device.cc:1613] Created device /job:localhost/replica:0/task:0/device:GPU:1 with 38364 MB memory:  -> device: 1, name: NVIDIA A100-SXM4-40GB, pci bus id: 0000:44:00.0, compute capability: 8.0
2024-07-26 10:16:14.141251: I tensorflow/core/common_runtime/gpu/gpu_device.cc:1613] Created device /job:localhost/replica:0/task:0/device:GPU:2 with 38364 MB memory:  -> device: 2, name: NVIDIA A100-SXM4-40GB, pci bus id: 0000:84:00.0, compute capability: 8.0
2024-07-26 10:16:14.144531: I tensorflow/core/common_runtime/gpu/gpu_device.cc:1613] Created device /job:localhost/replica:0/task:0/device:GPU:3 with 38364 MB memory:  -> device: 3, name: NVIDIA A100-SXM4-40GB, pci bus id: 0000:c4:00.0, compute capability: 8.0
srun: error: jwb1004: task 0: Exited with exit code 1
srun: Job 10090951 step creation still disabled, retrying (Requested nodes are busy)
srun: Job 10090951 step creation still disabled, retrying (Requested nodes are busy)
srun: Job 10090951 step creation still disabled, retrying (Requested nodes are busy)
srun: Job 10090951 step creation still disabled, retrying (Requested nodes are busy)
srun: Job 10090951 step creation still disabled, retrying (Requested nodes are busy)
srun: Job 10090951 step creation still disabled, retrying (Requested nodes are busy)
srun: Job 10090951 step creation temporarily disabled, retrying (Requested nodes are busy)
srun: Step created for job 10090951
Traceback (most recent call last):
  File "/p/project1/cesmtst/patakchiyousefi1/CODES-MS3/FORECASTLEAD/DL_TRAIN.py", line 97, in <module>
    model = func_train.UNET(xpixels, ypixels, n_channels, Filters, dropout, unet_type)
  File "/p/project1/cesmtst/patakchiyousefi1/CODES-MS3/FORECASTLEAD/func_train.py", line 201, in UNET
    p4 = tf.keras.layers.MaxPooling2D((2, 2))(c4)
  File "/p/software/juwelsbooster/stages/2023/software/TensorFlow/2.11.0-foss-2022a-CUDA-11.7/lib/python3.10/site-packages/keras/utils/traceback_utils.py", line 70, in error_handler
    raise e.with_traceback(filtered_tb) from None
  File "/p/software/juwelsbooster/stages/2023/software/TensorFlow/2.11.0-foss-2022a-CUDA-11.7/lib/python3.10/site-packages/tensorflow/python/framework/ops.py", line 1967, in _create_c_op
    raise ValueError(e.message)
ValueError: Exception encountered when calling layer "max_pooling2d_3" (type MaxPooling2D).

Negative dimension size caused by subtracting 2 from 1 for '{{node max_pooling2d_3/MaxPool}} = MaxPool[T=DT_FLOAT, data_format="NHWC", explicit_paddings=[], ksize=[1, 2, 2, 1], padding="VALID", strides=[1, 2, 2, 1]](Placeholder)' with input shapes: [?,1,3,512].

Call arguments received by layer "max_pooling2d_3" (type MaxPooling2D):
  • inputs=tf.Tensor(shape=(None, 1, 3, 512), dtype=float32)
2024-07-26 10:16:14.535658: I tensorflow/core/common_runtime/gpu/gpu_device.cc:1613] Created device /job:localhost/replica:0/task:0/device:GPU:0 with 38364 MB memory:  -> device: 0, name: NVIDIA A100-SXM4-40GB, pci bus id: 0000:03:00.0, compute capability: 8.0
2024-07-26 10:16:14.538463: I tensorflow/core/common_runtime/gpu/gpu_device.cc:1613] Created device /job:localhost/replica:0/task:0/device:GPU:1 with 38364 MB memory:  -> device: 1, name: NVIDIA A100-SXM4-40GB, pci bus id: 0000:44:00.0, compute capability: 8.0
2024-07-26 10:16:14.540914: I tensorflow/core/common_runtime/gpu/gpu_device.cc:1613] Created device /job:localhost/replica:0/task:0/device:GPU:2 with 38364 MB memory:  -> device: 2, name: NVIDIA A100-SXM4-40GB, pci bus id: 0000:84:00.0, compute capability: 8.0
2024-07-26 10:16:14.542355: I tensorflow/core/common_runtime/gpu/gpu_device.cc:1613] Created device /job:localhost/replica:0/task:0/device:GPU:3 with 38364 MB memory:  -> device: 3, name: NVIDIA A100-SXM4-40GB, pci bus id: 0000:c4:00.0, compute capability: 8.0
2024-07-26 10:16:14.606189: I tensorflow/core/common_runtime/gpu/gpu_device.cc:1613] Created device /job:localhost/replica:0/task:0/device:GPU:0 with 38364 MB memory:  -> device: 0, name: NVIDIA A100-SXM4-40GB, pci bus id: 0000:03:00.0, compute capability: 8.0
2024-07-26 10:16:14.607944: I tensorflow/core/common_runtime/gpu/gpu_device.cc:1613] Created device /job:localhost/replica:0/task:0/device:GPU:1 with 38364 MB memory:  -> device: 1, name: NVIDIA A100-SXM4-40GB, pci bus id: 0000:44:00.0, compute capability: 8.0
2024-07-26 10:16:14.609702: I tensorflow/core/common_runtime/gpu/gpu_device.cc:1613] Created device /job:localhost/replica:0/task:0/device:GPU:2 with 38364 MB memory:  -> device: 2, name: NVIDIA A100-SXM4-40GB, pci bus id: 0000:84:00.0, compute capability: 8.0
2024-07-26 10:16:14.611439: I tensorflow/core/common_runtime/gpu/gpu_device.cc:1613] Created device /job:localhost/replica:0/task:0/device:GPU:3 with 38364 MB memory:  -> device: 3, name: NVIDIA A100-SXM4-40GB, pci bus id: 0000:c4:00.0, compute capability: 8.0
Traceback (most recent call last):
  File "/p/project1/cesmtst/patakchiyousefi1/CODES-MS3/FORECASTLEAD/DL_TRAIN.py", line 97, in <module>
    model = func_train.UNET(xpixels, ypixels, n_channels, Filters, dropout, unet_type)
  File "/p/project1/cesmtst/patakchiyousefi1/CODES-MS3/FORECASTLEAD/func_train.py", line 201, in UNET
    p4 = tf.keras.layers.MaxPooling2D((2, 2))(c4)
  File "/p/software/juwelsbooster/stages/2023/software/TensorFlow/2.11.0-foss-2022a-CUDA-11.7/lib/python3.10/site-packages/keras/utils/traceback_utils.py", line 70, in error_handler
    raise e.with_traceback(filtered_tb) from None
  File "/p/software/juwelsbooster/stages/2023/software/TensorFlow/2.11.0-foss-2022a-CUDA-11.7/lib/python3.10/site-packages/tensorflow/python/framework/ops.py", line 1967, in _create_c_op
    raise ValueError(e.message)
ValueError: Exception encountered when calling layer "max_pooling2d_3" (type MaxPooling2D).

Negative dimension size caused by subtracting 2 from 1 for '{{node max_pooling2d_3/MaxPool}} = MaxPool[T=DT_FLOAT, data_format="NHWC", explicit_paddings=[], ksize=[1, 2, 2, 1], padding="VALID", strides=[1, 2, 2, 1]](Placeholder)' with input shapes: [?,1,3,512].

Call arguments received by layer "max_pooling2d_3" (type MaxPooling2D):
  • inputs=tf.Tensor(shape=(None, 1, 3, 512), dtype=float32)
Traceback (most recent call last):
  File "/p/project1/cesmtst/patakchiyousefi1/CODES-MS3/FORECASTLEAD/DL_TRAIN.py", line 97, in <module>
    model = func_train.UNET(xpixels, ypixels, n_channels, Filters, dropout, unet_type)
  File "/p/project1/cesmtst/patakchiyousefi1/CODES-MS3/FORECASTLEAD/func_train.py", line 201, in UNET
    p4 = tf.keras.layers.MaxPooling2D((2, 2))(c4)
  File "/p/software/juwelsbooster/stages/2023/software/TensorFlow/2.11.0-foss-2022a-CUDA-11.7/lib/python3.10/site-packages/keras/utils/traceback_utils.py", line 70, in error_handler
    raise e.with_traceback(filtered_tb) from None
  File "/p/software/juwelsbooster/stages/2023/software/TensorFlow/2.11.0-foss-2022a-CUDA-11.7/lib/python3.10/site-packages/tensorflow/python/framework/ops.py", line 1967, in _create_c_op
    raise ValueError(e.message)
ValueError: Exception encountered when calling layer "max_pooling2d_3" (type MaxPooling2D).

Negative dimension size caused by subtracting 2 from 1 for '{{node max_pooling2d_3/MaxPool}} = MaxPool[T=DT_FLOAT, data_format="NHWC", explicit_paddings=[], ksize=[1, 2, 2, 1], padding="VALID", strides=[1, 2, 2, 1]](Placeholder)' with input shapes: [?,1,3,512].

Call arguments received by layer "max_pooling2d_3" (type MaxPooling2D):
  • inputs=tf.Tensor(shape=(None, 1, 3, 512), dtype=float32)
2024-07-26 10:16:14.911888: I tensorflow/core/common_runtime/gpu/gpu_device.cc:1613] Created device /job:localhost/replica:0/task:0/device:GPU:0 with 38364 MB memory:  -> device: 0, name: NVIDIA A100-SXM4-40GB, pci bus id: 0000:03:00.0, compute capability: 8.0
2024-07-26 10:16:14.914641: I tensorflow/core/common_runtime/gpu/gpu_device.cc:1613] Created device /job:localhost/replica:0/task:0/device:GPU:1 with 38364 MB memory:  -> device: 1, name: NVIDIA A100-SXM4-40GB, pci bus id: 0000:44:00.0, compute capability: 8.0
2024-07-26 10:16:14.917261: I tensorflow/core/common_runtime/gpu/gpu_device.cc:1613] Created device /job:localhost/replica:0/task:0/device:GPU:2 with 38364 MB memory:  -> device: 2, name: NVIDIA A100-SXM4-40GB, pci bus id: 0000:84:00.0, compute capability: 8.0
2024-07-26 10:16:14.919890: I tensorflow/core/common_runtime/gpu/gpu_device.cc:1613] Created device /job:localhost/replica:0/task:0/device:GPU:3 with 38364 MB memory:  -> device: 3, name: NVIDIA A100-SXM4-40GB, pci bus id: 0000:c4:00.0, compute capability: 8.0
Traceback (most recent call last):
  File "/p/project1/cesmtst/patakchiyousefi1/CODES-MS3/FORECASTLEAD/DL_TRAIN.py", line 97, in <module>
    model = func_train.UNET(xpixels, ypixels, n_channels, Filters, dropout, unet_type)
  File "/p/project1/cesmtst/patakchiyousefi1/CODES-MS3/FORECASTLEAD/func_train.py", line 201, in UNET
    p4 = tf.keras.layers.MaxPooling2D((2, 2))(c4)
  File "/p/software/juwelsbooster/stages/2023/software/TensorFlow/2.11.0-foss-2022a-CUDA-11.7/lib/python3.10/site-packages/keras/utils/traceback_utils.py", line 70, in error_handler
    raise e.with_traceback(filtered_tb) from None
  File "/p/software/juwelsbooster/stages/2023/software/TensorFlow/2.11.0-foss-2022a-CUDA-11.7/lib/python3.10/site-packages/tensorflow/python/framework/ops.py", line 1967, in _create_c_op
    raise ValueError(e.message)
ValueError: Exception encountered when calling layer "max_pooling2d_3" (type MaxPooling2D).

Negative dimension size caused by subtracting 2 from 1 for '{{node max_pooling2d_3/MaxPool}} = MaxPool[T=DT_FLOAT, data_format="NHWC", explicit_paddings=[], ksize=[1, 2, 2, 1], padding="VALID", strides=[1, 2, 2, 1]](Placeholder)' with input shapes: [?,1,3,512].

Call arguments received by layer "max_pooling2d_3" (type MaxPooling2D):
  • inputs=tf.Tensor(shape=(None, 1, 3, 512), dtype=float32)
Traceback (most recent call last):
  File "/p/project1/cesmtst/patakchiyousefi1/CODES-MS3/FORECASTLEAD/DL_TRAIN.py", line 97, in <module>
    model = func_train.UNET(xpixels, ypixels, n_channels, Filters, dropout, unet_type)
  File "/p/project1/cesmtst/patakchiyousefi1/CODES-MS3/FORECASTLEAD/func_train.py", line 201, in UNET
    p4 = tf.keras.layers.MaxPooling2D((2, 2))(c4)
  File "/p/software/juwelsbooster/stages/2023/software/TensorFlow/2.11.0-foss-2022a-CUDA-11.7/lib/python3.10/site-packages/keras/utils/traceback_utils.py", line 70, in error_handler
    raise e.with_traceback(filtered_tb) from None
  File "/p/software/juwelsbooster/stages/2023/software/TensorFlow/2.11.0-foss-2022a-CUDA-11.7/lib/python3.10/site-packages/tensorflow/python/framework/ops.py", line 1967, in _create_c_op
    raise ValueError(e.message)
ValueError: Exception encountered when calling layer "max_pooling2d_3" (type MaxPooling2D).

Negative dimension size caused by subtracting 2 from 1 for '{{node max_pooling2d_3/MaxPool}} = MaxPool[T=DT_FLOAT, data_format="NHWC", explicit_paddings=[], ksize=[1, 2, 2, 1], padding="VALID", strides=[1, 2, 2, 1]](Placeholder)' with input shapes: [?,1,3,512].

Call arguments received by layer "max_pooling2d_3" (type MaxPooling2D):
  • inputs=tf.Tensor(shape=(None, 1, 3, 512), dtype=float32)
Traceback (most recent call last):
  File "/p/project1/cesmtst/patakchiyousefi1/CODES-MS3/FORECASTLEAD/DL_TRAIN.py", line 97, in <module>
    model = func_train.UNET(xpixels, ypixels, n_channels, Filters, dropout, unet_type)
  File "/p/project1/cesmtst/patakchiyousefi1/CODES-MS3/FORECASTLEAD/func_train.py", line 201, in UNET
    p4 = tf.keras.layers.MaxPooling2D((2, 2))(c4)
  File "/p/software/juwelsbooster/stages/2023/software/TensorFlow/2.11.0-foss-2022a-CUDA-11.7/lib/python3.10/site-packages/keras/utils/traceback_utils.py", line 70, in error_handler
2024-07-26 10:16:15.752577: I tensorflow/core/common_runtime/gpu/gpu_device.cc:1613] Created device /job:localhost/replica:0/task:0/device:GPU:0 with 38364 MB memory:  -> device: 0, name: NVIDIA A100-SXM4-40GB, pci bus id: 0000:03:00.0, compute capability: 8.0
    raise e.with_traceback(filtered_tb) from None
  File "/p/software/juwelsbooster/stages/2023/software/TensorFlow/2.11.0-foss-2022a-CUDA-11.7/lib/python3.10/site-packages/tensorflow/python/framework/ops.py", line 1967, in _create_c_op
    raise ValueError(e.message)
ValueError: Exception encountered when calling layer "max_pooling2d_3" (type MaxPooling2D).

Negative dimension size caused by subtracting 2 from 1 for '{{node max_pooling2d_3/MaxPool}} = MaxPool[T=DT_FLOAT, data_format="NHWC", explicit_paddings=[], ksize=[1, 2, 2, 1], padding="VALID", strides=[1, 2, 2, 1]](Placeholder)' with input shapes: [?,1,3,512].

Call arguments received by layer "max_pooling2d_3" (type MaxPooling2D):
  • inputs=tf.Tensor(shape=(None, 1, 3, 512), dtype=float32)
2024-07-26 10:16:15.754479: I tensorflow/core/common_runtime/gpu/gpu_device.cc:1613] Created device /job:localhost/replica:0/task:0/device:GPU:1 with 38364 MB memory:  -> device: 1, name: NVIDIA A100-SXM4-40GB, pci bus id: 0000:44:00.0, compute capability: 8.0
2024-07-26 10:16:15.755969: I tensorflow/core/common_runtime/gpu/gpu_device.cc:1613] Created device /job:localhost/replica:0/task:0/device:GPU:2 with 38364 MB memory:  -> device: 2, name: NVIDIA A100-SXM4-40GB, pci bus id: 0000:84:00.0, compute capability: 8.0
2024-07-26 10:16:15.758592: I tensorflow/core/common_runtime/gpu/gpu_device.cc:1613] Created device /job:localhost/replica:0/task:0/device:GPU:3 with 38364 MB memory:  -> device: 3, name: NVIDIA A100-SXM4-40GB, pci bus id: 0000:c4:00.0, compute capability: 8.0
srun: error: jwb1018: task 0: Exited with exit code 1
srun: Job 10090951 step creation still disabled, retrying (Requested nodes are busy)
srun: Job 10090951 step creation still disabled, retrying (Requested nodes are busy)
srun: Job 10090951 step creation still disabled, retrying (Requested nodes are busy)
srun: Job 10090951 step creation still disabled, retrying (Requested nodes are busy)
srun: Job 10090951 step creation still disabled, retrying (Requested nodes are busy)
srun: Job 10090951 step creation still disabled, retrying (Requested nodes are busy)
srun: Job 10090951 step creation temporarily disabled, retrying (Requested nodes are busy)
srun: Job 10090951 step creation temporarily disabled, retrying (Requested nodes are busy)
srun: Step created for job 10090951
2024-07-26 10:16:15.965319: I tensorflow/core/common_runtime/gpu/gpu_device.cc:1613] Created device /job:localhost/replica:0/task:0/device:GPU:0 with 38364 MB memory:  -> device: 0, name: NVIDIA A100-SXM4-40GB, pci bus id: 0000:03:00.0, compute capability: 8.0
2024-07-26 10:16:15.967237: I tensorflow/core/common_runtime/gpu/gpu_device.cc:1613] Created device /job:localhost/replica:0/task:0/device:GPU:1 with 38364 MB memory:  -> device: 1, name: NVIDIA A100-SXM4-40GB, pci bus id: 0000:44:00.0, compute capability: 8.0
2024-07-26 10:16:15.968902: I tensorflow/core/common_runtime/gpu/gpu_device.cc:1613] Created device /job:localhost/replica:0/task:0/device:GPU:2 with 38364 MB memory:  -> device: 2, name: NVIDIA A100-SXM4-40GB, pci bus id: 0000:84:00.0, compute capability: 8.0
2024-07-26 10:16:15.970531: I tensorflow/core/common_runtime/gpu/gpu_device.cc:1613] Created device /job:localhost/replica:0/task:0/device:GPU:3 with 38364 MB memory:  -> device: 3, name: NVIDIA A100-SXM4-40GB, pci bus id: 0000:c4:00.0, compute capability: 8.0
Traceback (most recent call last):
  File "/p/project1/cesmtst/patakchiyousefi1/CODES-MS3/FORECASTLEAD/DL_TRAIN.py", line 97, in <module>
    model = func_train.UNET(xpixels, ypixels, n_channels, Filters, dropout, unet_type)
  File "/p/project1/cesmtst/patakchiyousefi1/CODES-MS3/FORECASTLEAD/func_train.py", line 201, in UNET
    p4 = tf.keras.layers.MaxPooling2D((2, 2))(c4)
  File "/p/software/juwelsbooster/stages/2023/software/TensorFlow/2.11.0-foss-2022a-CUDA-11.7/lib/python3.10/site-packages/keras/utils/traceback_utils.py", line 70, in error_handler
    raise e.with_traceback(filtered_tb) from None
  File "/p/software/juwelsbooster/stages/2023/software/TensorFlow/2.11.0-foss-2022a-CUDA-11.7/lib/python3.10/site-packages/tensorflow/python/framework/ops.py", line 1967, in _create_c_op
    raise ValueError(e.message)
ValueError: Exception encountered when calling layer "max_pooling2d_3" (type MaxPooling2D).

Negative dimension size caused by subtracting 2 from 1 for '{{node max_pooling2d_3/MaxPool}} = MaxPool[T=DT_FLOAT, data_format="NHWC", explicit_paddings=[], ksize=[1, 2, 2, 1], padding="VALID", strides=[1, 2, 2, 1]](Placeholder)' with input shapes: [?,1,3,512].

Call arguments received by layer "max_pooling2d_3" (type MaxPooling2D):
  • inputs=tf.Tensor(shape=(None, 1, 3, 512), dtype=float32)
srun: error: jwb0380: task 0: Exited with exit code 1
srun: Job 10090951 step creation still disabled, retrying (Requested nodes are busy)
srun: Job 10090951 step creation temporarily disabled, retrying (Requested nodes are busy)
srun: Job 10090951 step creation still disabled, retrying (Requested nodes are busy)
srun: Job 10090951 step creation still disabled, retrying (Requested nodes are busy)
srun: Job 10090951 step creation still disabled, retrying (Requested nodes are busy)
srun: Job 10090951 step creation still disabled, retrying (Requested nodes are busy)
srun: Job 10090951 step creation still disabled, retrying (Requested nodes are busy)
srun: Job 10090951 step creation still disabled, retrying (Requested nodes are busy)
srun: Step created for job 10090951
Traceback (most recent call last):
  File "/p/project1/cesmtst/patakchiyousefi1/CODES-MS3/FORECASTLEAD/DL_TRAIN.py", line 97, in <module>
    model = func_train.UNET(xpixels, ypixels, n_channels, Filters, dropout, unet_type)
  File "/p/project1/cesmtst/patakchiyousefi1/CODES-MS3/FORECASTLEAD/func_train.py", line 201, in UNET
    p4 = tf.keras.layers.MaxPooling2D((2, 2))(c4)
  File "/p/software/juwelsbooster/stages/2023/software/TensorFlow/2.11.0-foss-2022a-CUDA-11.7/lib/python3.10/site-packages/keras/utils/traceback_utils.py", line 70, in error_handler
    raise e.with_traceback(filtered_tb) from None
  File "/p/software/juwelsbooster/stages/2023/software/TensorFlow/2.11.0-foss-2022a-CUDA-11.7/lib/python3.10/site-packages/tensorflow/python/framework/ops.py", line 1967, in _create_c_op
    raise ValueError(e.message)
ValueError: Exception encountered when calling layer "max_pooling2d_3" (type MaxPooling2D).

Negative dimension size caused by subtracting 2 from 1 for '{{node max_pooling2d_3/MaxPool}} = MaxPool[T=DT_FLOAT, data_format="NHWC", explicit_paddings=[], ksize=[1, 2, 2, 1], padding="VALID", strides=[1, 2, 2, 1]](Placeholder)' with input shapes: [?,1,3,512].

Call arguments received by layer "max_pooling2d_3" (type MaxPooling2D):
  • inputs=tf.Tensor(shape=(None, 1, 3, 512), dtype=float32)
srun: error: jwb0661: task 0: Exited with exit code 1
srun: Job 10090951 step creation still disabled, retrying (Requested nodes are busy)
srun: Job 10090951 step creation still disabled, retrying (Requested nodes are busy)
srun: Job 10090951 step creation temporarily disabled, retrying (Requested nodes are busy)
srun: Job 10090951 step creation still disabled, retrying (Requested nodes are busy)
srun: Job 10090951 step creation still disabled, retrying (Requested nodes are busy)
srun: Job 10090951 step creation still disabled, retrying (Requested nodes are busy)
srun: Job 10090951 step creation still disabled, retrying (Requested nodes are busy)
srun: Job 10090951 step creation still disabled, retrying (Requested nodes are busy)
srun: Step created for job 10090951
srun: error: jwb1019: task 0: Exited with exit code 1
srun: Job 10090951 step creation still disabled, retrying (Requested nodes are busy)
srun: Job 10090951 step creation still disabled, retrying (Requested nodes are busy)
srun: Job 10090951 step creation still disabled, retrying (Requested nodes are busy)
srun: Job 10090951 step creation still disabled, retrying (Requested nodes are busy)
srun: Job 10090951 step creation still disabled, retrying (Requested nodes are busy)
srun: Job 10090951 step creation still disabled, retrying (Requested nodes are busy)
srun: Job 10090951 step creation still disabled, retrying (Requested nodes are busy)
srun: Step created for job 10090951
Traceback (most recent call last):
  File "/p/project1/cesmtst/patakchiyousefi1/CODES-MS3/FORECASTLEAD/DL_TRAIN.py", line 97, in <module>
    model = func_train.UNET(xpixels, ypixels, n_channels, Filters, dropout, unet_type)
  File "/p/project1/cesmtst/patakchiyousefi1/CODES-MS3/FORECASTLEAD/func_train.py", line 201, in UNET
    p4 = tf.keras.layers.MaxPooling2D((2, 2))(c4)
  File "/p/software/juwelsbooster/stages/2023/software/TensorFlow/2.11.0-foss-2022a-CUDA-11.7/lib/python3.10/site-packages/keras/utils/traceback_utils.py", line 70, in error_handler
    raise e.with_traceback(filtered_tb) from None
  File "/p/software/juwelsbooster/stages/2023/software/TensorFlow/2.11.0-foss-2022a-CUDA-11.7/lib/python3.10/site-packages/tensorflow/python/framework/ops.py", line 1967, in _create_c_op
    raise ValueError(e.message)
ValueError: Exception encountered when calling layer "max_pooling2d_3" (type MaxPooling2D).

Negative dimension size caused by subtracting 2 from 1 for '{{node max_pooling2d_3/MaxPool}} = MaxPool[T=DT_FLOAT, data_format="NHWC", explicit_paddings=[], ksize=[1, 2, 2, 1], padding="VALID", strides=[1, 2, 2, 1]](Placeholder)' with input shapes: [?,1,3,512].

Call arguments received by layer "max_pooling2d_3" (type MaxPooling2D):
  • inputs=tf.Tensor(shape=(None, 1, 3, 512), dtype=float32)
Traceback (most recent call last):
  File "/p/project1/cesmtst/patakchiyousefi1/CODES-MS3/FORECASTLEAD/DL_TRAIN.py", line 97, in <module>
    model = func_train.UNET(xpixels, ypixels, n_channels, Filters, dropout, unet_type)
  File "/p/project1/cesmtst/patakchiyousefi1/CODES-MS3/FORECASTLEAD/func_train.py", line 201, in UNET
    p4 = tf.keras.layers.MaxPooling2D((2, 2))(c4)
  File "/p/software/juwelsbooster/stages/2023/software/TensorFlow/2.11.0-foss-2022a-CUDA-11.7/lib/python3.10/site-packages/keras/utils/traceback_utils.py", line 70, in error_handler
2024-07-26 10:16:16.878016: I tensorflow/core/common_runtime/gpu/gpu_device.cc:1613] Created device /job:localhost/replica:0/task:0/device:GPU:0 with 38364 MB memory:  -> device: 0, name: NVIDIA A100-SXM4-40GB, pci bus id: 0000:03:00.0, compute capability: 8.0
    raise e.with_traceback(filtered_tb) from None
  File "/p/software/juwelsbooster/stages/2023/software/TensorFlow/2.11.0-foss-2022a-CUDA-11.7/lib/python3.10/site-packages/tensorflow/python/framework/ops.py", line 1967, in _create_c_op
    raise ValueError(e.message)
ValueError: Exception encountered when calling layer "max_pooling2d_3" (type MaxPooling2D).

Negative dimension size caused by subtracting 2 from 1 for '{{node max_pooling2d_3/MaxPool}} = MaxPool[T=DT_FLOAT, data_format="NHWC", explicit_paddings=[], ksize=[1, 2, 2, 1], padding="VALID", strides=[1, 2, 2, 1]](Placeholder)' with input shapes: [?,1,3,512].

Call arguments received by layer "max_pooling2d_3" (type MaxPooling2D):
  • inputs=tf.Tensor(shape=(None, 1, 3, 512), dtype=float32)
2024-07-26 10:16:16.880720: I tensorflow/core/common_runtime/gpu/gpu_device.cc:1613] Created device /job:localhost/replica:0/task:0/device:GPU:1 with 38364 MB memory:  -> device: 1, name: NVIDIA A100-SXM4-40GB, pci bus id: 0000:44:00.0, compute capability: 8.0
2024-07-26 10:16:16.884044: I tensorflow/core/common_runtime/gpu/gpu_device.cc:1613] Created device /job:localhost/replica:0/task:0/device:GPU:2 with 38364 MB memory:  -> device: 2, name: NVIDIA A100-SXM4-40GB, pci bus id: 0000:84:00.0, compute capability: 8.0
2024-07-26 10:16:16.885565: I tensorflow/core/common_runtime/gpu/gpu_device.cc:1613] Created device /job:localhost/replica:0/task:0/device:GPU:3 with 38364 MB memory:  -> device: 3, name: NVIDIA A100-SXM4-40GB, pci bus id: 0000:c4:00.0, compute capability: 8.0
srun: error: jwb0381: task 0: Exited with exit code 1
srun: Job 10090951 step creation still disabled, retrying (Requested nodes are busy)
srun: Job 10090951 step creation still disabled, retrying (Requested nodes are busy)
srun: Job 10090951 step creation still disabled, retrying (Requested nodes are busy)
srun: Job 10090951 step creation still disabled, retrying (Requested nodes are busy)
srun: Job 10090951 step creation still disabled, retrying (Requested nodes are busy)
srun: Job 10090951 step creation still disabled, retrying (Requested nodes are busy)
srun: Job 10090951 step creation temporarily disabled, retrying (Requested nodes are busy)
srun: Step created for job 10090951
srun: error: jwb1022: task 0: Exited with exit code 1
srun: Job 10090951 step creation still disabled, retrying (Requested nodes are busy)
srun: Job 10090951 step creation still disabled, retrying (Requested nodes are busy)
srun: Job 10090951 step creation still disabled, retrying (Requested nodes are busy)
srun: Job 10090951 step creation still disabled, retrying (Requested nodes are busy)
srun: Job 10090951 step creation still disabled, retrying (Requested nodes are busy)
srun: Job 10090951 step creation still disabled, retrying (Requested nodes are busy)
srun: Step created for job 10090951
Traceback (most recent call last):
  File "/p/project1/cesmtst/patakchiyousefi1/CODES-MS3/FORECASTLEAD/DL_TRAIN.py", line 97, in <module>
    model = func_train.UNET(xpixels, ypixels, n_channels, Filters, dropout, unet_type)
  File "/p/project1/cesmtst/patakchiyousefi1/CODES-MS3/FORECASTLEAD/func_train.py", line 201, in UNET
    p4 = tf.keras.layers.MaxPooling2D((2, 2))(c4)
  File "/p/software/juwelsbooster/stages/2023/software/TensorFlow/2.11.0-foss-2022a-CUDA-11.7/lib/python3.10/site-packages/keras/utils/traceback_utils.py", line 70, in error_handler
    raise e.with_traceback(filtered_tb) from None
  File "/p/software/juwelsbooster/stages/2023/software/TensorFlow/2.11.0-foss-2022a-CUDA-11.7/lib/python3.10/site-packages/tensorflow/python/framework/ops.py", line 1967, in _create_c_op
    raise ValueError(e.message)
ValueError: Exception encountered when calling layer "max_pooling2d_3" (type MaxPooling2D).

Negative dimension size caused by subtracting 2 from 1 for '{{node max_pooling2d_3/MaxPool}} = MaxPool[T=DT_FLOAT, data_format="NHWC", explicit_paddings=[], ksize=[1, 2, 2, 1], padding="VALID", strides=[1, 2, 2, 1]](Placeholder)' with input shapes: [?,1,3,512].

Call arguments received by layer "max_pooling2d_3" (type MaxPooling2D):
  • inputs=tf.Tensor(shape=(None, 1, 3, 512), dtype=float32)
Traceback (most recent call last):
  File "/p/project1/cesmtst/patakchiyousefi1/CODES-MS3/FORECASTLEAD/DL_TRAIN.py", line 97, in <module>
    model = func_train.UNET(xpixels, ypixels, n_channels, Filters, dropout, unet_type)
  File "/p/project1/cesmtst/patakchiyousefi1/CODES-MS3/FORECASTLEAD/func_train.py", line 201, in UNET
    p4 = tf.keras.layers.MaxPooling2D((2, 2))(c4)
  File "/p/software/juwelsbooster/stages/2023/software/TensorFlow/2.11.0-foss-2022a-CUDA-11.7/lib/python3.10/site-packages/keras/utils/traceback_utils.py", line 70, in error_handler
    raise e.with_traceback(filtered_tb) from None
  File "/p/software/juwelsbooster/stages/2023/software/TensorFlow/2.11.0-foss-2022a-CUDA-11.7/lib/python3.10/site-packages/tensorflow/python/framework/ops.py", line 1967, in _create_c_op
    raise ValueError(e.message)
ValueError: Exception encountered when calling layer "max_pooling2d_3" (type MaxPooling2D).

Negative dimension size caused by subtracting 2 from 1 for '{{node max_pooling2d_3/MaxPool}} = MaxPool[T=DT_FLOAT, data_format="NHWC", explicit_paddings=[], ksize=[1, 2, 2, 1], padding="VALID", strides=[1, 2, 2, 1]](Placeholder)' with input shapes: [?,1,3,512].

Call arguments received by layer "max_pooling2d_3" (type MaxPooling2D):
  • inputs=tf.Tensor(shape=(None, 1, 3, 512), dtype=float32)
2024-07-26 10:16:17.510061: I tensorflow/core/common_runtime/gpu/gpu_device.cc:1613] Created device /job:localhost/replica:0/task:0/device:GPU:0 with 38364 MB memory:  -> device: 0, name: NVIDIA A100-SXM4-40GB, pci bus id: 0000:03:00.0, compute capability: 8.0
2024-07-26 10:16:17.513043: I tensorflow/core/common_runtime/gpu/gpu_device.cc:1613] Created device /job:localhost/replica:0/task:0/device:GPU:1 with 38364 MB memory:  -> device: 1, name: NVIDIA A100-SXM4-40GB, pci bus id: 0000:44:00.0, compute capability: 8.0
2024-07-26 10:16:17.514695: I tensorflow/core/common_runtime/gpu/gpu_device.cc:1613] Created device /job:localhost/replica:0/task:0/device:GPU:2 with 38364 MB memory:  -> device: 2, name: NVIDIA A100-SXM4-40GB, pci bus id: 0000:84:00.0, compute capability: 8.0
2024-07-26 10:16:17.516470: I tensorflow/core/common_runtime/gpu/gpu_device.cc:1613] Created device /job:localhost/replica:0/task:0/device:GPU:3 with 38364 MB memory:  -> device: 3, name: NVIDIA A100-SXM4-40GB, pci bus id: 0000:c4:00.0, compute capability: 8.0
srun: error: jwb0666: task 0: Exited with exit code 1
srun: Job 10090951 step creation still disabled, retrying (Requested nodes are busy)
srun: Job 10090951 step creation still disabled, retrying (Requested nodes are busy)
srun: Job 10090951 step creation still disabled, retrying (Requested nodes are busy)
srun: Job 10090951 step creation still disabled, retrying (Requested nodes are busy)
srun: Job 10090951 step creation still disabled, retrying (Requested nodes are busy)
srun: Job 10090951 step creation temporarily disabled, retrying (Requested nodes are busy)
srun: Step created for job 10090951
Traceback (most recent call last):
  File "/p/project1/cesmtst/patakchiyousefi1/CODES-MS3/FORECASTLEAD/DL_TRAIN.py", line 97, in <module>
    model = func_train.UNET(xpixels, ypixels, n_channels, Filters, dropout, unet_type)
  File "/p/project1/cesmtst/patakchiyousefi1/CODES-MS3/FORECASTLEAD/func_train.py", line 201, in UNET
    p4 = tf.keras.layers.MaxPooling2D((2, 2))(c4)
  File "/p/software/juwelsbooster/stages/2023/software/TensorFlow/2.11.0-foss-2022a-CUDA-11.7/lib/python3.10/site-packages/keras/utils/traceback_utils.py", line 70, in error_handler
    raise e.with_traceback(filtered_tb) from None
  File "/p/software/juwelsbooster/stages/2023/software/TensorFlow/2.11.0-foss-2022a-CUDA-11.7/lib/python3.10/site-packages/tensorflow/python/framework/ops.py", line 1967, in _create_c_op
    raise ValueError(e.message)
ValueError: Exception encountered when calling layer "max_pooling2d_3" (type MaxPooling2D).

Negative dimension size caused by subtracting 2 from 1 for '{{node max_pooling2d_3/MaxPool}} = MaxPool[T=DT_FLOAT, data_format="NHWC", explicit_paddings=[], ksize=[1, 2, 2, 1], padding="VALID", strides=[1, 2, 2, 1]](Placeholder)' with input shapes: [?,1,3,512].

Call arguments received by layer "max_pooling2d_3" (type MaxPooling2D):
  • inputs=tf.Tensor(shape=(None, 1, 3, 512), dtype=float32)
2024-07-26 10:16:17.830875: I tensorflow/core/common_runtime/gpu/gpu_device.cc:1613] Created device /job:localhost/replica:0/task:0/device:GPU:0 with 38364 MB memory:  -> device: 0, name: NVIDIA A100-SXM4-40GB, pci bus id: 0000:03:00.0, compute capability: 8.0
2024-07-26 10:16:17.832788: I tensorflow/core/common_runtime/gpu/gpu_device.cc:1613] Created device /job:localhost/replica:0/task:0/device:GPU:1 with 38364 MB memory:  -> device: 1, name: NVIDIA A100-SXM4-40GB, pci bus id: 0000:44:00.0, compute capability: 8.0
2024-07-26 10:16:17.834531: I tensorflow/core/common_runtime/gpu/gpu_device.cc:1613] Created device /job:localhost/replica:0/task:0/device:GPU:2 with 38364 MB memory:  -> device: 2, name: NVIDIA A100-SXM4-40GB, pci bus id: 0000:84:00.0, compute capability: 8.0
2024-07-26 10:16:17.836008: I tensorflow/core/common_runtime/gpu/gpu_device.cc:1613] Created device /job:localhost/replica:0/task:0/device:GPU:3 with 38364 MB memory:  -> device: 3, name: NVIDIA A100-SXM4-40GB, pci bus id: 0000:c4:00.0, compute capability: 8.0
srun: error: jwb0383: task 0: Exited with exit code 1
srun: Job 10090951 step creation still disabled, retrying (Requested nodes are busy)
srun: Job 10090951 step creation still disabled, retrying (Requested nodes are busy)
srun: Job 10090951 step creation still disabled, retrying (Requested nodes are busy)
srun: Job 10090951 step creation temporarily disabled, retrying (Requested nodes are busy)
srun: Job 10090951 step creation still disabled, retrying (Requested nodes are busy)
srun: Job 10090951 step creation still disabled, retrying (Requested nodes are busy)
srun: Step created for job 10090951
srun: error: jwb0667: task 0: Exited with exit code 1
srun: Job 10090951 step creation still disabled, retrying (Requested nodes are busy)
srun: Job 10090951 step creation still disabled, retrying (Requested nodes are busy)
srun: Job 10090951 step creation still disabled, retrying (Requested nodes are busy)
srun: Job 10090951 step creation still disabled, retrying (Requested nodes are busy)
srun: Job 10090951 step creation still disabled, retrying (Requested nodes are busy)
srun: Step created for job 10090951
Traceback (most recent call last):
  File "/p/project1/cesmtst/patakchiyousefi1/CODES-MS3/FORECASTLEAD/DL_TRAIN.py", line 97, in <module>
    model = func_train.UNET(xpixels, ypixels, n_channels, Filters, dropout, unet_type)
  File "/p/project1/cesmtst/patakchiyousefi1/CODES-MS3/FORECASTLEAD/func_train.py", line 201, in UNET
    p4 = tf.keras.layers.MaxPooling2D((2, 2))(c4)
  File "/p/software/juwelsbooster/stages/2023/software/TensorFlow/2.11.0-foss-2022a-CUDA-11.7/lib/python3.10/site-packages/keras/utils/traceback_utils.py", line 70, in error_handler
    raise e.with_traceback(filtered_tb) from None
  File "/p/software/juwelsbooster/stages/2023/software/TensorFlow/2.11.0-foss-2022a-CUDA-11.7/lib/python3.10/site-packages/tensorflow/python/framework/ops.py", line 1967, in _create_c_op
    raise ValueError(e.message)
ValueError: Exception encountered when calling layer "max_pooling2d_3" (type MaxPooling2D).

Negative dimension size caused by subtracting 2 from 1 for '{{node max_pooling2d_3/MaxPool}} = MaxPool[T=DT_FLOAT, data_format="NHWC", explicit_paddings=[], ksize=[1, 2, 2, 1], padding="VALID", strides=[1, 2, 2, 1]](Placeholder)' with input shapes: [?,1,3,512].

Call arguments received by layer "max_pooling2d_3" (type MaxPooling2D):
  • inputs=tf.Tensor(shape=(None, 1, 3, 512), dtype=float32)
srun: error: jwb0384: task 0: Exited with exit code 1
srun: Job 10090951 step creation still disabled, retrying (Requested nodes are busy)
srun: Job 10090951 step creation still disabled, retrying (Requested nodes are busy)
srun: Job 10090951 step creation still disabled, retrying (Requested nodes are busy)
srun: Job 10090951 step creation still disabled, retrying (Requested nodes are busy)
srun: Job 10090951 step creation temporarily disabled, retrying (Requested nodes are busy)
srun: Step created for job 10090951
Traceback (most recent call last):
  File "/p/project1/cesmtst/patakchiyousefi1/CODES-MS3/FORECASTLEAD/DL_TRAIN.py", line 97, in <module>
    model = func_train.UNET(xpixels, ypixels, n_channels, Filters, dropout, unet_type)
  File "/p/project1/cesmtst/patakchiyousefi1/CODES-MS3/FORECASTLEAD/func_train.py", line 201, in UNET
    p4 = tf.keras.layers.MaxPooling2D((2, 2))(c4)
  File "/p/software/juwelsbooster/stages/2023/software/TensorFlow/2.11.0-foss-2022a-CUDA-11.7/lib/python3.10/site-packages/keras/utils/traceback_utils.py", line 70, in error_handler
    raise e.with_traceback(filtered_tb) from None
  File "/p/software/juwelsbooster/stages/2023/software/TensorFlow/2.11.0-foss-2022a-CUDA-11.7/lib/python3.10/site-packages/tensorflow/python/framework/ops.py", line 1967, in _create_c_op
    raise ValueError(e.message)
ValueError: Exception encountered when calling layer "max_pooling2d_3" (type MaxPooling2D).

Negative dimension size caused by subtracting 2 from 1 for '{{node max_pooling2d_3/MaxPool}} = MaxPool[T=DT_FLOAT, data_format="NHWC", explicit_paddings=[], ksize=[1, 2, 2, 1], padding="VALID", strides=[1, 2, 2, 1]](Placeholder)' with input shapes: [?,1,3,512].

Call arguments received by layer "max_pooling2d_3" (type MaxPooling2D):
  • inputs=tf.Tensor(shape=(None, 1, 3, 512), dtype=float32)
srun: error: jwb0668: task 0: Exited with exit code 1
srun: Job 10090951 step creation still disabled, retrying (Requested nodes are busy)
srun: Job 10090951 step creation still disabled, retrying (Requested nodes are busy)
srun: Job 10090951 step creation still disabled, retrying (Requested nodes are busy)
srun: Job 10090951 step creation still disabled, retrying (Requested nodes are busy)
srun: Step created for job 10090951
2024-07-26 10:16:19.048607: I tensorflow/core/common_runtime/gpu/gpu_device.cc:1613] Created device /job:localhost/replica:0/task:0/device:GPU:0 with 38364 MB memory:  -> device: 0, name: NVIDIA A100-SXM4-40GB, pci bus id: 0000:03:00.0, compute capability: 8.0
2024-07-26 10:16:19.050452: I tensorflow/core/common_runtime/gpu/gpu_device.cc:1613] Created device /job:localhost/replica:0/task:0/device:GPU:1 with 38364 MB memory:  -> device: 1, name: NVIDIA A100-SXM4-40GB, pci bus id: 0000:44:00.0, compute capability: 8.0
2024-07-26 10:16:19.052758: I tensorflow/core/common_runtime/gpu/gpu_device.cc:1613] Created device /job:localhost/replica:0/task:0/device:GPU:2 with 38364 MB memory:  -> device: 2, name: NVIDIA A100-SXM4-40GB, pci bus id: 0000:84:00.0, compute capability: 8.0
2024-07-26 10:16:19.055129: I tensorflow/core/common_runtime/gpu/gpu_device.cc:1613] Created device /job:localhost/replica:0/task:0/device:GPU:3 with 38364 MB memory:  -> device: 3, name: NVIDIA A100-SXM4-40GB, pci bus id: 0000:c4:00.0, compute capability: 8.0
srun: error: jwb0669: task 0: Exited with exit code 1
srun: Job 10090951 step creation still disabled, retrying (Requested nodes are busy)
srun: Job 10090951 step creation still disabled, retrying (Requested nodes are busy)
srun: Job 10090951 step creation still disabled, retrying (Requested nodes are busy)
srun: Job 10090951 step creation temporarily disabled, retrying (Requested nodes are busy)
srun: Step created for job 10090951
srun: error: jwb0382: task 0: Exited with exit code 1
srun: Job 10090951 step creation still disabled, retrying (Requested nodes are busy)
srun: Job 10090951 step creation still disabled, retrying (Requested nodes are busy)
srun: Job 10090951 step creation still disabled, retrying (Requested nodes are busy)
srun: Step created for job 10090951
srun: error: jwb0320: task 0: Exited with exit code 1
srun: Job 10090951 step creation still disabled, retrying (Requested nodes are busy)
srun: Job 10090951 step creation still disabled, retrying (Requested nodes are busy)
srun: Step created for job 10090951
Traceback (most recent call last):
  File "/p/project1/cesmtst/patakchiyousefi1/CODES-MS3/FORECASTLEAD/DL_TRAIN.py", line 97, in <module>
    model = func_train.UNET(xpixels, ypixels, n_channels, Filters, dropout, unet_type)
  File "/p/project1/cesmtst/patakchiyousefi1/CODES-MS3/FORECASTLEAD/func_train.py", line 201, in UNET
    p4 = tf.keras.layers.MaxPooling2D((2, 2))(c4)
  File "/p/software/juwelsbooster/stages/2023/software/TensorFlow/2.11.0-foss-2022a-CUDA-11.7/lib/python3.10/site-packages/keras/utils/traceback_utils.py", line 70, in error_handler
    raise e.with_traceback(filtered_tb) from None
  File "/p/software/juwelsbooster/stages/2023/software/TensorFlow/2.11.0-foss-2022a-CUDA-11.7/lib/python3.10/site-packages/tensorflow/python/framework/ops.py", line 1967, in _create_c_op
    raise ValueError(e.message)
ValueError: Exception encountered when calling layer "max_pooling2d_3" (type MaxPooling2D).

Negative dimension size caused by subtracting 2 from 1 for '{{node max_pooling2d_3/MaxPool}} = MaxPool[T=DT_FLOAT, data_format="NHWC", explicit_paddings=[], ksize=[1, 2, 2, 1], padding="VALID", strides=[1, 2, 2, 1]](Placeholder)' with input shapes: [?,1,3,512].

Call arguments received by layer "max_pooling2d_3" (type MaxPooling2D):
  • inputs=tf.Tensor(shape=(None, 1, 3, 512), dtype=float32)
2024-07-26 10:16:19.593352: I tensorflow/core/common_runtime/gpu/gpu_device.cc:1613] Created device /job:localhost/replica:0/task:0/device:GPU:0 with 38364 MB memory:  -> device: 0, name: NVIDIA A100-SXM4-40GB, pci bus id: 0000:03:00.0, compute capability: 8.0
2024-07-26 10:16:19.632973: I tensorflow/core/common_runtime/gpu/gpu_device.cc:1613] Created device /job:localhost/replica:0/task:0/device:GPU:0 with 38364 MB memory:  -> device: 0, name: NVIDIA A100-SXM4-40GB, pci bus id: 0000:03:00.0, compute capability: 8.0
2024-07-26 10:16:19.595100: I tensorflow/core/common_runtime/gpu/gpu_device.cc:1613] Created device /job:localhost/replica:0/task:0/device:GPU:1 with 38364 MB memory:  -> device: 1, name: NVIDIA A100-SXM4-40GB, pci bus id: 0000:44:00.0, compute capability: 8.0
2024-07-26 10:16:19.596805: I tensorflow/core/common_runtime/gpu/gpu_device.cc:1613] Created device /job:localhost/replica:0/task:0/device:GPU:2 with 38364 MB memory:  -> device: 2, name: NVIDIA A100-SXM4-40GB, pci bus id: 0000:84:00.0, compute capability: 8.0
2024-07-26 10:16:19.599460: I tensorflow/core/common_runtime/gpu/gpu_device.cc:1613] Created device /job:localhost/replica:0/task:0/device:GPU:3 with 38364 MB memory:  -> device: 3, name: NVIDIA A100-SXM4-40GB, pci bus id: 0000:c4:00.0, compute capability: 8.0
2024-07-26 10:16:19.636488: I tensorflow/core/common_runtime/gpu/gpu_device.cc:1613] Created device /job:localhost/replica:0/task:0/device:GPU:1 with 38364 MB memory:  -> device: 1, name: NVIDIA A100-SXM4-40GB, pci bus id: 0000:44:00.0, compute capability: 8.0
2024-07-26 10:16:19.638046: I tensorflow/core/common_runtime/gpu/gpu_device.cc:1613] Created device /job:localhost/replica:0/task:0/device:GPU:2 with 38364 MB memory:  -> device: 2, name: NVIDIA A100-SXM4-40GB, pci bus id: 0000:84:00.0, compute capability: 8.0
2024-07-26 10:16:19.639503: I tensorflow/core/common_runtime/gpu/gpu_device.cc:1613] Created device /job:localhost/replica:0/task:0/device:GPU:3 with 38364 MB memory:  -> device: 3, name: NVIDIA A100-SXM4-40GB, pci bus id: 0000:c4:00.0, compute capability: 8.0
2024-07-26 10:16:19.810034: I tensorflow/core/common_runtime/gpu/gpu_device.cc:1613] Created device /job:localhost/replica:0/task:0/device:GPU:0 with 38364 MB memory:  -> device: 0, name: NVIDIA A100-SXM4-40GB, pci bus id: 0000:03:00.0, compute capability: 8.0
2024-07-26 10:16:19.811903: I tensorflow/core/common_runtime/gpu/gpu_device.cc:1613] Created device /job:localhost/replica:0/task:0/device:GPU:1 with 38364 MB memory:  -> device: 1, name: NVIDIA A100-SXM4-40GB, pci bus id: 0000:44:00.0, compute capability: 8.0
2024-07-26 10:16:19.813539: I tensorflow/core/common_runtime/gpu/gpu_device.cc:1613] Created device /job:localhost/replica:0/task:0/device:GPU:2 with 38364 MB memory:  -> device: 2, name: NVIDIA A100-SXM4-40GB, pci bus id: 0000:84:00.0, compute capability: 8.0
2024-07-26 10:16:19.816276: I tensorflow/core/common_runtime/gpu/gpu_device.cc:1613] Created device /job:localhost/replica:0/task:0/device:GPU:3 with 38364 MB memory:  -> device: 3, name: NVIDIA A100-SXM4-40GB, pci bus id: 0000:c4:00.0, compute capability: 8.0
2024-07-26 10:16:19.893600: I tensorflow/core/common_runtime/gpu/gpu_device.cc:1613] Created device /job:localhost/replica:0/task:0/device:GPU:0 with 38364 MB memory:  -> device: 0, name: NVIDIA A100-SXM4-40GB, pci bus id: 0000:03:00.0, compute capability: 8.0
2024-07-26 10:16:19.895544: I tensorflow/core/common_runtime/gpu/gpu_device.cc:1613] Created device /job:localhost/replica:0/task:0/device:GPU:1 with 38364 MB memory:  -> device: 1, name: NVIDIA A100-SXM4-40GB, pci bus id: 0000:44:00.0, compute capability: 8.0
2024-07-26 10:16:19.897197: I tensorflow/core/common_runtime/gpu/gpu_device.cc:1613] Created device /job:localhost/replica:0/task:0/device:GPU:2 with 38364 MB memory:  -> device: 2, name: NVIDIA A100-SXM4-40GB, pci bus id: 0000:84:00.0, compute capability: 8.0
2024-07-26 10:16:19.898825: I tensorflow/core/common_runtime/gpu/gpu_device.cc:1613] Created device /job:localhost/replica:0/task:0/device:GPU:3 with 38364 MB memory:  -> device: 3, name: NVIDIA A100-SXM4-40GB, pci bus id: 0000:c4:00.0, compute capability: 8.0
Traceback (most recent call last):
  File "/p/project1/cesmtst/patakchiyousefi1/CODES-MS3/FORECASTLEAD/DL_TRAIN.py", line 97, in <module>
    model = func_train.UNET(xpixels, ypixels, n_channels, Filters, dropout, unet_type)
  File "/p/project1/cesmtst/patakchiyousefi1/CODES-MS3/FORECASTLEAD/func_train.py", line 201, in UNET
    p4 = tf.keras.layers.MaxPooling2D((2, 2))(c4)
  File "/p/software/juwelsbooster/stages/2023/software/TensorFlow/2.11.0-foss-2022a-CUDA-11.7/lib/python3.10/site-packages/keras/utils/traceback_utils.py", line 70, in error_handler
    raise e.with_traceback(filtered_tb) from None
  File "/p/software/juwelsbooster/stages/2023/software/TensorFlow/2.11.0-foss-2022a-CUDA-11.7/lib/python3.10/site-packages/tensorflow/python/framework/ops.py", line 1967, in _create_c_op
    raise ValueError(e.message)
ValueError: Exception encountered when calling layer "max_pooling2d_3" (type MaxPooling2D).

Negative dimension size caused by subtracting 2 from 1 for '{{node max_pooling2d_3/MaxPool}} = MaxPool[T=DT_FLOAT, data_format="NHWC", explicit_paddings=[], ksize=[1, 2, 2, 1], padding="VALID", strides=[1, 2, 2, 1]](Placeholder)' with input shapes: [?,1,3,512].

Call arguments received by layer "max_pooling2d_3" (type MaxPooling2D):
  • inputs=tf.Tensor(shape=(None, 1, 3, 512), dtype=float32)
srun: error: jwb0324: task 0: Exited with exit code 1
srun: Job 10090951 step creation still disabled, retrying (Requested nodes are busy)
srun: Job 10090951 step creation temporarily disabled, retrying (Requested nodes are busy)
srun: Job 10090951 step creation temporarily disabled, retrying (Requested nodes are busy)
srun: Step created for job 10090951
2024-07-26 10:16:20.339953: I tensorflow/core/common_runtime/gpu/gpu_device.cc:1613] Created device /job:localhost/replica:0/task:0/device:GPU:0 with 38364 MB memory:  -> device: 0, name: NVIDIA A100-SXM4-40GB, pci bus id: 0000:03:00.0, compute capability: 8.0
2024-07-26 10:16:20.341918: I tensorflow/core/common_runtime/gpu/gpu_device.cc:1613] Created device /job:localhost/replica:0/task:0/device:GPU:1 with 38364 MB memory:  -> device: 1, name: NVIDIA A100-SXM4-40GB, pci bus id: 0000:44:00.0, compute capability: 8.0
2024-07-26 10:16:20.344716: I tensorflow/core/common_runtime/gpu/gpu_device.cc:1613] Created device /job:localhost/replica:0/task:0/device:GPU:2 with 38364 MB memory:  -> device: 2, name: NVIDIA A100-SXM4-40GB, pci bus id: 0000:84:00.0, compute capability: 8.0
2024-07-26 10:16:20.346367: I tensorflow/core/common_runtime/gpu/gpu_device.cc:1613] Created device /job:localhost/replica:0/task:0/device:GPU:3 with 38364 MB memory:  -> device: 3, name: NVIDIA A100-SXM4-40GB, pci bus id: 0000:c4:00.0, compute capability: 8.0
srun: error: jwb0344: task 0: Exited with exit code 1
srun: Job 10090951 step creation still disabled, retrying (Requested nodes are busy)
srun: Job 10090951 step creation still disabled, retrying (Requested nodes are busy)
srun: Step created for job 10090951
Traceback (most recent call last):
  File "/p/project1/cesmtst/patakchiyousefi1/CODES-MS3/FORECASTLEAD/DL_TRAIN.py", line 97, in <module>
    model = func_train.UNET(xpixels, ypixels, n_channels, Filters, dropout, unet_type)
  File "/p/project1/cesmtst/patakchiyousefi1/CODES-MS3/FORECASTLEAD/func_train.py", line 201, in UNET
    p4 = tf.keras.layers.MaxPooling2D((2, 2))(c4)
  File "/p/software/juwelsbooster/stages/2023/software/TensorFlow/2.11.0-foss-2022a-CUDA-11.7/lib/python3.10/site-packages/keras/utils/traceback_utils.py", line 70, in error_handler
    raise e.with_traceback(filtered_tb) from None
  File "/p/software/juwelsbooster/stages/2023/software/TensorFlow/2.11.0-foss-2022a-CUDA-11.7/lib/python3.10/site-packages/tensorflow/python/framework/ops.py", line 1967, in _create_c_op
    raise ValueError(e.message)
ValueError: Exception encountered when calling layer "max_pooling2d_3" (type MaxPooling2D).

Negative dimension size caused by subtracting 2 from 1 for '{{node max_pooling2d_3/MaxPool}} = MaxPool[T=DT_FLOAT, data_format="NHWC", explicit_paddings=[], ksize=[1, 2, 2, 1], padding="VALID", strides=[1, 2, 2, 1]](Placeholder)' with input shapes: [?,1,3,512].

Call arguments received by layer "max_pooling2d_3" (type MaxPooling2D):
  • inputs=tf.Tensor(shape=(None, 1, 3, 512), dtype=float32)
2024-07-26 10:16:20.729568: I tensorflow/core/common_runtime/gpu/gpu_device.cc:1613] Created device /job:localhost/replica:0/task:0/device:GPU:0 with 38364 MB memory:  -> device: 0, name: NVIDIA A100-SXM4-40GB, pci bus id: 0000:03:00.0, compute capability: 8.0
2024-07-26 10:16:20.731475: I tensorflow/core/common_runtime/gpu/gpu_device.cc:1613] Created device /job:localhost/replica:0/task:0/device:GPU:1 with 38364 MB memory:  -> device: 1, name: NVIDIA A100-SXM4-40GB, pci bus id: 0000:44:00.0, compute capability: 8.0
2024-07-26 10:16:20.734304: I tensorflow/core/common_runtime/gpu/gpu_device.cc:1613] Created device /job:localhost/replica:0/task:0/device:GPU:2 with 38364 MB memory:  -> device: 2, name: NVIDIA A100-SXM4-40GB, pci bus id: 0000:84:00.0, compute capability: 8.0
2024-07-26 10:16:20.735813: I tensorflow/core/common_runtime/gpu/gpu_device.cc:1613] Created device /job:localhost/replica:0/task:0/device:GPU:3 with 38364 MB memory:  -> device: 3, name: NVIDIA A100-SXM4-40GB, pci bus id: 0000:c4:00.0, compute capability: 8.0
2024-07-26 10:16:21.176783: I tensorflow/core/common_runtime/gpu/gpu_device.cc:1613] Created device /job:localhost/replica:0/task:0/device:GPU:0 with 38364 MB memory:  -> device: 0, name: NVIDIA A100-SXM4-40GB, pci bus id: 0000:03:00.0, compute capability: 8.0
2024-07-26 10:16:21.178497: I tensorflow/core/common_runtime/gpu/gpu_device.cc:1613] Created device /job:localhost/replica:0/task:0/device:GPU:1 with 38364 MB memory:  -> device: 1, name: NVIDIA A100-SXM4-40GB, pci bus id: 0000:44:00.0, compute capability: 8.0
2024-07-26 10:16:21.180285: I tensorflow/core/common_runtime/gpu/gpu_device.cc:1613] Created device /job:localhost/replica:0/task:0/device:GPU:2 with 38364 MB memory:  -> device: 2, name: NVIDIA A100-SXM4-40GB, pci bus id: 0000:84:00.0, compute capability: 8.0
2024-07-26 10:16:21.183126: I tensorflow/core/common_runtime/gpu/gpu_device.cc:1613] Created device /job:localhost/replica:0/task:0/device:GPU:3 with 38364 MB memory:  -> device: 3, name: NVIDIA A100-SXM4-40GB, pci bus id: 0000:c4:00.0, compute capability: 8.0
srun: error: jwb0346: task 0: Exited with exit code 1
srun: Job 10090951 step creation still disabled, retrying (Requested nodes are busy)
srun: Step created for job 10090951
2024-07-26 10:16:21.706414: I tensorflow/core/common_runtime/gpu/gpu_device.cc:1613] Created device /job:localhost/replica:0/task:0/device:GPU:0 with 38364 MB memory:  -> device: 0, name: NVIDIA A100-SXM4-40GB, pci bus id: 0000:03:00.0, compute capability: 8.0
Traceback (most recent call last):
  File "/p/project1/cesmtst/patakchiyousefi1/CODES-MS3/FORECASTLEAD/DL_TRAIN.py", line 97, in <module>
    model = func_train.UNET(xpixels, ypixels, n_channels, Filters, dropout, unet_type)
  File "/p/project1/cesmtst/patakchiyousefi1/CODES-MS3/FORECASTLEAD/func_train.py", line 201, in UNET
    p4 = tf.keras.layers.MaxPooling2D((2, 2))(c4)
  File "/p/software/juwelsbooster/stages/2023/software/TensorFlow/2.11.0-foss-2022a-CUDA-11.7/lib/python3.10/site-packages/keras/utils/traceback_utils.py", line 70, in error_handler
    raise e.with_traceback(filtered_tb) from None
  File "/p/software/juwelsbooster/stages/2023/software/TensorFlow/2.11.0-foss-2022a-CUDA-11.7/lib/python3.10/site-packages/tensorflow/python/framework/ops.py", line 1967, in _create_c_op
    raise ValueError(e.message)
ValueError: Exception encountered when calling layer "max_pooling2d_3" (type MaxPooling2D).

Negative dimension size caused by subtracting 2 from 1 for '{{node max_pooling2d_3/MaxPool}} = MaxPool[T=DT_FLOAT, data_format="NHWC", explicit_paddings=[], ksize=[1, 2, 2, 1], padding="VALID", strides=[1, 2, 2, 1]](Placeholder)' with input shapes: [?,1,3,512].

Call arguments received by layer "max_pooling2d_3" (type MaxPooling2D):
  • inputs=tf.Tensor(shape=(None, 1, 3, 512), dtype=float32)
2024-07-26 10:16:21.709362: I tensorflow/core/common_runtime/gpu/gpu_device.cc:1613] Created device /job:localhost/replica:0/task:0/device:GPU:1 with 38364 MB memory:  -> device: 1, name: NVIDIA A100-SXM4-40GB, pci bus id: 0000:44:00.0, compute capability: 8.0
2024-07-26 10:16:21.711006: I tensorflow/core/common_runtime/gpu/gpu_device.cc:1613] Created device /job:localhost/replica:0/task:0/device:GPU:2 with 38364 MB memory:  -> device: 2, name: NVIDIA A100-SXM4-40GB, pci bus id: 0000:84:00.0, compute capability: 8.0
2024-07-26 10:16:21.713543: I tensorflow/core/common_runtime/gpu/gpu_device.cc:1613] Created device /job:localhost/replica:0/task:0/device:GPU:3 with 38364 MB memory:  -> device: 3, name: NVIDIA A100-SXM4-40GB, pci bus id: 0000:c4:00.0, compute capability: 8.0
srun: error: jwb0348: task 0: Exited with exit code 1
srun: error: jwb0349: task 0: Exited with exit code 1
Traceback (most recent call last):
  File "/p/project1/cesmtst/patakchiyousefi1/CODES-MS3/FORECASTLEAD/DL_TRAIN.py", line 97, in <module>
    model = func_train.UNET(xpixels, ypixels, n_channels, Filters, dropout, unet_type)
  File "/p/project1/cesmtst/patakchiyousefi1/CODES-MS3/FORECASTLEAD/func_train.py", line 201, in UNET
    p4 = tf.keras.layers.MaxPooling2D((2, 2))(c4)
  File "/p/software/juwelsbooster/stages/2023/software/TensorFlow/2.11.0-foss-2022a-CUDA-11.7/lib/python3.10/site-packages/keras/utils/traceback_utils.py", line 70, in error_handler
    raise e.with_traceback(filtered_tb) from None
  File "/p/software/juwelsbooster/stages/2023/software/TensorFlow/2.11.0-foss-2022a-CUDA-11.7/lib/python3.10/site-packages/tensorflow/python/framework/ops.py", line 1967, in _create_c_op
    raise ValueError(e.message)
ValueError: Exception encountered when calling layer "max_pooling2d_3" (type MaxPooling2D).

Negative dimension size caused by subtracting 2 from 1 for '{{node max_pooling2d_3/MaxPool}} = MaxPool[T=DT_FLOAT, data_format="NHWC", explicit_paddings=[], ksize=[1, 2, 2, 1], padding="VALID", strides=[1, 2, 2, 1]](Placeholder)' with input shapes: [?,1,3,512].

Call arguments received by layer "max_pooling2d_3" (type MaxPooling2D):
  • inputs=tf.Tensor(shape=(None, 1, 3, 512), dtype=float32)
Traceback (most recent call last):
  File "/p/project1/cesmtst/patakchiyousefi1/CODES-MS3/FORECASTLEAD/DL_TRAIN.py", line 97, in <module>
    model = func_train.UNET(xpixels, ypixels, n_channels, Filters, dropout, unet_type)
  File "/p/project1/cesmtst/patakchiyousefi1/CODES-MS3/FORECASTLEAD/func_train.py", line 201, in UNET
    p4 = tf.keras.layers.MaxPooling2D((2, 2))(c4)
  File "/p/software/juwelsbooster/stages/2023/software/TensorFlow/2.11.0-foss-2022a-CUDA-11.7/lib/python3.10/site-packages/keras/utils/traceback_utils.py", line 70, in error_handler
    raise e.with_traceback(filtered_tb) from None
  File "/p/software/juwelsbooster/stages/2023/software/TensorFlow/2.11.0-foss-2022a-CUDA-11.7/lib/python3.10/site-packages/tensorflow/python/framework/ops.py", line 1967, in _create_c_op
    raise ValueError(e.message)
ValueError: Exception encountered when calling layer "max_pooling2d_3" (type MaxPooling2D).

Negative dimension size caused by subtracting 2 from 1 for '{{node max_pooling2d_3/MaxPool}} = MaxPool[T=DT_FLOAT, data_format="NHWC", explicit_paddings=[], ksize=[1, 2, 2, 1], padding="VALID", strides=[1, 2, 2, 1]](Placeholder)' with input shapes: [?,1,3,512].

Call arguments received by layer "max_pooling2d_3" (type MaxPooling2D):
  • inputs=tf.Tensor(shape=(None, 1, 3, 512), dtype=float32)
Traceback (most recent call last):
  File "/p/project1/cesmtst/patakchiyousefi1/CODES-MS3/FORECASTLEAD/DL_TRAIN.py", line 97, in <module>
    model = func_train.UNET(xpixels, ypixels, n_channels, Filters, dropout, unet_type)
  File "/p/project1/cesmtst/patakchiyousefi1/CODES-MS3/FORECASTLEAD/func_train.py", line 201, in UNET
    p4 = tf.keras.layers.MaxPooling2D((2, 2))(c4)
  File "/p/software/juwelsbooster/stages/2023/software/TensorFlow/2.11.0-foss-2022a-CUDA-11.7/lib/python3.10/site-packages/keras/utils/traceback_utils.py", line 70, in error_handler
    raise e.with_traceback(filtered_tb) from None
  File "/p/software/juwelsbooster/stages/2023/software/TensorFlow/2.11.0-foss-2022a-CUDA-11.7/lib/python3.10/site-packages/tensorflow/python/framework/ops.py", line 1967, in _create_c_op
    raise ValueError(e.message)
ValueError: Exception encountered when calling layer "max_pooling2d_3" (type MaxPooling2D).

Negative dimension size caused by subtracting 2 from 1 for '{{node max_pooling2d_3/MaxPool}} = MaxPool[T=DT_FLOAT, data_format="NHWC", explicit_paddings=[], ksize=[1, 2, 2, 1], padding="VALID", strides=[1, 2, 2, 1]](Placeholder)' with input shapes: [?,1,3,512].

Call arguments received by layer "max_pooling2d_3" (type MaxPooling2D):
  • inputs=tf.Tensor(shape=(None, 1, 3, 512), dtype=float32)
Traceback (most recent call last):
  File "/p/project1/cesmtst/patakchiyousefi1/CODES-MS3/FORECASTLEAD/DL_TRAIN.py", line 97, in <module>
    model = func_train.UNET(xpixels, ypixels, n_channels, Filters, dropout, unet_type)
  File "/p/project1/cesmtst/patakchiyousefi1/CODES-MS3/FORECASTLEAD/func_train.py", line 201, in UNET
    p4 = tf.keras.layers.MaxPooling2D((2, 2))(c4)
  File "/p/software/juwelsbooster/stages/2023/software/TensorFlow/2.11.0-foss-2022a-CUDA-11.7/lib/python3.10/site-packages/keras/utils/traceback_utils.py", line 70, in error_handler
    raise e.with_traceback(filtered_tb) from None
  File "/p/software/juwelsbooster/stages/2023/software/TensorFlow/2.11.0-foss-2022a-CUDA-11.7/lib/python3.10/site-packages/tensorflow/python/framework/ops.py", line 1967, in _create_c_op
    raise ValueError(e.message)
ValueError: Exception encountered when calling layer "max_pooling2d_3" (type MaxPooling2D).

Negative dimension size caused by subtracting 2 from 1 for '{{node max_pooling2d_3/MaxPool}} = MaxPool[T=DT_FLOAT, data_format="NHWC", explicit_paddings=[], ksize=[1, 2, 2, 1], padding="VALID", strides=[1, 2, 2, 1]](Placeholder)' with input shapes: [?,1,3,512].

Call arguments received by layer "max_pooling2d_3" (type MaxPooling2D):
  • inputs=tf.Tensor(shape=(None, 1, 3, 512), dtype=float32)
Traceback (most recent call last):
  File "/p/project1/cesmtst/patakchiyousefi1/CODES-MS3/FORECASTLEAD/DL_TRAIN.py", line 97, in <module>
    model = func_train.UNET(xpixels, ypixels, n_channels, Filters, dropout, unet_type)
  File "/p/project1/cesmtst/patakchiyousefi1/CODES-MS3/FORECASTLEAD/func_train.py", line 201, in UNET
    p4 = tf.keras.layers.MaxPooling2D((2, 2))(c4)
  File "/p/software/juwelsbooster/stages/2023/software/TensorFlow/2.11.0-foss-2022a-CUDA-11.7/lib/python3.10/site-packages/keras/utils/traceback_utils.py", line 70, in error_handler
    raise e.with_traceback(filtered_tb) from None
  File "/p/software/juwelsbooster/stages/2023/software/TensorFlow/2.11.0-foss-2022a-CUDA-11.7/lib/python3.10/site-packages/tensorflow/python/framework/ops.py", line 1967, in _create_c_op
    raise ValueError(e.message)
ValueError: Exception encountered when calling layer "max_pooling2d_3" (type MaxPooling2D).

Negative dimension size caused by subtracting 2 from 1 for '{{node max_pooling2d_3/MaxPool}} = MaxPool[T=DT_FLOAT, data_format="NHWC", explicit_paddings=[], ksize=[1, 2, 2, 1], padding="VALID", strides=[1, 2, 2, 1]](Placeholder)' with input shapes: [?,1,3,512].

Call arguments received by layer "max_pooling2d_3" (type MaxPooling2D):
  • inputs=tf.Tensor(shape=(None, 1, 3, 512), dtype=float32)
Traceback (most recent call last):
  File "/p/project1/cesmtst/patakchiyousefi1/CODES-MS3/FORECASTLEAD/DL_TRAIN.py", line 97, in <module>
    model = func_train.UNET(xpixels, ypixels, n_channels, Filters, dropout, unet_type)
  File "/p/project1/cesmtst/patakchiyousefi1/CODES-MS3/FORECASTLEAD/func_train.py", line 201, in UNET
    p4 = tf.keras.layers.MaxPooling2D((2, 2))(c4)
  File "/p/software/juwelsbooster/stages/2023/software/TensorFlow/2.11.0-foss-2022a-CUDA-11.7/lib/python3.10/site-packages/keras/utils/traceback_utils.py", line 70, in error_handler
    raise e.with_traceback(filtered_tb) from None
  File "/p/software/juwelsbooster/stages/2023/software/TensorFlow/2.11.0-foss-2022a-CUDA-11.7/lib/python3.10/site-packages/tensorflow/python/framework/ops.py", line 1967, in _create_c_op
    raise ValueError(e.message)
ValueError: Exception encountered when calling layer "max_pooling2d_3" (type MaxPooling2D).

Negative dimension size caused by subtracting 2 from 1 for '{{node max_pooling2d_3/MaxPool}} = MaxPool[T=DT_FLOAT, data_format="NHWC", explicit_paddings=[], ksize=[1, 2, 2, 1], padding="VALID", strides=[1, 2, 2, 1]](Placeholder)' with input shapes: [?,1,3,512].

Call arguments received by layer "max_pooling2d_3" (type MaxPooling2D):
  • inputs=tf.Tensor(shape=(None, 1, 3, 512), dtype=float32)
srun: error: jwb0094: task 0: Exited with exit code 1
Traceback (most recent call last):
  File "/p/project1/cesmtst/patakchiyousefi1/CODES-MS3/FORECASTLEAD/DL_TRAIN.py", line 97, in <module>
    model = func_train.UNET(xpixels, ypixels, n_channels, Filters, dropout, unet_type)
  File "/p/project1/cesmtst/patakchiyousefi1/CODES-MS3/FORECASTLEAD/func_train.py", line 201, in UNET
    p4 = tf.keras.layers.MaxPooling2D((2, 2))(c4)
  File "/p/software/juwelsbooster/stages/2023/software/TensorFlow/2.11.0-foss-2022a-CUDA-11.7/lib/python3.10/site-packages/keras/utils/traceback_utils.py", line 70, in error_handler
    raise e.with_traceback(filtered_tb) from None
  File "/p/software/juwelsbooster/stages/2023/software/TensorFlow/2.11.0-foss-2022a-CUDA-11.7/lib/python3.10/site-packages/tensorflow/python/framework/ops.py", line 1967, in _create_c_op
    raise ValueError(e.message)
ValueError: Exception encountered when calling layer "max_pooling2d_3" (type MaxPooling2D).

Negative dimension size caused by subtracting 2 from 1 for '{{node max_pooling2d_3/MaxPool}} = MaxPool[T=DT_FLOAT, data_format="NHWC", explicit_paddings=[], ksize=[1, 2, 2, 1], padding="VALID", strides=[1, 2, 2, 1]](Placeholder)' with input shapes: [?,1,3,512].

Call arguments received by layer "max_pooling2d_3" (type MaxPooling2D):
  • inputs=tf.Tensor(shape=(None, 1, 3, 512), dtype=float32)
srun: error: jwb1026: task 0: Exited with exit code 1
srun: error: jwb1028: task 0: Exited with exit code 1
srun: error: jwb0095: task 0: Exited with exit code 1
Traceback (most recent call last):
  File "/p/project1/cesmtst/patakchiyousefi1/CODES-MS3/FORECASTLEAD/DL_TRAIN.py", line 97, in <module>
    model = func_train.UNET(xpixels, ypixels, n_channels, Filters, dropout, unet_type)
  File "/p/project1/cesmtst/patakchiyousefi1/CODES-MS3/FORECASTLEAD/func_train.py", line 201, in UNET
    p4 = tf.keras.layers.MaxPooling2D((2, 2))(c4)
  File "/p/software/juwelsbooster/stages/2023/software/TensorFlow/2.11.0-foss-2022a-CUDA-11.7/lib/python3.10/site-packages/keras/utils/traceback_utils.py", line 70, in error_handler
    raise e.with_traceback(filtered_tb) from None
  File "/p/software/juwelsbooster/stages/2023/software/TensorFlow/2.11.0-foss-2022a-CUDA-11.7/lib/python3.10/site-packages/tensorflow/python/framework/ops.py", line 1967, in _create_c_op
    raise ValueError(e.message)
ValueError: Exception encountered when calling layer "max_pooling2d_3" (type MaxPooling2D).

Negative dimension size caused by subtracting 2 from 1 for '{{node max_pooling2d_3/MaxPool}} = MaxPool[T=DT_FLOAT, data_format="NHWC", explicit_paddings=[], ksize=[1, 2, 2, 1], padding="VALID", strides=[1, 2, 2, 1]](Placeholder)' with input shapes: [?,1,3,512].

Call arguments received by layer "max_pooling2d_3" (type MaxPooling2D):
  • inputs=tf.Tensor(shape=(None, 1, 3, 512), dtype=float32)
srun: error: jwb1032: task 0: Exited with exit code 1
2024-07-26 10:16:24.714339: I tensorflow/core/common_runtime/gpu/gpu_device.cc:1613] Created device /job:localhost/replica:0/task:0/device:GPU:0 with 38364 MB memory:  -> device: 0, name: NVIDIA A100-SXM4-40GB, pci bus id: 0000:03:00.0, compute capability: 8.0
2024-07-26 10:16:24.716080: I tensorflow/core/common_runtime/gpu/gpu_device.cc:1613] Created device /job:localhost/replica:0/task:0/device:GPU:1 with 38364 MB memory:  -> device: 1, name: NVIDIA A100-SXM4-40GB, pci bus id: 0000:44:00.0, compute capability: 8.0
2024-07-26 10:16:24.718652: I tensorflow/core/common_runtime/gpu/gpu_device.cc:1613] Created device /job:localhost/replica:0/task:0/device:GPU:2 with 38364 MB memory:  -> device: 2, name: NVIDIA A100-SXM4-40GB, pci bus id: 0000:84:00.0, compute capability: 8.0
2024-07-26 10:16:24.720131: I tensorflow/core/common_runtime/gpu/gpu_device.cc:1613] Created device /job:localhost/replica:0/task:0/device:GPU:3 with 38364 MB memory:  -> device: 3, name: NVIDIA A100-SXM4-40GB, pci bus id: 0000:c4:00.0, compute capability: 8.0
srun: error: jwb0130: task 0: Exited with exit code 1
2024-07-26 10:16:25.001078: I tensorflow/core/common_runtime/gpu/gpu_device.cc:1613] Created device /job:localhost/replica:0/task:0/device:GPU:0 with 38364 MB memory:  -> device: 0, name: NVIDIA A100-SXM4-40GB, pci bus id: 0000:03:00.0, compute capability: 8.0
2024-07-26 10:16:25.002801: I tensorflow/core/common_runtime/gpu/gpu_device.cc:1613] Created device /job:localhost/replica:0/task:0/device:GPU:1 with 38364 MB memory:  -> device: 1, name: NVIDIA A100-SXM4-40GB, pci bus id: 0000:44:00.0, compute capability: 8.0
2024-07-26 10:16:25.005512: I tensorflow/core/common_runtime/gpu/gpu_device.cc:1613] Created device /job:localhost/replica:0/task:0/device:GPU:2 with 38364 MB memory:  -> device: 2, name: NVIDIA A100-SXM4-40GB, pci bus id: 0000:84:00.0, compute capability: 8.0
2024-07-26 10:16:25.007012: I tensorflow/core/common_runtime/gpu/gpu_device.cc:1613] Created device /job:localhost/replica:0/task:0/device:GPU:3 with 38364 MB memory:  -> device: 3, name: NVIDIA A100-SXM4-40GB, pci bus id: 0000:c4:00.0, compute capability: 8.0
2024-07-26 10:16:25.173767: I tensorflow/core/common_runtime/gpu/gpu_device.cc:1613] Created device /job:localhost/replica:0/task:0/device:GPU:0 with 38364 MB memory:  -> device: 0, name: NVIDIA A100-SXM4-40GB, pci bus id: 0000:03:00.0, compute capability: 8.0
2024-07-26 10:16:25.175581: I tensorflow/core/common_runtime/gpu/gpu_device.cc:1613] Created device /job:localhost/replica:0/task:0/device:GPU:1 with 38364 MB memory:  -> device: 1, name: NVIDIA A100-SXM4-40GB, pci bus id: 0000:44:00.0, compute capability: 8.0
2024-07-26 10:16:25.177057: I tensorflow/core/common_runtime/gpu/gpu_device.cc:1613] Created device /job:localhost/replica:0/task:0/device:GPU:2 with 38364 MB memory:  -> device: 2, name: NVIDIA A100-SXM4-40GB, pci bus id: 0000:84:00.0, compute capability: 8.0
2024-07-26 10:16:25.178679: I tensorflow/core/common_runtime/gpu/gpu_device.cc:1613] Created device /job:localhost/replica:0/task:0/device:GPU:3 with 38364 MB memory:  -> device: 3, name: NVIDIA A100-SXM4-40GB, pci bus id: 0000:c4:00.0, compute capability: 8.0
srun: error: jwb1054: task 0: Exited with exit code 1
srun: error: jwb0131: task 0: Exited with exit code 1
2024-07-26 10:16:25.682771: I tensorflow/core/common_runtime/gpu/gpu_device.cc:1613] Created device /job:localhost/replica:0/task:0/device:GPU:0 with 38364 MB memory:  -> device: 0, name: NVIDIA A100-SXM4-40GB, pci bus id: 0000:03:00.0, compute capability: 8.0
2024-07-26 10:16:25.685541: I tensorflow/core/common_runtime/gpu/gpu_device.cc:1613] Created device /job:localhost/replica:0/task:0/device:GPU:1 with 38364 MB memory:  -> device: 1, name: NVIDIA A100-SXM4-40GB, pci bus id: 0000:44:00.0, compute capability: 8.0
2024-07-26 10:16:25.687205: I tensorflow/core/common_runtime/gpu/gpu_device.cc:1613] Created device /job:localhost/replica:0/task:0/device:GPU:2 with 38364 MB memory:  -> device: 2, name: NVIDIA A100-SXM4-40GB, pci bus id: 0000:84:00.0, compute capability: 8.0
2024-07-26 10:16:25.688699: I tensorflow/core/common_runtime/gpu/gpu_device.cc:1613] Created device /job:localhost/replica:0/task:0/device:GPU:3 with 38364 MB memory:  -> device: 3, name: NVIDIA A100-SXM4-40GB, pci bus id: 0000:c4:00.0, compute capability: 8.0
srun: error: jwb0315: task 0: Exited with exit code 1
2024-07-26 10:16:27.237877: I tensorflow/core/common_runtime/gpu/gpu_device.cc:1613] Created device /job:localhost/replica:0/task:0/device:GPU:0 with 38364 MB memory:  -> device: 0, name: NVIDIA A100-SXM4-40GB, pci bus id: 0000:03:00.0, compute capability: 8.0
2024-07-26 10:16:27.241447: I tensorflow/core/common_runtime/gpu/gpu_device.cc:1613] Created device /job:localhost/replica:0/task:0/device:GPU:1 with 38364 MB memory:  -> device: 1, name: NVIDIA A100-SXM4-40GB, pci bus id: 0000:44:00.0, compute capability: 8.0
2024-07-26 10:16:27.242908: I tensorflow/core/common_runtime/gpu/gpu_device.cc:1613] Created device /job:localhost/replica:0/task:0/device:GPU:2 with 38364 MB memory:  -> device: 2, name: NVIDIA A100-SXM4-40GB, pci bus id: 0000:84:00.0, compute capability: 8.0
2024-07-26 10:16:27.244411: I tensorflow/core/common_runtime/gpu/gpu_device.cc:1613] Created device /job:localhost/replica:0/task:0/device:GPU:3 with 38364 MB memory:  -> device: 3, name: NVIDIA A100-SXM4-40GB, pci bus id: 0000:c4:00.0, compute capability: 8.0
Traceback (most recent call last):
  File "/p/project1/cesmtst/patakchiyousefi1/CODES-MS3/FORECASTLEAD/DL_TRAIN.py", line 97, in <module>
    model = func_train.UNET(xpixels, ypixels, n_channels, Filters, dropout, unet_type)
  File "/p/project1/cesmtst/patakchiyousefi1/CODES-MS3/FORECASTLEAD/func_train.py", line 201, in UNET
    p4 = tf.keras.layers.MaxPooling2D((2, 2))(c4)
  File "/p/software/juwelsbooster/stages/2023/software/TensorFlow/2.11.0-foss-2022a-CUDA-11.7/lib/python3.10/site-packages/keras/utils/traceback_utils.py", line 70, in error_handler
    raise e.with_traceback(filtered_tb) from None
  File "/p/software/juwelsbooster/stages/2023/software/TensorFlow/2.11.0-foss-2022a-CUDA-11.7/lib/python3.10/site-packages/tensorflow/python/framework/ops.py", line 1967, in _create_c_op
    raise ValueError(e.message)
ValueError: Exception encountered when calling layer "max_pooling2d_3" (type MaxPooling2D).

Negative dimension size caused by subtracting 2 from 1 for '{{node max_pooling2d_3/MaxPool}} = MaxPool[T=DT_FLOAT, data_format="NHWC", explicit_paddings=[], ksize=[1, 2, 2, 1], padding="VALID", strides=[1, 2, 2, 1]](Placeholder)' with input shapes: [?,1,3,512].

Call arguments received by layer "max_pooling2d_3" (type MaxPooling2D):
  • inputs=tf.Tensor(shape=(None, 1, 3, 512), dtype=float32)
2024-07-26 10:16:27.663646: I tensorflow/core/common_runtime/gpu/gpu_device.cc:1613] Created device /job:localhost/replica:0/task:0/device:GPU:0 with 38364 MB memory:  -> device: 0, name: NVIDIA A100-SXM4-40GB, pci bus id: 0000:03:00.0, compute capability: 8.0
Traceback (most recent call last):
  File "/p/project1/cesmtst/patakchiyousefi1/CODES-MS3/FORECASTLEAD/DL_TRAIN.py", line 97, in <module>
    model = func_train.UNET(xpixels, ypixels, n_channels, Filters, dropout, unet_type)
  File "/p/project1/cesmtst/patakchiyousefi1/CODES-MS3/FORECASTLEAD/func_train.py", line 201, in UNET
    p4 = tf.keras.layers.MaxPooling2D((2, 2))(c4)
  File "/p/software/juwelsbooster/stages/2023/software/TensorFlow/2.11.0-foss-2022a-CUDA-11.7/lib/python3.10/site-packages/keras/utils/traceback_utils.py", line 70, in error_handler
    raise e.with_traceback(filtered_tb) from None
  File "/p/software/juwelsbooster/stages/2023/software/TensorFlow/2.11.0-foss-2022a-CUDA-11.7/lib/python3.10/site-packages/tensorflow/python/framework/ops.py", line 1967, in _create_c_op
    raise ValueError(e.message)
ValueError: Exception encountered when calling layer "max_pooling2d_3" (type MaxPooling2D).

Negative dimension size caused by subtracting 2 from 1 for '{{node max_pooling2d_3/MaxPool}} = MaxPool[T=DT_FLOAT, data_format="NHWC", explicit_paddings=[], ksize=[1, 2, 2, 1], padding="VALID", strides=[1, 2, 2, 1]](Placeholder)' with input shapes: [?,1,3,512].

Call arguments received by layer "max_pooling2d_3" (type MaxPooling2D):
  • inputs=tf.Tensor(shape=(None, 1, 3, 512), dtype=float32)
2024-07-26 10:16:27.665501: I tensorflow/core/common_runtime/gpu/gpu_device.cc:1613] Created device /job:localhost/replica:0/task:0/device:GPU:1 with 38364 MB memory:  -> device: 1, name: NVIDIA A100-SXM4-40GB, pci bus id: 0000:44:00.0, compute capability: 8.0
2024-07-26 10:16:27.667925: I tensorflow/core/common_runtime/gpu/gpu_device.cc:1613] Created device /job:localhost/replica:0/task:0/device:GPU:2 with 38364 MB memory:  -> device: 2, name: NVIDIA A100-SXM4-40GB, pci bus id: 0000:84:00.0, compute capability: 8.0
2024-07-26 10:16:27.669528: I tensorflow/core/common_runtime/gpu/gpu_device.cc:1613] Created device /job:localhost/replica:0/task:0/device:GPU:3 with 38364 MB memory:  -> device: 3, name: NVIDIA A100-SXM4-40GB, pci bus id: 0000:c4:00.0, compute capability: 8.0
Traceback (most recent call last):
  File "/p/project1/cesmtst/patakchiyousefi1/CODES-MS3/FORECASTLEAD/DL_TRAIN.py", line 97, in <module>
    model = func_train.UNET(xpixels, ypixels, n_channels, Filters, dropout, unet_type)
  File "/p/project1/cesmtst/patakchiyousefi1/CODES-MS3/FORECASTLEAD/func_train.py", line 201, in UNET
    p4 = tf.keras.layers.MaxPooling2D((2, 2))(c4)
  File "/p/software/juwelsbooster/stages/2023/software/TensorFlow/2.11.0-foss-2022a-CUDA-11.7/lib/python3.10/site-packages/keras/utils/traceback_utils.py", line 70, in error_handler
    raise e.with_traceback(filtered_tb) from None
  File "/p/software/juwelsbooster/stages/2023/software/TensorFlow/2.11.0-foss-2022a-CUDA-11.7/lib/python3.10/site-packages/tensorflow/python/framework/ops.py", line 1967, in _create_c_op
    raise ValueError(e.message)
ValueError: Exception encountered when calling layer "max_pooling2d_3" (type MaxPooling2D).

Negative dimension size caused by subtracting 2 from 1 for '{{node max_pooling2d_3/MaxPool}} = MaxPool[T=DT_FLOAT, data_format="NHWC", explicit_paddings=[], ksize=[1, 2, 2, 1], padding="VALID", strides=[1, 2, 2, 1]](Placeholder)' with input shapes: [?,1,3,512].

Call arguments received by layer "max_pooling2d_3" (type MaxPooling2D):
  • inputs=tf.Tensor(shape=(None, 1, 3, 512), dtype=float32)
2024-07-26 10:16:27.879857: I tensorflow/core/common_runtime/gpu/gpu_device.cc:1613] Created device /job:localhost/replica:0/task:0/device:GPU:0 with 38364 MB memory:  -> device: 0, name: NVIDIA A100-SXM4-40GB, pci bus id: 0000:03:00.0, compute capability: 8.0
2024-07-26 10:16:27.881820: I tensorflow/core/common_runtime/gpu/gpu_device.cc:1613] Created device /job:localhost/replica:0/task:0/device:GPU:1 with 38364 MB memory:  -> device: 1, name: NVIDIA A100-SXM4-40GB, pci bus id: 0000:44:00.0, compute capability: 8.0
2024-07-26 10:16:27.884359: I tensorflow/core/common_runtime/gpu/gpu_device.cc:1613] Created device /job:localhost/replica:0/task:0/device:GPU:2 with 38364 MB memory:  -> device: 2, name: NVIDIA A100-SXM4-40GB, pci bus id: 0000:84:00.0, compute capability: 8.0
2024-07-26 10:16:27.887386: I tensorflow/core/common_runtime/gpu/gpu_device.cc:1613] Created device /job:localhost/replica:0/task:0/device:GPU:3 with 38364 MB memory:  -> device: 3, name: NVIDIA A100-SXM4-40GB, pci bus id: 0000:c4:00.0, compute capability: 8.0
2024-07-26 10:16:27.968908: I tensorflow/core/common_runtime/gpu/gpu_device.cc:1613] Created device /job:localhost/replica:0/task:0/device:GPU:0 with 38364 MB memory:  -> device: 0, name: NVIDIA A100-SXM4-40GB, pci bus id: 0000:03:00.0, compute capability: 8.0
2024-07-26 10:16:27.972136: I tensorflow/core/common_runtime/gpu/gpu_device.cc:1613] Created device /job:localhost/replica:0/task:0/device:GPU:1 with 38364 MB memory:  -> device: 1, name: NVIDIA A100-SXM4-40GB, pci bus id: 0000:44:00.0, compute capability: 8.0
2024-07-26 10:16:27.973937: I tensorflow/core/common_runtime/gpu/gpu_device.cc:1613] Created device /job:localhost/replica:0/task:0/device:GPU:2 with 38364 MB memory:  -> device: 2, name: NVIDIA A100-SXM4-40GB, pci bus id: 0000:84:00.0, compute capability: 8.0
2024-07-26 10:16:27.975438: I tensorflow/core/common_runtime/gpu/gpu_device.cc:1613] Created device /job:localhost/replica:0/task:0/device:GPU:3 with 38364 MB memory:  -> device: 3, name: NVIDIA A100-SXM4-40GB, pci bus id: 0000:c4:00.0, compute capability: 8.0
Traceback (most recent call last):
  File "/p/project1/cesmtst/patakchiyousefi1/CODES-MS3/FORECASTLEAD/DL_TRAIN.py", line 97, in <module>
    model = func_train.UNET(xpixels, ypixels, n_channels, Filters, dropout, unet_type)
  File "/p/project1/cesmtst/patakchiyousefi1/CODES-MS3/FORECASTLEAD/func_train.py", line 201, in UNET
    p4 = tf.keras.layers.MaxPooling2D((2, 2))(c4)
  File "/p/software/juwelsbooster/stages/2023/software/TensorFlow/2.11.0-foss-2022a-CUDA-11.7/lib/python3.10/site-packages/keras/utils/traceback_utils.py", line 70, in error_handler
    raise e.with_traceback(filtered_tb) from None
  File "/p/software/juwelsbooster/stages/2023/software/TensorFlow/2.11.0-foss-2022a-CUDA-11.7/lib/python3.10/site-packages/tensorflow/python/framework/ops.py", line 1967, in _create_c_op
    raise ValueError(e.message)
ValueError: Exception encountered when calling layer "max_pooling2d_3" (type MaxPooling2D).

Negative dimension size caused by subtracting 2 from 1 for '{{node max_pooling2d_3/MaxPool}} = MaxPool[T=DT_FLOAT, data_format="NHWC", explicit_paddings=[], ksize=[1, 2, 2, 1], padding="VALID", strides=[1, 2, 2, 1]](Placeholder)' with input shapes: [?,1,3,512].

Call arguments received by layer "max_pooling2d_3" (type MaxPooling2D):
  • inputs=tf.Tensor(shape=(None, 1, 3, 512), dtype=float32)
2024-07-26 10:16:28.465836: I tensorflow/core/common_runtime/gpu/gpu_device.cc:1613] Created device /job:localhost/replica:0/task:0/device:GPU:0 with 38364 MB memory:  -> device: 0, name: NVIDIA A100-SXM4-40GB, pci bus id: 0000:03:00.0, compute capability: 8.0
2024-07-26 10:16:28.467339: I tensorflow/core/common_runtime/gpu/gpu_device.cc:1613] Created device /job:localhost/replica:0/task:0/device:GPU:0 with 38364 MB memory:  -> device: 0, name: NVIDIA A100-SXM4-40GB, pci bus id: 0000:03:00.0, compute capability: 8.0
2024-07-26 10:16:28.469250: I tensorflow/core/common_runtime/gpu/gpu_device.cc:1613] Created device /job:localhost/replica:0/task:0/device:GPU:1 with 38364 MB memory:  -> device: 1, name: NVIDIA A100-SXM4-40GB, pci bus id: 0000:44:00.0, compute capability: 8.0
2024-07-26 10:16:28.471950: I tensorflow/core/common_runtime/gpu/gpu_device.cc:1613] Created device /job:localhost/replica:0/task:0/device:GPU:2 with 38364 MB memory:  -> device: 2, name: NVIDIA A100-SXM4-40GB, pci bus id: 0000:84:00.0, compute capability: 8.0
2024-07-26 10:16:28.475445: I tensorflow/core/common_runtime/gpu/gpu_device.cc:1613] Created device /job:localhost/replica:0/task:0/device:GPU:3 with 38364 MB memory:  -> device: 3, name: NVIDIA A100-SXM4-40GB, pci bus id: 0000:c4:00.0, compute capability: 8.0
2024-07-26 10:16:28.469256: I tensorflow/core/common_runtime/gpu/gpu_device.cc:1613] Created device /job:localhost/replica:0/task:0/device:GPU:1 with 38364 MB memory:  -> device: 1, name: NVIDIA A100-SXM4-40GB, pci bus id: 0000:44:00.0, compute capability: 8.0
2024-07-26 10:16:28.470912: I tensorflow/core/common_runtime/gpu/gpu_device.cc:1613] Created device /job:localhost/replica:0/task:0/device:GPU:2 with 38364 MB memory:  -> device: 2, name: NVIDIA A100-SXM4-40GB, pci bus id: 0000:84:00.0, compute capability: 8.0
2024-07-26 10:16:28.472541: I tensorflow/core/common_runtime/gpu/gpu_device.cc:1613] Created device /job:localhost/replica:0/task:0/device:GPU:3 with 38364 MB memory:  -> device: 3, name: NVIDIA A100-SXM4-40GB, pci bus id: 0000:c4:00.0, compute capability: 8.0
2024-07-26 10:16:29.053238: I tensorflow/core/common_runtime/gpu/gpu_device.cc:1613] Created device /job:localhost/replica:0/task:0/device:GPU:0 with 38364 MB memory:  -> device: 0, name: NVIDIA A100-SXM4-40GB, pci bus id: 0000:03:00.0, compute capability: 8.0
2024-07-26 10:16:29.055938: I tensorflow/core/common_runtime/gpu/gpu_device.cc:1613] Created device /job:localhost/replica:0/task:0/device:GPU:1 with 38364 MB memory:  -> device: 1, name: NVIDIA A100-SXM4-40GB, pci bus id: 0000:44:00.0, compute capability: 8.0
2024-07-26 10:16:29.057622: I tensorflow/core/common_runtime/gpu/gpu_device.cc:1613] Created device /job:localhost/replica:0/task:0/device:GPU:2 with 38364 MB memory:  -> device: 2, name: NVIDIA A100-SXM4-40GB, pci bus id: 0000:84:00.0, compute capability: 8.0
2024-07-26 10:16:29.060407: I tensorflow/core/common_runtime/gpu/gpu_device.cc:1613] Created device /job:localhost/replica:0/task:0/device:GPU:3 with 38364 MB memory:  -> device: 3, name: NVIDIA A100-SXM4-40GB, pci bus id: 0000:c4:00.0, compute capability: 8.0
srun: error: jwb0996: task 0: Exited with exit code 1
2024-07-26 10:16:29.441345: I tensorflow/core/common_runtime/gpu/gpu_device.cc:1613] Created device /job:localhost/replica:0/task:0/device:GPU:0 with 38364 MB memory:  -> device: 0, name: NVIDIA A100-SXM4-40GB, pci bus id: 0000:03:00.0, compute capability: 8.0
srun: error: jwb0993: task 0: Exited with exit code 1
2024-07-26 10:16:29.443219: I tensorflow/core/common_runtime/gpu/gpu_device.cc:1613] Created device /job:localhost/replica:0/task:0/device:GPU:1 with 38364 MB memory:  -> device: 1, name: NVIDIA A100-SXM4-40GB, pci bus id: 0000:44:00.0, compute capability: 8.0
2024-07-26 10:16:29.444833: I tensorflow/core/common_runtime/gpu/gpu_device.cc:1613] Created device /job:localhost/replica:0/task:0/device:GPU:2 with 38364 MB memory:  -> device: 2, name: NVIDIA A100-SXM4-40GB, pci bus id: 0000:84:00.0, compute capability: 8.0
2024-07-26 10:16:29.446276: I tensorflow/core/common_runtime/gpu/gpu_device.cc:1613] Created device /job:localhost/replica:0/task:0/device:GPU:3 with 38364 MB memory:  -> device: 3, name: NVIDIA A100-SXM4-40GB, pci bus id: 0000:c4:00.0, compute capability: 8.0
2024-07-26 10:16:29.579409: I tensorflow/core/common_runtime/gpu/gpu_device.cc:1613] Created device /job:localhost/replica:0/task:0/device:GPU:0 with 38364 MB memory:  -> device: 0, name: NVIDIA A100-SXM4-40GB, pci bus id: 0000:03:00.0, compute capability: 8.0
2024-07-26 10:16:29.581229: I tensorflow/core/common_runtime/gpu/gpu_device.cc:1613] Created device /job:localhost/replica:0/task:0/device:GPU:1 with 38364 MB memory:  -> device: 1, name: NVIDIA A100-SXM4-40GB, pci bus id: 0000:44:00.0, compute capability: 8.0
2024-07-26 10:16:29.583023: I tensorflow/core/common_runtime/gpu/gpu_device.cc:1613] Created device /job:localhost/replica:0/task:0/device:GPU:2 with 38364 MB memory:  -> device: 2, name: NVIDIA A100-SXM4-40GB, pci bus id: 0000:84:00.0, compute capability: 8.0
2024-07-26 10:16:29.584469: I tensorflow/core/common_runtime/gpu/gpu_device.cc:1613] Created device /job:localhost/replica:0/task:0/device:GPU:3 with 38364 MB memory:  -> device: 3, name: NVIDIA A100-SXM4-40GB, pci bus id: 0000:c4:00.0, compute capability: 8.0
srun: error: jwb1002: task 0: Exited with exit code 1
Traceback (most recent call last):
  File "/p/project1/cesmtst/patakchiyousefi1/CODES-MS3/FORECASTLEAD/DL_TRAIN.py", line 97, in <module>
    model = func_train.UNET(xpixels, ypixels, n_channels, Filters, dropout, unet_type)
  File "/p/project1/cesmtst/patakchiyousefi1/CODES-MS3/FORECASTLEAD/func_train.py", line 201, in UNET
    p4 = tf.keras.layers.MaxPooling2D((2, 2))(c4)
  File "/p/software/juwelsbooster/stages/2023/software/TensorFlow/2.11.0-foss-2022a-CUDA-11.7/lib/python3.10/site-packages/keras/utils/traceback_utils.py", line 70, in error_handler
    raise e.with_traceback(filtered_tb) from None
  File "/p/software/juwelsbooster/stages/2023/software/TensorFlow/2.11.0-foss-2022a-CUDA-11.7/lib/python3.10/site-packages/tensorflow/python/framework/ops.py", line 1967, in _create_c_op
    raise ValueError(e.message)
ValueError: Exception encountered when calling layer "max_pooling2d_3" (type MaxPooling2D).

Negative dimension size caused by subtracting 2 from 1 for '{{node max_pooling2d_3/MaxPool}} = MaxPool[T=DT_FLOAT, data_format="NHWC", explicit_paddings=[], ksize=[1, 2, 2, 1], padding="VALID", strides=[1, 2, 2, 1]](Placeholder)' with input shapes: [?,1,3,512].

Call arguments received by layer "max_pooling2d_3" (type MaxPooling2D):
  • inputs=tf.Tensor(shape=(None, 1, 3, 512), dtype=float32)
2024-07-26 10:16:30.031081: I tensorflow/core/common_runtime/gpu/gpu_device.cc:1613] Created device /job:localhost/replica:0/task:0/device:GPU:0 with 38364 MB memory:  -> device: 0, name: NVIDIA A100-SXM4-40GB, pci bus id: 0000:03:00.0, compute capability: 8.0
2024-07-26 10:16:30.033882: I tensorflow/core/common_runtime/gpu/gpu_device.cc:1613] Created device /job:localhost/replica:0/task:0/device:GPU:1 with 38364 MB memory:  -> device: 1, name: NVIDIA A100-SXM4-40GB, pci bus id: 0000:44:00.0, compute capability: 8.0
2024-07-26 10:16:30.035534: I tensorflow/core/common_runtime/gpu/gpu_device.cc:1613] Created device /job:localhost/replica:0/task:0/device:GPU:2 with 38364 MB memory:  -> device: 2, name: NVIDIA A100-SXM4-40GB, pci bus id: 0000:84:00.0, compute capability: 8.0
2024-07-26 10:16:30.039079: I tensorflow/core/common_runtime/gpu/gpu_device.cc:1613] Created device /job:localhost/replica:0/task:0/device:GPU:3 with 38364 MB memory:  -> device: 3, name: NVIDIA A100-SXM4-40GB, pci bus id: 0000:c4:00.0, compute capability: 8.0
2024-07-26 10:16:30.081599: I tensorflow/core/common_runtime/gpu/gpu_device.cc:1613] Created device /job:localhost/replica:0/task:0/device:GPU:0 with 38364 MB memory:  -> device: 0, name: NVIDIA A100-SXM4-40GB, pci bus id: 0000:03:00.0, compute capability: 8.0
2024-07-26 10:16:30.083399: I tensorflow/core/common_runtime/gpu/gpu_device.cc:1613] Created device /job:localhost/replica:0/task:0/device:GPU:1 with 38364 MB memory:  -> device: 1, name: NVIDIA A100-SXM4-40GB, pci bus id: 0000:44:00.0, compute capability: 8.0
2024-07-26 10:16:30.085027: I tensorflow/core/common_runtime/gpu/gpu_device.cc:1613] Created device /job:localhost/replica:0/task:0/device:GPU:2 with 38364 MB memory:  -> device: 2, name: NVIDIA A100-SXM4-40GB, pci bus id: 0000:84:00.0, compute capability: 8.0
2024-07-26 10:16:30.086484: I tensorflow/core/common_runtime/gpu/gpu_device.cc:1613] Created device /job:localhost/replica:0/task:0/device:GPU:3 with 38364 MB memory:  -> device: 3, name: NVIDIA A100-SXM4-40GB, pci bus id: 0000:c4:00.0, compute capability: 8.0
srun: error: jwb1004: task 0: Exited with exit code 1
Traceback (most recent call last):
  File "/p/project1/cesmtst/patakchiyousefi1/CODES-MS3/FORECASTLEAD/DL_TRAIN.py", line 97, in <module>
    model = func_train.UNET(xpixels, ypixels, n_channels, Filters, dropout, unet_type)
  File "/p/project1/cesmtst/patakchiyousefi1/CODES-MS3/FORECASTLEAD/func_train.py", line 201, in UNET
    p4 = tf.keras.layers.MaxPooling2D((2, 2))(c4)
  File "/p/software/juwelsbooster/stages/2023/software/TensorFlow/2.11.0-foss-2022a-CUDA-11.7/lib/python3.10/site-packages/keras/utils/traceback_utils.py", line 70, in error_handler
    raise e.with_traceback(filtered_tb) from None
  File "/p/software/juwelsbooster/stages/2023/software/TensorFlow/2.11.0-foss-2022a-CUDA-11.7/lib/python3.10/site-packages/tensorflow/python/framework/ops.py", line 1967, in _create_c_op
    raise ValueError(e.message)
ValueError: Exception encountered when calling layer "max_pooling2d_3" (type MaxPooling2D).

Negative dimension size caused by subtracting 2 from 1 for '{{node max_pooling2d_3/MaxPool}} = MaxPool[T=DT_FLOAT, data_format="NHWC", explicit_paddings=[], ksize=[1, 2, 2, 1], padding="VALID", strides=[1, 2, 2, 1]](Placeholder)' with input shapes: [?,1,3,512].

Call arguments received by layer "max_pooling2d_3" (type MaxPooling2D):
  • inputs=tf.Tensor(shape=(None, 1, 3, 512), dtype=float32)
2024-07-26 10:16:30.506536: I tensorflow/core/common_runtime/gpu/gpu_device.cc:1613] Created device /job:localhost/replica:0/task:0/device:GPU:0 with 38364 MB memory:  -> device: 0, name: NVIDIA A100-SXM4-40GB, pci bus id: 0000:03:00.0, compute capability: 8.0
2024-07-26 10:16:30.508390: I tensorflow/core/common_runtime/gpu/gpu_device.cc:1613] Created device /job:localhost/replica:0/task:0/device:GPU:1 with 38364 MB memory:  -> device: 1, name: NVIDIA A100-SXM4-40GB, pci bus id: 0000:44:00.0, compute capability: 8.0
2024-07-26 10:16:30.509941: I tensorflow/core/common_runtime/gpu/gpu_device.cc:1613] Created device /job:localhost/replica:0/task:0/device:GPU:2 with 38364 MB memory:  -> device: 2, name: NVIDIA A100-SXM4-40GB, pci bus id: 0000:84:00.0, compute capability: 8.0
2024-07-26 10:16:30.511556: I tensorflow/core/common_runtime/gpu/gpu_device.cc:1613] Created device /job:localhost/replica:0/task:0/device:GPU:3 with 38364 MB memory:  -> device: 3, name: NVIDIA A100-SXM4-40GB, pci bus id: 0000:c4:00.0, compute capability: 8.0
Traceback (most recent call last):
  File "/p/project1/cesmtst/patakchiyousefi1/CODES-MS3/FORECASTLEAD/DL_TRAIN.py", line 97, in <module>
    model = func_train.UNET(xpixels, ypixels, n_channels, Filters, dropout, unet_type)
  File "/p/project1/cesmtst/patakchiyousefi1/CODES-MS3/FORECASTLEAD/func_train.py", line 201, in UNET
    p4 = tf.keras.layers.MaxPooling2D((2, 2))(c4)
  File "/p/software/juwelsbooster/stages/2023/software/TensorFlow/2.11.0-foss-2022a-CUDA-11.7/lib/python3.10/site-packages/keras/utils/traceback_utils.py", line 70, in error_handler
    raise e.with_traceback(filtered_tb) from None
  File "/p/software/juwelsbooster/stages/2023/software/TensorFlow/2.11.0-foss-2022a-CUDA-11.7/lib/python3.10/site-packages/tensorflow/python/framework/ops.py", line 1967, in _create_c_op
    raise ValueError(e.message)
ValueError: Exception encountered when calling layer "max_pooling2d_3" (type MaxPooling2D).

Negative dimension size caused by subtracting 2 from 1 for '{{node max_pooling2d_3/MaxPool}} = MaxPool[T=DT_FLOAT, data_format="NHWC", explicit_paddings=[], ksize=[1, 2, 2, 1], padding="VALID", strides=[1, 2, 2, 1]](Placeholder)' with input shapes: [?,1,3,512].

Call arguments received by layer "max_pooling2d_3" (type MaxPooling2D):
  • inputs=tf.Tensor(shape=(None, 1, 3, 512), dtype=float32)
Traceback (most recent call last):
  File "/p/project1/cesmtst/patakchiyousefi1/CODES-MS3/FORECASTLEAD/DL_TRAIN.py", line 97, in <module>
    model = func_train.UNET(xpixels, ypixels, n_channels, Filters, dropout, unet_type)
  File "/p/project1/cesmtst/patakchiyousefi1/CODES-MS3/FORECASTLEAD/func_train.py", line 201, in UNET
    p4 = tf.keras.layers.MaxPooling2D((2, 2))(c4)
  File "/p/software/juwelsbooster/stages/2023/software/TensorFlow/2.11.0-foss-2022a-CUDA-11.7/lib/python3.10/site-packages/keras/utils/traceback_utils.py", line 70, in error_handler
    raise e.with_traceback(filtered_tb) from None
  File "/p/software/juwelsbooster/stages/2023/software/TensorFlow/2.11.0-foss-2022a-CUDA-11.7/lib/python3.10/site-packages/tensorflow/python/framework/ops.py", line 1967, in _create_c_op
    raise ValueError(e.message)
ValueError: Exception encountered when calling layer "max_pooling2d_3" (type MaxPooling2D).

Negative dimension size caused by subtracting 2 from 1 for '{{node max_pooling2d_3/MaxPool}} = MaxPool[T=DT_FLOAT, data_format="NHWC", explicit_paddings=[], ksize=[1, 2, 2, 1], padding="VALID", strides=[1, 2, 2, 1]](Placeholder)' with input shapes: [?,1,3,512].

Call arguments received by layer "max_pooling2d_3" (type MaxPooling2D):
  • inputs=tf.Tensor(shape=(None, 1, 3, 512), dtype=float32)
2024-07-26 10:16:30.705371: I tensorflow/core/common_runtime/gpu/gpu_device.cc:1613] Created device /job:localhost/replica:0/task:0/device:GPU:0 with 38364 MB memory:  -> device: 0, name: NVIDIA A100-SXM4-40GB, pci bus id: 0000:03:00.0, compute capability: 8.0
2024-07-26 10:16:30.714492: I tensorflow/core/common_runtime/gpu/gpu_device.cc:1613] Created device /job:localhost/replica:0/task:0/device:GPU:0 with 38364 MB memory:  -> device: 0, name: NVIDIA A100-SXM4-40GB, pci bus id: 0000:03:00.0, compute capability: 8.0
2024-07-26 10:16:30.707235: I tensorflow/core/common_runtime/gpu/gpu_device.cc:1613] Created device /job:localhost/replica:0/task:0/device:GPU:1 with 38364 MB memory:  -> device: 1, name: NVIDIA A100-SXM4-40GB, pci bus id: 0000:44:00.0, compute capability: 8.0
2024-07-26 10:16:30.710265: I tensorflow/core/common_runtime/gpu/gpu_device.cc:1613] Created device /job:localhost/replica:0/task:0/device:GPU:2 with 38364 MB memory:  -> device: 2, name: NVIDIA A100-SXM4-40GB, pci bus id: 0000:84:00.0, compute capability: 8.0
2024-07-26 10:16:30.711726: I tensorflow/core/common_runtime/gpu/gpu_device.cc:1613] Created device /job:localhost/replica:0/task:0/device:GPU:3 with 38364 MB memory:  -> device: 3, name: NVIDIA A100-SXM4-40GB, pci bus id: 0000:c4:00.0, compute capability: 8.0
2024-07-26 10:16:30.716389: I tensorflow/core/common_runtime/gpu/gpu_device.cc:1613] Created device /job:localhost/replica:0/task:0/device:GPU:1 with 38364 MB memory:  -> device: 1, name: NVIDIA A100-SXM4-40GB, pci bus id: 0000:44:00.0, compute capability: 8.0
2024-07-26 10:16:30.717880: I tensorflow/core/common_runtime/gpu/gpu_device.cc:1613] Created device /job:localhost/replica:0/task:0/device:GPU:2 with 38364 MB memory:  -> device: 2, name: NVIDIA A100-SXM4-40GB, pci bus id: 0000:84:00.0, compute capability: 8.0
2024-07-26 10:16:30.719336: I tensorflow/core/common_runtime/gpu/gpu_device.cc:1613] Created device /job:localhost/replica:0/task:0/device:GPU:3 with 38364 MB memory:  -> device: 3, name: NVIDIA A100-SXM4-40GB, pci bus id: 0000:c4:00.0, compute capability: 8.0
Traceback (most recent call last):
  File "/p/project1/cesmtst/patakchiyousefi1/CODES-MS3/FORECASTLEAD/DL_TRAIN.py", line 97, in <module>
    model = func_train.UNET(xpixels, ypixels, n_channels, Filters, dropout, unet_type)
  File "/p/project1/cesmtst/patakchiyousefi1/CODES-MS3/FORECASTLEAD/func_train.py", line 201, in UNET
    p4 = tf.keras.layers.MaxPooling2D((2, 2))(c4)
  File "/p/software/juwelsbooster/stages/2023/software/TensorFlow/2.11.0-foss-2022a-CUDA-11.7/lib/python3.10/site-packages/keras/utils/traceback_utils.py", line 70, in error_handler
    raise e.with_traceback(filtered_tb) from None
  File "/p/software/juwelsbooster/stages/2023/software/TensorFlow/2.11.0-foss-2022a-CUDA-11.7/lib/python3.10/site-packages/tensorflow/python/framework/ops.py", line 1967, in _create_c_op
    raise ValueError(e.message)
ValueError: Exception encountered when calling layer "max_pooling2d_3" (type MaxPooling2D).

Negative dimension size caused by subtracting 2 from 1 for '{{node max_pooling2d_3/MaxPool}} = MaxPool[T=DT_FLOAT, data_format="NHWC", explicit_paddings=[], ksize=[1, 2, 2, 1], padding="VALID", strides=[1, 2, 2, 1]](Placeholder)' with input shapes: [?,1,3,512].

Call arguments received by layer "max_pooling2d_3" (type MaxPooling2D):
  • inputs=tf.Tensor(shape=(None, 1, 3, 512), dtype=float32)
Traceback (most recent call last):
  File "/p/project1/cesmtst/patakchiyousefi1/CODES-MS3/FORECASTLEAD/DL_TRAIN.py", line 97, in <module>
    model = func_train.UNET(xpixels, ypixels, n_channels, Filters, dropout, unet_type)
  File "/p/project1/cesmtst/patakchiyousefi1/CODES-MS3/FORECASTLEAD/func_train.py", line 201, in UNET
    p4 = tf.keras.layers.MaxPooling2D((2, 2))(c4)
  File "/p/software/juwelsbooster/stages/2023/software/TensorFlow/2.11.0-foss-2022a-CUDA-11.7/lib/python3.10/site-packages/keras/utils/traceback_utils.py", line 70, in error_handler
    raise e.with_traceback(filtered_tb) from None
  File "/p/software/juwelsbooster/stages/2023/software/TensorFlow/2.11.0-foss-2022a-CUDA-11.7/lib/python3.10/site-packages/tensorflow/python/framework/ops.py", line 1967, in _create_c_op
    raise ValueError(e.message)
ValueError: Exception encountered when calling layer "max_pooling2d_3" (type MaxPooling2D).

Negative dimension size caused by subtracting 2 from 1 for '{{node max_pooling2d_3/MaxPool}} = MaxPool[T=DT_FLOAT, data_format="NHWC", explicit_paddings=[], ksize=[1, 2, 2, 1], padding="VALID", strides=[1, 2, 2, 1]](Placeholder)' with input shapes: [?,1,3,512].

Call arguments received by layer "max_pooling2d_3" (type MaxPooling2D):
  • inputs=tf.Tensor(shape=(None, 1, 3, 512), dtype=float32)
2024-07-26 10:16:31.700782: I tensorflow/core/common_runtime/gpu/gpu_device.cc:1613] Created device /job:localhost/replica:0/task:0/device:GPU:0 with 38364 MB memory:  -> device: 0, name: NVIDIA A100-SXM4-40GB, pci bus id: 0000:03:00.0, compute capability: 8.0
srun: error: jwb1018: task 0: Exited with exit code 1
2024-07-26 10:16:31.726971: I tensorflow/core/common_runtime/gpu/gpu_device.cc:1613] Created device /job:localhost/replica:0/task:0/device:GPU:0 with 38364 MB memory:  -> device: 0, name: NVIDIA A100-SXM4-40GB, pci bus id: 0000:03:00.0, compute capability: 8.0
2024-07-26 10:16:31.704370: I tensorflow/core/common_runtime/gpu/gpu_device.cc:1613] Created device /job:localhost/replica:0/task:0/device:GPU:1 with 38364 MB memory:  -> device: 1, name: NVIDIA A100-SXM4-40GB, pci bus id: 0000:44:00.0, compute capability: 8.0
2024-07-26 10:16:31.705883: I tensorflow/core/common_runtime/gpu/gpu_device.cc:1613] Created device /job:localhost/replica:0/task:0/device:GPU:2 with 38364 MB memory:  -> device: 2, name: NVIDIA A100-SXM4-40GB, pci bus id: 0000:84:00.0, compute capability: 8.0
2024-07-26 10:16:31.708553: I tensorflow/core/common_runtime/gpu/gpu_device.cc:1613] Created device /job:localhost/replica:0/task:0/device:GPU:3 with 38364 MB memory:  -> device: 3, name: NVIDIA A100-SXM4-40GB, pci bus id: 0000:c4:00.0, compute capability: 8.0
2024-07-26 10:16:31.729555: I tensorflow/core/common_runtime/gpu/gpu_device.cc:1613] Created device /job:localhost/replica:0/task:0/device:GPU:1 with 38364 MB memory:  -> device: 1, name: NVIDIA A100-SXM4-40GB, pci bus id: 0000:44:00.0, compute capability: 8.0
2024-07-26 10:16:31.731181: I tensorflow/core/common_runtime/gpu/gpu_device.cc:1613] Created device /job:localhost/replica:0/task:0/device:GPU:2 with 38364 MB memory:  -> device: 2, name: NVIDIA A100-SXM4-40GB, pci bus id: 0000:84:00.0, compute capability: 8.0
2024-07-26 10:16:31.732955: I tensorflow/core/common_runtime/gpu/gpu_device.cc:1613] Created device /job:localhost/replica:0/task:0/device:GPU:3 with 38364 MB memory:  -> device: 3, name: NVIDIA A100-SXM4-40GB, pci bus id: 0000:c4:00.0, compute capability: 8.0
Traceback (most recent call last):
  File "/p/project1/cesmtst/patakchiyousefi1/CODES-MS3/FORECASTLEAD/DL_TRAIN.py", line 97, in <module>
    model = func_train.UNET(xpixels, ypixels, n_channels, Filters, dropout, unet_type)
  File "/p/project1/cesmtst/patakchiyousefi1/CODES-MS3/FORECASTLEAD/func_train.py", line 201, in UNET
    p4 = tf.keras.layers.MaxPooling2D((2, 2))(c4)
  File "/p/software/juwelsbooster/stages/2023/software/TensorFlow/2.11.0-foss-2022a-CUDA-11.7/lib/python3.10/site-packages/keras/utils/traceback_utils.py", line 70, in error_handler
    raise e.with_traceback(filtered_tb) from None
  File "/p/software/juwelsbooster/stages/2023/software/TensorFlow/2.11.0-foss-2022a-CUDA-11.7/lib/python3.10/site-packages/tensorflow/python/framework/ops.py", line 1967, in _create_c_op
    raise ValueError(e.message)
ValueError: Exception encountered when calling layer "max_pooling2d_3" (type MaxPooling2D).

Negative dimension size caused by subtracting 2 from 1 for '{{node max_pooling2d_3/MaxPool}} = MaxPool[T=DT_FLOAT, data_format="NHWC", explicit_paddings=[], ksize=[1, 2, 2, 1], padding="VALID", strides=[1, 2, 2, 1]](Placeholder)' with input shapes: [?,1,3,512].

Call arguments received by layer "max_pooling2d_3" (type MaxPooling2D):
  • inputs=tf.Tensor(shape=(None, 1, 3, 512), dtype=float32)
srun: error: jwb0380: task 0: Exited with exit code 1
Traceback (most recent call last):
  File "/p/project1/cesmtst/patakchiyousefi1/CODES-MS3/FORECASTLEAD/DL_TRAIN.py", line 97, in <module>
    model = func_train.UNET(xpixels, ypixels, n_channels, Filters, dropout, unet_type)
  File "/p/project1/cesmtst/patakchiyousefi1/CODES-MS3/FORECASTLEAD/func_train.py", line 201, in UNET
    p4 = tf.keras.layers.MaxPooling2D((2, 2))(c4)
  File "/p/software/juwelsbooster/stages/2023/software/TensorFlow/2.11.0-foss-2022a-CUDA-11.7/lib/python3.10/site-packages/keras/utils/traceback_utils.py", line 70, in error_handler
    raise e.with_traceback(filtered_tb) from None
  File "/p/software/juwelsbooster/stages/2023/software/TensorFlow/2.11.0-foss-2022a-CUDA-11.7/lib/python3.10/site-packages/tensorflow/python/framework/ops.py", line 1967, in _create_c_op
    raise ValueError(e.message)
ValueError: Exception encountered when calling layer "max_pooling2d_3" (type MaxPooling2D).

Negative dimension size caused by subtracting 2 from 1 for '{{node max_pooling2d_3/MaxPool}} = MaxPool[T=DT_FLOAT, data_format="NHWC", explicit_paddings=[], ksize=[1, 2, 2, 1], padding="VALID", strides=[1, 2, 2, 1]](Placeholder)' with input shapes: [?,1,3,512].

Call arguments received by layer "max_pooling2d_3" (type MaxPooling2D):
  • inputs=tf.Tensor(shape=(None, 1, 3, 512), dtype=float32)
Traceback (most recent call last):
  File "/p/project1/cesmtst/patakchiyousefi1/CODES-MS3/FORECASTLEAD/DL_TRAIN.py", line 97, in <module>
    model = func_train.UNET(xpixels, ypixels, n_channels, Filters, dropout, unet_type)
  File "/p/project1/cesmtst/patakchiyousefi1/CODES-MS3/FORECASTLEAD/func_train.py", line 201, in UNET
    p4 = tf.keras.layers.MaxPooling2D((2, 2))(c4)
  File "/p/software/juwelsbooster/stages/2023/software/TensorFlow/2.11.0-foss-2022a-CUDA-11.7/lib/python3.10/site-packages/keras/utils/traceback_utils.py", line 70, in error_handler
    raise e.with_traceback(filtered_tb) from None
  File "/p/software/juwelsbooster/stages/2023/software/TensorFlow/2.11.0-foss-2022a-CUDA-11.7/lib/python3.10/site-packages/tensorflow/python/framework/ops.py", line 1967, in _create_c_op
    raise ValueError(e.message)
ValueError: Exception encountered when calling layer "max_pooling2d_3" (type MaxPooling2D).

Negative dimension size caused by subtracting 2 from 1 for '{{node max_pooling2d_3/MaxPool}} = MaxPool[T=DT_FLOAT, data_format="NHWC", explicit_paddings=[], ksize=[1, 2, 2, 1], padding="VALID", strides=[1, 2, 2, 1]](Placeholder)' with input shapes: [?,1,3,512].

Call arguments received by layer "max_pooling2d_3" (type MaxPooling2D):
  • inputs=tf.Tensor(shape=(None, 1, 3, 512), dtype=float32)
srun: error: jwb0661: task 0: Exited with exit code 1
srun: error: jwb1019: task 0: Exited with exit code 1
2024-07-26 10:16:32.724426: I tensorflow/core/common_runtime/gpu/gpu_device.cc:1613] Created device /job:localhost/replica:0/task:0/device:GPU:0 with 38364 MB memory:  -> device: 0, name: NVIDIA A100-SXM4-40GB, pci bus id: 0000:03:00.0, compute capability: 8.0
Traceback (most recent call last):
  File "/p/project1/cesmtst/patakchiyousefi1/CODES-MS3/FORECASTLEAD/DL_TRAIN.py", line 97, in <module>
    model = func_train.UNET(xpixels, ypixels, n_channels, Filters, dropout, unet_type)
  File "/p/project1/cesmtst/patakchiyousefi1/CODES-MS3/FORECASTLEAD/func_train.py", line 201, in UNET
    p4 = tf.keras.layers.MaxPooling2D((2, 2))(c4)
  File "/p/software/juwelsbooster/stages/2023/software/TensorFlow/2.11.0-foss-2022a-CUDA-11.7/lib/python3.10/site-packages/keras/utils/traceback_utils.py", line 70, in error_handler
    raise e.with_traceback(filtered_tb) from None
  File "/p/software/juwelsbooster/stages/2023/software/TensorFlow/2.11.0-foss-2022a-CUDA-11.7/lib/python3.10/site-packages/tensorflow/python/framework/ops.py", line 1967, in _create_c_op
    raise ValueError(e.message)
ValueError: Exception encountered when calling layer "max_pooling2d_3" (type MaxPooling2D).

Negative dimension size caused by subtracting 2 from 1 for '{{node max_pooling2d_3/MaxPool}} = MaxPool[T=DT_FLOAT, data_format="NHWC", explicit_paddings=[], ksize=[1, 2, 2, 1], padding="VALID", strides=[1, 2, 2, 1]](Placeholder)' with input shapes: [?,1,3,512].

Call arguments received by layer "max_pooling2d_3" (type MaxPooling2D):
  • inputs=tf.Tensor(shape=(None, 1, 3, 512), dtype=float32)
2024-07-26 10:16:32.726265: I tensorflow/core/common_runtime/gpu/gpu_device.cc:1613] Created device /job:localhost/replica:0/task:0/device:GPU:1 with 38364 MB memory:  -> device: 1, name: NVIDIA A100-SXM4-40GB, pci bus id: 0000:44:00.0, compute capability: 8.0
2024-07-26 10:16:32.727857: I tensorflow/core/common_runtime/gpu/gpu_device.cc:1613] Created device /job:localhost/replica:0/task:0/device:GPU:2 with 38364 MB memory:  -> device: 2, name: NVIDIA A100-SXM4-40GB, pci bus id: 0000:84:00.0, compute capability: 8.0
2024-07-26 10:16:32.729490: I tensorflow/core/common_runtime/gpu/gpu_device.cc:1613] Created device /job:localhost/replica:0/task:0/device:GPU:3 with 38364 MB memory:  -> device: 3, name: NVIDIA A100-SXM4-40GB, pci bus id: 0000:c4:00.0, compute capability: 8.0
Traceback (most recent call last):
  File "/p/project1/cesmtst/patakchiyousefi1/CODES-MS3/FORECASTLEAD/DL_TRAIN.py", line 97, in <module>
    model = func_train.UNET(xpixels, ypixels, n_channels, Filters, dropout, unet_type)
  File "/p/project1/cesmtst/patakchiyousefi1/CODES-MS3/FORECASTLEAD/func_train.py", line 201, in UNET
    p4 = tf.keras.layers.MaxPooling2D((2, 2))(c4)
  File "/p/software/juwelsbooster/stages/2023/software/TensorFlow/2.11.0-foss-2022a-CUDA-11.7/lib/python3.10/site-packages/keras/utils/traceback_utils.py", line 70, in error_handler
    raise e.with_traceback(filtered_tb) from None
  File "/p/software/juwelsbooster/stages/2023/software/TensorFlow/2.11.0-foss-2022a-CUDA-11.7/lib/python3.10/site-packages/tensorflow/python/framework/ops.py", line 1967, in _create_c_op
    raise ValueError(e.message)
ValueError: Exception encountered when calling layer "max_pooling2d_3" (type MaxPooling2D).

Negative dimension size caused by subtracting 2 from 1 for '{{node max_pooling2d_3/MaxPool}} = MaxPool[T=DT_FLOAT, data_format="NHWC", explicit_paddings=[], ksize=[1, 2, 2, 1], padding="VALID", strides=[1, 2, 2, 1]](Placeholder)' with input shapes: [?,1,3,512].

Call arguments received by layer "max_pooling2d_3" (type MaxPooling2D):
  • inputs=tf.Tensor(shape=(None, 1, 3, 512), dtype=float32)
srun: error: jwb0381: task 0: Exited with exit code 1
srun: error: jwb1022: task 0: Exited with exit code 1
Traceback (most recent call last):
  File "/p/project1/cesmtst/patakchiyousefi1/CODES-MS3/FORECASTLEAD/DL_TRAIN.py", line 97, in <module>
    model = func_train.UNET(xpixels, ypixels, n_channels, Filters, dropout, unet_type)
  File "/p/project1/cesmtst/patakchiyousefi1/CODES-MS3/FORECASTLEAD/func_train.py", line 201, in UNET
    p4 = tf.keras.layers.MaxPooling2D((2, 2))(c4)
  File "/p/software/juwelsbooster/stages/2023/software/TensorFlow/2.11.0-foss-2022a-CUDA-11.7/lib/python3.10/site-packages/keras/utils/traceback_utils.py", line 70, in error_handler
    raise e.with_traceback(filtered_tb) from None
  File "/p/software/juwelsbooster/stages/2023/software/TensorFlow/2.11.0-foss-2022a-CUDA-11.7/lib/python3.10/site-packages/tensorflow/python/framework/ops.py", line 1967, in _create_c_op
    raise ValueError(e.message)
ValueError: Exception encountered when calling layer "max_pooling2d_3" (type MaxPooling2D).

Negative dimension size caused by subtracting 2 from 1 for '{{node max_pooling2d_3/MaxPool}} = MaxPool[T=DT_FLOAT, data_format="NHWC", explicit_paddings=[], ksize=[1, 2, 2, 1], padding="VALID", strides=[1, 2, 2, 1]](Placeholder)' with input shapes: [?,1,3,512].

Call arguments received by layer "max_pooling2d_3" (type MaxPooling2D):
  • inputs=tf.Tensor(shape=(None, 1, 3, 512), dtype=float32)
Traceback (most recent call last):
  File "/p/project1/cesmtst/patakchiyousefi1/CODES-MS3/FORECASTLEAD/DL_TRAIN.py", line 97, in <module>
    model = func_train.UNET(xpixels, ypixels, n_channels, Filters, dropout, unet_type)
  File "/p/project1/cesmtst/patakchiyousefi1/CODES-MS3/FORECASTLEAD/func_train.py", line 201, in UNET
    p4 = tf.keras.layers.MaxPooling2D((2, 2))(c4)
  File "/p/software/juwelsbooster/stages/2023/software/TensorFlow/2.11.0-foss-2022a-CUDA-11.7/lib/python3.10/site-packages/keras/utils/traceback_utils.py", line 70, in error_handler
    raise e.with_traceback(filtered_tb) from None
  File "/p/software/juwelsbooster/stages/2023/software/TensorFlow/2.11.0-foss-2022a-CUDA-11.7/lib/python3.10/site-packages/tensorflow/python/framework/ops.py", line 1967, in _create_c_op
    raise ValueError(e.message)
ValueError: Exception encountered when calling layer "max_pooling2d_3" (type MaxPooling2D).

Negative dimension size caused by subtracting 2 from 1 for '{{node max_pooling2d_3/MaxPool}} = MaxPool[T=DT_FLOAT, data_format="NHWC", explicit_paddings=[], ksize=[1, 2, 2, 1], padding="VALID", strides=[1, 2, 2, 1]](Placeholder)' with input shapes: [?,1,3,512].

Call arguments received by layer "max_pooling2d_3" (type MaxPooling2D):
  • inputs=tf.Tensor(shape=(None, 1, 3, 512), dtype=float32)
Traceback (most recent call last):
  File "/p/project1/cesmtst/patakchiyousefi1/CODES-MS3/FORECASTLEAD/DL_TRAIN.py", line 97, in <module>
    model = func_train.UNET(xpixels, ypixels, n_channels, Filters, dropout, unet_type)
  File "/p/project1/cesmtst/patakchiyousefi1/CODES-MS3/FORECASTLEAD/func_train.py", line 201, in UNET
    p4 = tf.keras.layers.MaxPooling2D((2, 2))(c4)
  File "/p/software/juwelsbooster/stages/2023/software/TensorFlow/2.11.0-foss-2022a-CUDA-11.7/lib/python3.10/site-packages/keras/utils/traceback_utils.py", line 70, in error_handler
    raise e.with_traceback(filtered_tb) from None
  File "/p/software/juwelsbooster/stages/2023/software/TensorFlow/2.11.0-foss-2022a-CUDA-11.7/lib/python3.10/site-packages/tensorflow/python/framework/ops.py", line 1967, in _create_c_op
    raise ValueError(e.message)
ValueError: Exception encountered when calling layer "max_pooling2d_3" (type MaxPooling2D).

Negative dimension size caused by subtracting 2 from 1 for '{{node max_pooling2d_3/MaxPool}} = MaxPool[T=DT_FLOAT, data_format="NHWC", explicit_paddings=[], ksize=[1, 2, 2, 1], padding="VALID", strides=[1, 2, 2, 1]](Placeholder)' with input shapes: [?,1,3,512].

Call arguments received by layer "max_pooling2d_3" (type MaxPooling2D):
  • inputs=tf.Tensor(shape=(None, 1, 3, 512), dtype=float32)
srun: error: jwb0666: task 0: Exited with exit code 1
srun: error: jwb0383: task 0: Exited with exit code 1
srun: error: jwb0667: task 0: Exited with exit code 1
Traceback (most recent call last):
  File "/p/project1/cesmtst/patakchiyousefi1/CODES-MS3/FORECASTLEAD/DL_TRAIN.py", line 97, in <module>
    model = func_train.UNET(xpixels, ypixels, n_channels, Filters, dropout, unet_type)
  File "/p/project1/cesmtst/patakchiyousefi1/CODES-MS3/FORECASTLEAD/func_train.py", line 201, in UNET
    p4 = tf.keras.layers.MaxPooling2D((2, 2))(c4)
  File "/p/software/juwelsbooster/stages/2023/software/TensorFlow/2.11.0-foss-2022a-CUDA-11.7/lib/python3.10/site-packages/keras/utils/traceback_utils.py", line 70, in error_handler
    raise e.with_traceback(filtered_tb) from None
  File "/p/software/juwelsbooster/stages/2023/software/TensorFlow/2.11.0-foss-2022a-CUDA-11.7/lib/python3.10/site-packages/tensorflow/python/framework/ops.py", line 1967, in _create_c_op
    raise ValueError(e.message)
ValueError: Exception encountered when calling layer "max_pooling2d_3" (type MaxPooling2D).

Negative dimension size caused by subtracting 2 from 1 for '{{node max_pooling2d_3/MaxPool}} = MaxPool[T=DT_FLOAT, data_format="NHWC", explicit_paddings=[], ksize=[1, 2, 2, 1], padding="VALID", strides=[1, 2, 2, 1]](Placeholder)' with input shapes: [?,1,3,512].

Call arguments received by layer "max_pooling2d_3" (type MaxPooling2D):
  • inputs=tf.Tensor(shape=(None, 1, 3, 512), dtype=float32)
Traceback (most recent call last):
  File "/p/project1/cesmtst/patakchiyousefi1/CODES-MS3/FORECASTLEAD/DL_TRAIN.py", line 97, in <module>
    model = func_train.UNET(xpixels, ypixels, n_channels, Filters, dropout, unet_type)
  File "/p/project1/cesmtst/patakchiyousefi1/CODES-MS3/FORECASTLEAD/func_train.py", line 201, in UNET
    p4 = tf.keras.layers.MaxPooling2D((2, 2))(c4)
  File "/p/software/juwelsbooster/stages/2023/software/TensorFlow/2.11.0-foss-2022a-CUDA-11.7/lib/python3.10/site-packages/keras/utils/traceback_utils.py", line 70, in error_handler
    raise e.with_traceback(filtered_tb) from None
  File "/p/software/juwelsbooster/stages/2023/software/TensorFlow/2.11.0-foss-2022a-CUDA-11.7/lib/python3.10/site-packages/tensorflow/python/framework/ops.py", line 1967, in _create_c_op
    raise ValueError(e.message)
ValueError: Exception encountered when calling layer "max_pooling2d_3" (type MaxPooling2D).

Negative dimension size caused by subtracting 2 from 1 for '{{node max_pooling2d_3/MaxPool}} = MaxPool[T=DT_FLOAT, data_format="NHWC", explicit_paddings=[], ksize=[1, 2, 2, 1], padding="VALID", strides=[1, 2, 2, 1]](Placeholder)' with input shapes: [?,1,3,512].

Call arguments received by layer "max_pooling2d_3" (type MaxPooling2D):
  • inputs=tf.Tensor(shape=(None, 1, 3, 512), dtype=float32)
srun: error: jwb0668: task 0: Exited with exit code 1
srun: error: jwb0384: task 0: Exited with exit code 1
srun: error: jwb0669: task 0: Exited with exit code 1
srun: error: jwb0382: task 0: Exited with exit code 1
srun: error: jwb0320: task 0: Exited with exit code 1
Traceback (most recent call last):
  File "/p/project1/cesmtst/patakchiyousefi1/CODES-MS3/FORECASTLEAD/DL_TRAIN.py", line 97, in <module>
    model = func_train.UNET(xpixels, ypixels, n_channels, Filters, dropout, unet_type)
  File "/p/project1/cesmtst/patakchiyousefi1/CODES-MS3/FORECASTLEAD/func_train.py", line 201, in UNET
    p4 = tf.keras.layers.MaxPooling2D((2, 2))(c4)
  File "/p/software/juwelsbooster/stages/2023/software/TensorFlow/2.11.0-foss-2022a-CUDA-11.7/lib/python3.10/site-packages/keras/utils/traceback_utils.py", line 70, in error_handler
    raise e.with_traceback(filtered_tb) from None
  File "/p/software/juwelsbooster/stages/2023/software/TensorFlow/2.11.0-foss-2022a-CUDA-11.7/lib/python3.10/site-packages/tensorflow/python/framework/ops.py", line 1967, in _create_c_op
    raise ValueError(e.message)
ValueError: Exception encountered when calling layer "max_pooling2d_3" (type MaxPooling2D).

Negative dimension size caused by subtracting 2 from 1 for '{{node max_pooling2d_3/MaxPool}} = MaxPool[T=DT_FLOAT, data_format="NHWC", explicit_paddings=[], ksize=[1, 2, 2, 1], padding="VALID", strides=[1, 2, 2, 1]](Placeholder)' with input shapes: [?,1,3,512].

Call arguments received by layer "max_pooling2d_3" (type MaxPooling2D):
  • inputs=tf.Tensor(shape=(None, 1, 3, 512), dtype=float32)
srun: error: jwb0324: task 0: Exited with exit code 1
srun: error: jwb0344: task 0: Exited with exit code 1
srun: error: jwb0346: task 0: Exited with exit code 1
