Traceback (most recent call last):
  File "/p/project1/cesmtst/patakchiyousefi1/CODES-MS3/FORECASTLEAD/STATS.py", line 29, in <module>
    MOD_D = MOD_D.where(MOD_D >= 0, drop=True)
NameError: name 'MOD_D' is not defined
srun: error: jwb0803: task 0: Exited with exit code 1
Traceback (most recent call last):
  File "/p/project1/cesmtst/patakchiyousefi1/CODES-MS3/FORECASTLEAD/STATS.py", line 29, in <module>
    MOD_D = MOD_D.where(MOD_D >= 0, drop=True)
NameError: name 'MOD_D' is not defined
srun: error: jwb0803: task 0: Exited with exit code 1
Traceback (most recent call last):
  File "/p/software/juwelsbooster/stages/2023/software/xarray/2022.9.0-gcccoremkl-11.3.0-2022.1.0/lib/python3.10/site-packages/xarray/backends/file_manager.py", line 201, in _acquire_with_cache_info
    file = self._cache[self._key]
  File "/p/software/juwelsbooster/stages/2023/software/xarray/2022.9.0-gcccoremkl-11.3.0-2022.1.0/lib/python3.10/site-packages/xarray/backends/lru_cache.py", line 55, in __getitem__
    value = self._cache[key]
KeyError: [<class 'netCDF4._netCDF4.Dataset'>, ('/p/scratch/cesmtst/patakchiyousefi1/FORECASTLEAD_CESMTST_SCRATCH/PREDICT_FILES/ADAPTER_DE05.day04.merged.nc.corrected.nc',), 'r', (('clobber', True), ('diskless', False), ('format', 'NETCDF4'), ('persist', False))]

During handling of the above exception, another exception occurred:

Traceback (most recent call last):
  File "/p/project1/cesmtst/patakchiyousefi1/CODES-MS3/FORECASTLEAD/STATS.py", line 23, in <module>
    CMOD = xr.open_dataset(CMOD)
  File "/p/software/juwelsbooster/stages/2023/software/xarray/2022.9.0-gcccoremkl-11.3.0-2022.1.0/lib/python3.10/site-packages/xarray/backends/api.py", line 531, in open_dataset
    backend_ds = backend.open_dataset(
  File "/p/software/juwelsbooster/stages/2023/software/xarray/2022.9.0-gcccoremkl-11.3.0-2022.1.0/lib/python3.10/site-packages/xarray/backends/netCDF4_.py", line 555, in open_dataset
    store = NetCDF4DataStore.open(
  File "/p/software/juwelsbooster/stages/2023/software/xarray/2022.9.0-gcccoremkl-11.3.0-2022.1.0/lib/python3.10/site-packages/xarray/backends/netCDF4_.py", line 384, in open
    return cls(manager, group=group, mode=mode, lock=lock, autoclose=autoclose)
  File "/p/software/juwelsbooster/stages/2023/software/xarray/2022.9.0-gcccoremkl-11.3.0-2022.1.0/lib/python3.10/site-packages/xarray/backends/netCDF4_.py", line 332, in __init__
    self.format = self.ds.data_model
  File "/p/software/juwelsbooster/stages/2023/software/xarray/2022.9.0-gcccoremkl-11.3.0-2022.1.0/lib/python3.10/site-packages/xarray/backends/netCDF4_.py", line 393, in ds
    return self._acquire()
  File "/p/software/juwelsbooster/stages/2023/software/xarray/2022.9.0-gcccoremkl-11.3.0-2022.1.0/lib/python3.10/site-packages/xarray/backends/netCDF4_.py", line 387, in _acquire
    with self._manager.acquire_context(needs_lock) as root:
  File "/p/software/juwelsbooster/stages/2023/software/Python/3.10.4-GCCcore-11.3.0/lib/python3.10/contextlib.py", line 135, in __enter__
    return next(self.gen)
  File "/p/software/juwelsbooster/stages/2023/software/xarray/2022.9.0-gcccoremkl-11.3.0-2022.1.0/lib/python3.10/site-packages/xarray/backends/file_manager.py", line 189, in acquire_context
    file, cached = self._acquire_with_cache_info(needs_lock)
  File "/p/software/juwelsbooster/stages/2023/software/xarray/2022.9.0-gcccoremkl-11.3.0-2022.1.0/lib/python3.10/site-packages/xarray/backends/file_manager.py", line 207, in _acquire_with_cache_info
    file = self._opener(*self._args, **kwargs)
  File "src/netCDF4/_netCDF4.pyx", line 2463, in netCDF4._netCDF4.Dataset.__init__
  File "src/netCDF4/_netCDF4.pyx", line 2026, in netCDF4._netCDF4._ensure_nc_success
FileNotFoundError: [Errno 2] No such file or directory: b'/p/scratch/cesmtst/patakchiyousefi1/FORECASTLEAD_CESMTST_SCRATCH/PREDICT_FILES/ADAPTER_DE05.day04.merged.nc.corrected.nc'
srun: error: jwb0803: task 0: Exited with exit code 1
Traceback (most recent call last):
  File "/p/software/juwelsbooster/stages/2023/software/xarray/2022.9.0-gcccoremkl-11.3.0-2022.1.0/lib/python3.10/site-packages/xarray/backends/file_manager.py", line 201, in _acquire_with_cache_info
    file = self._cache[self._key]
  File "/p/software/juwelsbooster/stages/2023/software/xarray/2022.9.0-gcccoremkl-11.3.0-2022.1.0/lib/python3.10/site-packages/xarray/backends/lru_cache.py", line 55, in __getitem__
    value = self._cache[key]
KeyError: [<class 'netCDF4._netCDF4.Dataset'>, ('/p/scratch/cesmtst/patakchiyousefi1/FORECASTLEAD_CESMTST_SCRATCH/PREDICT_FILES/ADAPTER_DE05.day05.merged.nc.corrected.nc',), 'r', (('clobber', True), ('diskless', False), ('format', 'NETCDF4'), ('persist', False))]

During handling of the above exception, another exception occurred:

Traceback (most recent call last):
  File "/p/project1/cesmtst/patakchiyousefi1/CODES-MS3/FORECASTLEAD/STATS.py", line 23, in <module>
    CMOD = xr.open_dataset(CMOD)
  File "/p/software/juwelsbooster/stages/2023/software/xarray/2022.9.0-gcccoremkl-11.3.0-2022.1.0/lib/python3.10/site-packages/xarray/backends/api.py", line 531, in open_dataset
    backend_ds = backend.open_dataset(
  File "/p/software/juwelsbooster/stages/2023/software/xarray/2022.9.0-gcccoremkl-11.3.0-2022.1.0/lib/python3.10/site-packages/xarray/backends/netCDF4_.py", line 555, in open_dataset
    store = NetCDF4DataStore.open(
  File "/p/software/juwelsbooster/stages/2023/software/xarray/2022.9.0-gcccoremkl-11.3.0-2022.1.0/lib/python3.10/site-packages/xarray/backends/netCDF4_.py", line 384, in open
    return cls(manager, group=group, mode=mode, lock=lock, autoclose=autoclose)
  File "/p/software/juwelsbooster/stages/2023/software/xarray/2022.9.0-gcccoremkl-11.3.0-2022.1.0/lib/python3.10/site-packages/xarray/backends/netCDF4_.py", line 332, in __init__
    self.format = self.ds.data_model
  File "/p/software/juwelsbooster/stages/2023/software/xarray/2022.9.0-gcccoremkl-11.3.0-2022.1.0/lib/python3.10/site-packages/xarray/backends/netCDF4_.py", line 393, in ds
    return self._acquire()
  File "/p/software/juwelsbooster/stages/2023/software/xarray/2022.9.0-gcccoremkl-11.3.0-2022.1.0/lib/python3.10/site-packages/xarray/backends/netCDF4_.py", line 387, in _acquire
    with self._manager.acquire_context(needs_lock) as root:
  File "/p/software/juwelsbooster/stages/2023/software/Python/3.10.4-GCCcore-11.3.0/lib/python3.10/contextlib.py", line 135, in __enter__
    return next(self.gen)
  File "/p/software/juwelsbooster/stages/2023/software/xarray/2022.9.0-gcccoremkl-11.3.0-2022.1.0/lib/python3.10/site-packages/xarray/backends/file_manager.py", line 189, in acquire_context
    file, cached = self._acquire_with_cache_info(needs_lock)
  File "/p/software/juwelsbooster/stages/2023/software/xarray/2022.9.0-gcccoremkl-11.3.0-2022.1.0/lib/python3.10/site-packages/xarray/backends/file_manager.py", line 207, in _acquire_with_cache_info
    file = self._opener(*self._args, **kwargs)
  File "src/netCDF4/_netCDF4.pyx", line 2463, in netCDF4._netCDF4.Dataset.__init__
  File "src/netCDF4/_netCDF4.pyx", line 2026, in netCDF4._netCDF4._ensure_nc_success
FileNotFoundError: [Errno 2] No such file or directory: b'/p/scratch/cesmtst/patakchiyousefi1/FORECASTLEAD_CESMTST_SCRATCH/PREDICT_FILES/ADAPTER_DE05.day05.merged.nc.corrected.nc'
srun: error: jwb0803: task 0: Exited with exit code 1
