rm: cannot remove '/p/oldscratch/cesmtst/patakchiyousefi1/FORECASTLEAD_CESMTST_SCRATCH/STATS/ADAPTER_DE05.day02_HRES_C_stats.nc': Read-only file system
rm: cannot remove '/p/oldscratch/cesmtst/patakchiyousefi1/FORECASTLEAD_CESMTST_SCRATCH/STATS/ADAPTER_DE05.day02_HRES_stats.nc': Read-only file system
rm: cannot remove '/p/oldscratch/cesmtst/patakchiyousefi1/FORECASTLEAD_CESMTST_SCRATCH/STATS/ADAPTER_DE05.day03_HRES_C_stats.nc': Read-only file system
rm: cannot remove '/p/oldscratch/cesmtst/patakchiyousefi1/FORECASTLEAD_CESMTST_SCRATCH/STATS/ADAPTER_DE05.day03_HRES_stats.nc': Read-only file system
rm: cannot remove '/p/oldscratch/cesmtst/patakchiyousefi1/FORECASTLEAD_CESMTST_SCRATCH/STATS/ADAPTER_DE05.day04_HRES_C_stats.nc': Read-only file system
rm: cannot remove '/p/oldscratch/cesmtst/patakchiyousefi1/FORECASTLEAD_CESMTST_SCRATCH/STATS/ADAPTER_DE05.day04_HRES_stats.nc': Read-only file system
rm: cannot remove '/p/oldscratch/cesmtst/patakchiyousefi1/FORECASTLEAD_CESMTST_SCRATCH/STATS/ADAPTER_DE05.day05_HRES_C_stats.nc': Read-only file system
rm: cannot remove '/p/oldscratch/cesmtst/patakchiyousefi1/FORECASTLEAD_CESMTST_SCRATCH/STATS/ADAPTER_DE05.day05_HRES_stats.nc': Read-only file system
rm: cannot remove '/p/oldscratch/cesmtst/patakchiyousefi1/FORECASTLEAD_CESMTST_SCRATCH/STATS/ADAPTER_DE05.day06_HRES_C_stats.nc': Read-only file system
rm: cannot remove '/p/oldscratch/cesmtst/patakchiyousefi1/FORECASTLEAD_CESMTST_SCRATCH/STATS/ADAPTER_DE05.day06_HRES_stats.nc': Read-only file system
rm: cannot remove '/p/oldscratch/cesmtst/patakchiyousefi1/FORECASTLEAD_CESMTST_SCRATCH/STATS/ADAPTER_DE05.day07_HRES_C_stats.nc': Read-only file system
rm: cannot remove '/p/oldscratch/cesmtst/patakchiyousefi1/FORECASTLEAD_CESMTST_SCRATCH/STATS/ADAPTER_DE05.day07_HRES_stats.nc': Read-only file system
rm: cannot remove '/p/oldscratch/cesmtst/patakchiyousefi1/FORECASTLEAD_CESMTST_SCRATCH/STATS/ADAPTER_DE05.day08_HRES_C_stats.nc': Read-only file system
rm: cannot remove '/p/oldscratch/cesmtst/patakchiyousefi1/FORECASTLEAD_CESMTST_SCRATCH/STATS/ADAPTER_DE05.day08_HRES_stats.nc': Read-only file system
rm: cannot remove '/p/oldscratch/cesmtst/patakchiyousefi1/FORECASTLEAD_CESMTST_SCRATCH/STATS/ADAPTER_DE05.day09_HRES_C_stats.nc': Read-only file system
rm: cannot remove '/p/oldscratch/cesmtst/patakchiyousefi1/FORECASTLEAD_CESMTST_SCRATCH/STATS/ADAPTER_DE05.day09_HRES_stats.nc': Read-only file system
rm: cannot remove '/p/oldscratch/cesmtst/patakchiyousefi1/FORECASTLEAD_CESMTST_SCRATCH/STATS/ADAPTER_DE05.day10_HRES_C_stats.nc': Read-only file system
rm: cannot remove '/p/oldscratch/cesmtst/patakchiyousefi1/FORECASTLEAD_CESMTST_SCRATCH/STATS/ADAPTER_DE05.day10_HRES_stats.nc': Read-only file system
Traceback (most recent call last):
  File "/p/software/juwelsbooster/stages/2023/software/xarray/2022.9.0-gcccoremkl-11.3.0-2022.1.0/lib/python3.10/site-packages/xarray/backends/file_manager.py", line 201, in _acquire_with_cache_info
    file = self._cache[self._key]
  File "/p/software/juwelsbooster/stages/2023/software/xarray/2022.9.0-gcccoremkl-11.3.0-2022.1.0/lib/python3.10/site-packages/xarray/backends/lru_cache.py", line 55, in __getitem__
    value = self._cache[key]
KeyError: [<class 'netCDF4._netCDF4.Dataset'>, ('/p/oldscratch/cesmtst/patakchiyousefi1/FORECASTLEAD_CESMTST_SCRATCH/STATS/ADAPTER_DE05.day03_HRES_stats.nc',), 'a', (('clobber', True), ('diskless', False), ('format', 'NETCDF4'), ('persist', False))]

During handling of the above exception, another exception occurred:

Traceback (most recent call last):
  File "/p/project1/cesmtst/patakchiyousefi1/CODES-MS3/FORECASTLEAD/STATS.py", line 43, in <module>
    xr.Dataset(MOD_METRICS).to_netcdf(MOD_OUT)
  File "/p/software/juwelsbooster/stages/2023/software/xarray/2022.9.0-gcccoremkl-11.3.0-2022.1.0/lib/python3.10/site-packages/xarray/core/dataset.py", line 1890, in to_netcdf
    return to_netcdf(  # type: ignore  # mypy cannot resolve the overloads:(
  File "/p/software/juwelsbooster/stages/2023/software/xarray/2022.9.0-gcccoremkl-11.3.0-2022.1.0/lib/python3.10/site-packages/xarray/backends/api.py", line 1209, in to_netcdf
    store = store_open(target, mode, format, group, **kwargs)
  File "/p/software/juwelsbooster/stages/2023/software/xarray/2022.9.0-gcccoremkl-11.3.0-2022.1.0/lib/python3.10/site-packages/xarray/backends/netCDF4_.py", line 384, in open
    return cls(manager, group=group, mode=mode, lock=lock, autoclose=autoclose)
  File "/p/software/juwelsbooster/stages/2023/software/xarray/2022.9.0-gcccoremkl-11.3.0-2022.1.0/lib/python3.10/site-packages/xarray/backends/netCDF4_.py", line 332, in __init__
    self.format = self.ds.data_model
  File "/p/software/juwelsbooster/stages/2023/software/xarray/2022.9.0-gcccoremkl-11.3.0-2022.1.0/lib/python3.10/site-packages/xarray/backends/netCDF4_.py", line 393, in ds
    return self._acquire()
  File "/p/software/juwelsbooster/stages/2023/software/xarray/2022.9.0-gcccoremkl-11.3.0-2022.1.0/lib/python3.10/site-packages/xarray/backends/netCDF4_.py", line 387, in _acquire
    with self._manager.acquire_context(needs_lock) as root:
  File "/p/software/juwelsbooster/stages/2023/software/Python/3.10.4-GCCcore-11.3.0/lib/python3.10/contextlib.py", line 135, in __enter__
    return next(self.gen)
  File "/p/software/juwelsbooster/stages/2023/software/xarray/2022.9.0-gcccoremkl-11.3.0-2022.1.0/lib/python3.10/site-packages/xarray/backends/file_manager.py", line 189, in acquire_context
    file, cached = self._acquire_with_cache_info(needs_lock)
  File "/p/software/juwelsbooster/stages/2023/software/xarray/2022.9.0-gcccoremkl-11.3.0-2022.1.0/lib/python3.10/site-packages/xarray/backends/file_manager.py", line 207, in _acquire_with_cache_info
    file = self._opener(*self._args, **kwargs)
  File "src/netCDF4/_netCDF4.pyx", line 2463, in netCDF4._netCDF4.Dataset.__init__
  File "src/netCDF4/_netCDF4.pyx", line 2026, in netCDF4._netCDF4._ensure_nc_success
PermissionError: [Errno 13] Permission denied: b'/p/oldscratch/cesmtst/patakchiyousefi1/FORECASTLEAD_CESMTST_SCRATCH/STATS/ADAPTER_DE05.day03_HRES_stats.nc'
Traceback (most recent call last):
  File "/p/software/juwelsbooster/stages/2023/software/xarray/2022.9.0-gcccoremkl-11.3.0-2022.1.0/lib/python3.10/site-packages/xarray/backends/file_manager.py", line 201, in _acquire_with_cache_info
    file = self._cache[self._key]
  File "/p/software/juwelsbooster/stages/2023/software/xarray/2022.9.0-gcccoremkl-11.3.0-2022.1.0/lib/python3.10/site-packages/xarray/backends/lru_cache.py", line 55, in __getitem__
    value = self._cache[key]
KeyError: [<class 'netCDF4._netCDF4.Dataset'>, ('/p/oldscratch/cesmtst/patakchiyousefi1/FORECASTLEAD_CESMTST_SCRATCH/STATS/ADAPTER_DE05.day02_HRES_stats.nc',), 'a', (('clobber', True), ('diskless', False), ('format', 'NETCDF4'), ('persist', False))]

During handling of the above exception, another exception occurred:

Traceback (most recent call last):
  File "/p/project1/cesmtst/patakchiyousefi1/CODES-MS3/FORECASTLEAD/STATS.py", line 43, in <module>
    xr.Dataset(MOD_METRICS).to_netcdf(MOD_OUT)
  File "/p/software/juwelsbooster/stages/2023/software/xarray/2022.9.0-gcccoremkl-11.3.0-2022.1.0/lib/python3.10/site-packages/xarray/core/dataset.py", line 1890, in to_netcdf
    return to_netcdf(  # type: ignore  # mypy cannot resolve the overloads:(
  File "/p/software/juwelsbooster/stages/2023/software/xarray/2022.9.0-gcccoremkl-11.3.0-2022.1.0/lib/python3.10/site-packages/xarray/backends/api.py", line 1209, in to_netcdf
    store = store_open(target, mode, format, group, **kwargs)
  File "/p/software/juwelsbooster/stages/2023/software/xarray/2022.9.0-gcccoremkl-11.3.0-2022.1.0/lib/python3.10/site-packages/xarray/backends/netCDF4_.py", line 384, in open
    return cls(manager, group=group, mode=mode, lock=lock, autoclose=autoclose)
  File "/p/software/juwelsbooster/stages/2023/software/xarray/2022.9.0-gcccoremkl-11.3.0-2022.1.0/lib/python3.10/site-packages/xarray/backends/netCDF4_.py", line 332, in __init__
    self.format = self.ds.data_model
  File "/p/software/juwelsbooster/stages/2023/software/xarray/2022.9.0-gcccoremkl-11.3.0-2022.1.0/lib/python3.10/site-packages/xarray/backends/netCDF4_.py", line 393, in ds
    return self._acquire()
  File "/p/software/juwelsbooster/stages/2023/software/xarray/2022.9.0-gcccoremkl-11.3.0-2022.1.0/lib/python3.10/site-packages/xarray/backends/netCDF4_.py", line 387, in _acquire
    with self._manager.acquire_context(needs_lock) as root:
  File "/p/software/juwelsbooster/stages/2023/software/Python/3.10.4-GCCcore-11.3.0/lib/python3.10/contextlib.py", line 135, in __enter__
    return next(self.gen)
  File "/p/software/juwelsbooster/stages/2023/software/xarray/2022.9.0-gcccoremkl-11.3.0-2022.1.0/lib/python3.10/site-packages/xarray/backends/file_manager.py", line 189, in acquire_context
    file, cached = self._acquire_with_cache_info(needs_lock)
  File "/p/software/juwelsbooster/stages/2023/software/xarray/2022.9.0-gcccoremkl-11.3.0-2022.1.0/lib/python3.10/site-packages/xarray/backends/file_manager.py", line 207, in _acquire_with_cache_info
    file = self._opener(*self._args, **kwargs)
  File "src/netCDF4/_netCDF4.pyx", line 2463, in netCDF4._netCDF4.Dataset.__init__
  File "src/netCDF4/_netCDF4.pyx", line 2026, in netCDF4._netCDF4._ensure_nc_success
PermissionError: [Errno 13] Permission denied: b'/p/oldscratch/cesmtst/patakchiyousefi1/FORECASTLEAD_CESMTST_SCRATCH/STATS/ADAPTER_DE05.day02_HRES_stats.nc'
srun: error: jwb0004: task 0: Exited with exit code 1
srun: error: jwb0002: task 0: Exited with exit code 1
Traceback (most recent call last):
  File "/p/software/juwelsbooster/stages/2023/software/xarray/2022.9.0-gcccoremkl-11.3.0-2022.1.0/lib/python3.10/site-packages/xarray/backends/file_manager.py", line 201, in _acquire_with_cache_info
    file = self._cache[self._key]
  File "/p/software/juwelsbooster/stages/2023/software/xarray/2022.9.0-gcccoremkl-11.3.0-2022.1.0/lib/python3.10/site-packages/xarray/backends/lru_cache.py", line 55, in __getitem__
    value = self._cache[key]
KeyError: [<class 'netCDF4._netCDF4.Dataset'>, ('/p/oldscratch/cesmtst/patakchiyousefi1/FORECASTLEAD_CESMTST_SCRATCH/STATS/ADAPTER_DE05.day04_HRES_stats.nc',), 'a', (('clobber', True), ('diskless', False), ('format', 'NETCDF4'), ('persist', False))]

During handling of the above exception, another exception occurred:

Traceback (most recent call last):
  File "/p/project1/cesmtst/patakchiyousefi1/CODES-MS3/FORECASTLEAD/STATS.py", line 43, in <module>
    xr.Dataset(MOD_METRICS).to_netcdf(MOD_OUT)
  File "/p/software/juwelsbooster/stages/2023/software/xarray/2022.9.0-gcccoremkl-11.3.0-2022.1.0/lib/python3.10/site-packages/xarray/core/dataset.py", line 1890, in to_netcdf
    return to_netcdf(  # type: ignore  # mypy cannot resolve the overloads:(
  File "/p/software/juwelsbooster/stages/2023/software/xarray/2022.9.0-gcccoremkl-11.3.0-2022.1.0/lib/python3.10/site-packages/xarray/backends/api.py", line 1209, in to_netcdf
    store = store_open(target, mode, format, group, **kwargs)
  File "/p/software/juwelsbooster/stages/2023/software/xarray/2022.9.0-gcccoremkl-11.3.0-2022.1.0/lib/python3.10/site-packages/xarray/backends/netCDF4_.py", line 384, in open
    return cls(manager, group=group, mode=mode, lock=lock, autoclose=autoclose)
  File "/p/software/juwelsbooster/stages/2023/software/xarray/2022.9.0-gcccoremkl-11.3.0-2022.1.0/lib/python3.10/site-packages/xarray/backends/netCDF4_.py", line 332, in __init__
    self.format = self.ds.data_model
  File "/p/software/juwelsbooster/stages/2023/software/xarray/2022.9.0-gcccoremkl-11.3.0-2022.1.0/lib/python3.10/site-packages/xarray/backends/netCDF4_.py", line 393, in ds
    return self._acquire()
  File "/p/software/juwelsbooster/stages/2023/software/xarray/2022.9.0-gcccoremkl-11.3.0-2022.1.0/lib/python3.10/site-packages/xarray/backends/netCDF4_.py", line 387, in _acquire
    with self._manager.acquire_context(needs_lock) as root:
  File "/p/software/juwelsbooster/stages/2023/software/Python/3.10.4-GCCcore-11.3.0/lib/python3.10/contextlib.py", line 135, in __enter__
    return next(self.gen)
  File "/p/software/juwelsbooster/stages/2023/software/xarray/2022.9.0-gcccoremkl-11.3.0-2022.1.0/lib/python3.10/site-packages/xarray/backends/file_manager.py", line 189, in acquire_context
    file, cached = self._acquire_with_cache_info(needs_lock)
  File "/p/software/juwelsbooster/stages/2023/software/xarray/2022.9.0-gcccoremkl-11.3.0-2022.1.0/lib/python3.10/site-packages/xarray/backends/file_manager.py", line 207, in _acquire_with_cache_info
    file = self._opener(*self._args, **kwargs)
  File "src/netCDF4/_netCDF4.pyx", line 2463, in netCDF4._netCDF4.Dataset.__init__
  File "src/netCDF4/_netCDF4.pyx", line 2026, in netCDF4._netCDF4._ensure_nc_success
PermissionError: [Errno 13] Permission denied: b'/p/oldscratch/cesmtst/patakchiyousefi1/FORECASTLEAD_CESMTST_SCRATCH/STATS/ADAPTER_DE05.day04_HRES_stats.nc'
srun: error: jwb0005: task 0: Exited with exit code 1
Traceback (most recent call last):
  File "/p/software/juwelsbooster/stages/2023/software/xarray/2022.9.0-gcccoremkl-11.3.0-2022.1.0/lib/python3.10/site-packages/xarray/backends/file_manager.py", line 201, in _acquire_with_cache_info
    file = self._cache[self._key]
  File "/p/software/juwelsbooster/stages/2023/software/xarray/2022.9.0-gcccoremkl-11.3.0-2022.1.0/lib/python3.10/site-packages/xarray/backends/lru_cache.py", line 55, in __getitem__
    value = self._cache[key]
KeyError: [<class 'netCDF4._netCDF4.Dataset'>, ('/p/oldscratch/cesmtst/patakchiyousefi1/FORECASTLEAD_CESMTST_SCRATCH/STATS/ADAPTER_DE05.day07_HRES_stats.nc',), 'a', (('clobber', True), ('diskless', False), ('format', 'NETCDF4'), ('persist', False))]

During handling of the above exception, another exception occurred:

Traceback (most recent call last):
  File "/p/project1/cesmtst/patakchiyousefi1/CODES-MS3/FORECASTLEAD/STATS.py", line 43, in <module>
    xr.Dataset(MOD_METRICS).to_netcdf(MOD_OUT)
  File "/p/software/juwelsbooster/stages/2023/software/xarray/2022.9.0-gcccoremkl-11.3.0-2022.1.0/lib/python3.10/site-packages/xarray/core/dataset.py", line 1890, in to_netcdf
    return to_netcdf(  # type: ignore  # mypy cannot resolve the overloads:(
  File "/p/software/juwelsbooster/stages/2023/software/xarray/2022.9.0-gcccoremkl-11.3.0-2022.1.0/lib/python3.10/site-packages/xarray/backends/api.py", line 1209, in to_netcdf
    store = store_open(target, mode, format, group, **kwargs)
  File "/p/software/juwelsbooster/stages/2023/software/xarray/2022.9.0-gcccoremkl-11.3.0-2022.1.0/lib/python3.10/site-packages/xarray/backends/netCDF4_.py", line 384, in open
    return cls(manager, group=group, mode=mode, lock=lock, autoclose=autoclose)
  File "/p/software/juwelsbooster/stages/2023/software/xarray/2022.9.0-gcccoremkl-11.3.0-2022.1.0/lib/python3.10/site-packages/xarray/backends/netCDF4_.py", line 332, in __init__
    self.format = self.ds.data_model
  File "/p/software/juwelsbooster/stages/2023/software/xarray/2022.9.0-gcccoremkl-11.3.0-2022.1.0/lib/python3.10/site-packages/xarray/backends/netCDF4_.py", line 393, in ds
    return self._acquire()
  File "/p/software/juwelsbooster/stages/2023/software/xarray/2022.9.0-gcccoremkl-11.3.0-2022.1.0/lib/python3.10/site-packages/xarray/backends/netCDF4_.py", line 387, in _acquire
    with self._manager.acquire_context(needs_lock) as root:
  File "/p/software/juwelsbooster/stages/2023/software/Python/3.10.4-GCCcore-11.3.0/lib/python3.10/contextlib.py", line 135, in __enter__
    return next(self.gen)
  File "/p/software/juwelsbooster/stages/2023/software/xarray/2022.9.0-gcccoremkl-11.3.0-2022.1.0/lib/python3.10/site-packages/xarray/backends/file_manager.py", line 189, in acquire_context
    file, cached = self._acquire_with_cache_info(needs_lock)
  File "/p/software/juwelsbooster/stages/2023/software/xarray/2022.9.0-gcccoremkl-11.3.0-2022.1.0/lib/python3.10/site-packages/xarray/backends/file_manager.py", line 207, in _acquire_with_cache_info
    file = self._opener(*self._args, **kwargs)
  File "src/netCDF4/_netCDF4.pyx", line 2463, in netCDF4._netCDF4.Dataset.__init__
  File "src/netCDF4/_netCDF4.pyx", line 2026, in netCDF4._netCDF4._ensure_nc_success
PermissionError: [Errno 13] Permission denied: b'/p/oldscratch/cesmtst/patakchiyousefi1/FORECASTLEAD_CESMTST_SCRATCH/STATS/ADAPTER_DE05.day07_HRES_stats.nc'
srun: error: jwb0022: task 0: Exited with exit code 1
Traceback (most recent call last):
  File "/p/software/juwelsbooster/stages/2023/software/xarray/2022.9.0-gcccoremkl-11.3.0-2022.1.0/lib/python3.10/site-packages/xarray/backends/file_manager.py", line 201, in _acquire_with_cache_info
    file = self._cache[self._key]
  File "/p/software/juwelsbooster/stages/2023/software/xarray/2022.9.0-gcccoremkl-11.3.0-2022.1.0/lib/python3.10/site-packages/xarray/backends/lru_cache.py", line 55, in __getitem__
    value = self._cache[key]
KeyError: [<class 'netCDF4._netCDF4.Dataset'>, ('/p/oldscratch/cesmtst/patakchiyousefi1/FORECASTLEAD_CESMTST_SCRATCH/STATS/ADAPTER_DE05.day08_HRES_stats.nc',), 'a', (('clobber', True), ('diskless', False), ('format', 'NETCDF4'), ('persist', False))]

During handling of the above exception, another exception occurred:

Traceback (most recent call last):
  File "/p/project1/cesmtst/patakchiyousefi1/CODES-MS3/FORECASTLEAD/STATS.py", line 43, in <module>
    xr.Dataset(MOD_METRICS).to_netcdf(MOD_OUT)
  File "/p/software/juwelsbooster/stages/2023/software/xarray/2022.9.0-gcccoremkl-11.3.0-2022.1.0/lib/python3.10/site-packages/xarray/core/dataset.py", line 1890, in to_netcdf
    return to_netcdf(  # type: ignore  # mypy cannot resolve the overloads:(
  File "/p/software/juwelsbooster/stages/2023/software/xarray/2022.9.0-gcccoremkl-11.3.0-2022.1.0/lib/python3.10/site-packages/xarray/backends/api.py", line 1209, in to_netcdf
    store = store_open(target, mode, format, group, **kwargs)
  File "/p/software/juwelsbooster/stages/2023/software/xarray/2022.9.0-gcccoremkl-11.3.0-2022.1.0/lib/python3.10/site-packages/xarray/backends/netCDF4_.py", line 384, in open
    return cls(manager, group=group, mode=mode, lock=lock, autoclose=autoclose)
  File "/p/software/juwelsbooster/stages/2023/software/xarray/2022.9.0-gcccoremkl-11.3.0-2022.1.0/lib/python3.10/site-packages/xarray/backends/netCDF4_.py", line 332, in __init__
    self.format = self.ds.data_model
  File "/p/software/juwelsbooster/stages/2023/software/xarray/2022.9.0-gcccoremkl-11.3.0-2022.1.0/lib/python3.10/site-packages/xarray/backends/netCDF4_.py", line 393, in ds
    return self._acquire()
  File "/p/software/juwelsbooster/stages/2023/software/xarray/2022.9.0-gcccoremkl-11.3.0-2022.1.0/lib/python3.10/site-packages/xarray/backends/netCDF4_.py", line 387, in _acquire
    with self._manager.acquire_context(needs_lock) as root:
  File "/p/software/juwelsbooster/stages/2023/software/Python/3.10.4-GCCcore-11.3.0/lib/python3.10/contextlib.py", line 135, in __enter__
    return next(self.gen)
  File "/p/software/juwelsbooster/stages/2023/software/xarray/2022.9.0-gcccoremkl-11.3.0-2022.1.0/lib/python3.10/site-packages/xarray/backends/file_manager.py", line 189, in acquire_context
    file, cached = self._acquire_with_cache_info(needs_lock)
  File "/p/software/juwelsbooster/stages/2023/software/xarray/2022.9.0-gcccoremkl-11.3.0-2022.1.0/lib/python3.10/site-packages/xarray/backends/file_manager.py", line 207, in _acquire_with_cache_info
    file = self._opener(*self._args, **kwargs)
  File "src/netCDF4/_netCDF4.pyx", line 2463, in netCDF4._netCDF4.Dataset.__init__
  File "src/netCDF4/_netCDF4.pyx", line 2026, in netCDF4._netCDF4._ensure_nc_success
PermissionError: [Errno 13] Permission denied: b'/p/oldscratch/cesmtst/patakchiyousefi1/FORECASTLEAD_CESMTST_SCRATCH/STATS/ADAPTER_DE05.day08_HRES_stats.nc'
srun: error: jwb0023: task 0: Exited with exit code 1
Traceback (most recent call last):
  File "/p/software/juwelsbooster/stages/2023/software/xarray/2022.9.0-gcccoremkl-11.3.0-2022.1.0/lib/python3.10/site-packages/xarray/backends/file_manager.py", line 201, in _acquire_with_cache_info
    file = self._cache[self._key]
  File "/p/software/juwelsbooster/stages/2023/software/xarray/2022.9.0-gcccoremkl-11.3.0-2022.1.0/lib/python3.10/site-packages/xarray/backends/lru_cache.py", line 55, in __getitem__
    value = self._cache[key]
KeyError: [<class 'netCDF4._netCDF4.Dataset'>, ('/p/oldscratch/cesmtst/patakchiyousefi1/FORECASTLEAD_CESMTST_SCRATCH/STATS/ADAPTER_DE05.day09_HRES_stats.nc',), 'a', (('clobber', True), ('diskless', False), ('format', 'NETCDF4'), ('persist', False))]

During handling of the above exception, another exception occurred:

Traceback (most recent call last):
  File "/p/project1/cesmtst/patakchiyousefi1/CODES-MS3/FORECASTLEAD/STATS.py", line 43, in <module>
    xr.Dataset(MOD_METRICS).to_netcdf(MOD_OUT)
  File "/p/software/juwelsbooster/stages/2023/software/xarray/2022.9.0-gcccoremkl-11.3.0-2022.1.0/lib/python3.10/site-packages/xarray/core/dataset.py", line 1890, in to_netcdf
    return to_netcdf(  # type: ignore  # mypy cannot resolve the overloads:(
  File "/p/software/juwelsbooster/stages/2023/software/xarray/2022.9.0-gcccoremkl-11.3.0-2022.1.0/lib/python3.10/site-packages/xarray/backends/api.py", line 1209, in to_netcdf
    store = store_open(target, mode, format, group, **kwargs)
  File "/p/software/juwelsbooster/stages/2023/software/xarray/2022.9.0-gcccoremkl-11.3.0-2022.1.0/lib/python3.10/site-packages/xarray/backends/netCDF4_.py", line 384, in open
    return cls(manager, group=group, mode=mode, lock=lock, autoclose=autoclose)
  File "/p/software/juwelsbooster/stages/2023/software/xarray/2022.9.0-gcccoremkl-11.3.0-2022.1.0/lib/python3.10/site-packages/xarray/backends/netCDF4_.py", line 332, in __init__
    self.format = self.ds.data_model
  File "/p/software/juwelsbooster/stages/2023/software/xarray/2022.9.0-gcccoremkl-11.3.0-2022.1.0/lib/python3.10/site-packages/xarray/backends/netCDF4_.py", line 393, in ds
    return self._acquire()
  File "/p/software/juwelsbooster/stages/2023/software/xarray/2022.9.0-gcccoremkl-11.3.0-2022.1.0/lib/python3.10/site-packages/xarray/backends/netCDF4_.py", line 387, in _acquire
    with self._manager.acquire_context(needs_lock) as root:
  File "/p/software/juwelsbooster/stages/2023/software/Python/3.10.4-GCCcore-11.3.0/lib/python3.10/contextlib.py", line 135, in __enter__
    return next(self.gen)
  File "/p/software/juwelsbooster/stages/2023/software/xarray/2022.9.0-gcccoremkl-11.3.0-2022.1.0/lib/python3.10/site-packages/xarray/backends/file_manager.py", line 189, in acquire_context
    file, cached = self._acquire_with_cache_info(needs_lock)
  File "/p/software/juwelsbooster/stages/2023/software/xarray/2022.9.0-gcccoremkl-11.3.0-2022.1.0/lib/python3.10/site-packages/xarray/backends/file_manager.py", line 207, in _acquire_with_cache_info
    file = self._opener(*self._args, **kwargs)
  File "src/netCDF4/_netCDF4.pyx", line 2463, in netCDF4._netCDF4.Dataset.__init__
  File "src/netCDF4/_netCDF4.pyx", line 2026, in netCDF4._netCDF4._ensure_nc_success
PermissionError: [Errno 13] Permission denied: b'/p/oldscratch/cesmtst/patakchiyousefi1/FORECASTLEAD_CESMTST_SCRATCH/STATS/ADAPTER_DE05.day09_HRES_stats.nc'
srun: error: jwb0025: task 0: Exited with exit code 1
Traceback (most recent call last):
  File "/p/software/juwelsbooster/stages/2023/software/xarray/2022.9.0-gcccoremkl-11.3.0-2022.1.0/lib/python3.10/site-packages/xarray/backends/file_manager.py", line 201, in _acquire_with_cache_info
    file = self._cache[self._key]
  File "/p/software/juwelsbooster/stages/2023/software/xarray/2022.9.0-gcccoremkl-11.3.0-2022.1.0/lib/python3.10/site-packages/xarray/backends/lru_cache.py", line 55, in __getitem__
    value = self._cache[key]
KeyError: [<class 'netCDF4._netCDF4.Dataset'>, ('/p/oldscratch/cesmtst/patakchiyousefi1/FORECASTLEAD_CESMTST_SCRATCH/STATS/ADAPTER_DE05.day10_HRES_stats.nc',), 'a', (('clobber', True), ('diskless', False), ('format', 'NETCDF4'), ('persist', False))]

During handling of the above exception, another exception occurred:

Traceback (most recent call last):
  File "/p/project1/cesmtst/patakchiyousefi1/CODES-MS3/FORECASTLEAD/STATS.py", line 43, in <module>
    xr.Dataset(MOD_METRICS).to_netcdf(MOD_OUT)
  File "/p/software/juwelsbooster/stages/2023/software/xarray/2022.9.0-gcccoremkl-11.3.0-2022.1.0/lib/python3.10/site-packages/xarray/core/dataset.py", line 1890, in to_netcdf
    return to_netcdf(  # type: ignore  # mypy cannot resolve the overloads:(
  File "/p/software/juwelsbooster/stages/2023/software/xarray/2022.9.0-gcccoremkl-11.3.0-2022.1.0/lib/python3.10/site-packages/xarray/backends/api.py", line 1209, in to_netcdf
    store = store_open(target, mode, format, group, **kwargs)
  File "/p/software/juwelsbooster/stages/2023/software/xarray/2022.9.0-gcccoremkl-11.3.0-2022.1.0/lib/python3.10/site-packages/xarray/backends/netCDF4_.py", line 384, in open
    return cls(manager, group=group, mode=mode, lock=lock, autoclose=autoclose)
  File "/p/software/juwelsbooster/stages/2023/software/xarray/2022.9.0-gcccoremkl-11.3.0-2022.1.0/lib/python3.10/site-packages/xarray/backends/netCDF4_.py", line 332, in __init__
    self.format = self.ds.data_model
  File "/p/software/juwelsbooster/stages/2023/software/xarray/2022.9.0-gcccoremkl-11.3.0-2022.1.0/lib/python3.10/site-packages/xarray/backends/netCDF4_.py", line 393, in ds
    return self._acquire()
  File "/p/software/juwelsbooster/stages/2023/software/xarray/2022.9.0-gcccoremkl-11.3.0-2022.1.0/lib/python3.10/site-packages/xarray/backends/netCDF4_.py", line 387, in _acquire
    with self._manager.acquire_context(needs_lock) as root:
  File "/p/software/juwelsbooster/stages/2023/software/Python/3.10.4-GCCcore-11.3.0/lib/python3.10/contextlib.py", line 135, in __enter__
    return next(self.gen)
  File "/p/software/juwelsbooster/stages/2023/software/xarray/2022.9.0-gcccoremkl-11.3.0-2022.1.0/lib/python3.10/site-packages/xarray/backends/file_manager.py", line 189, in acquire_context
    file, cached = self._acquire_with_cache_info(needs_lock)
  File "/p/software/juwelsbooster/stages/2023/software/xarray/2022.9.0-gcccoremkl-11.3.0-2022.1.0/lib/python3.10/site-packages/xarray/backends/file_manager.py", line 207, in _acquire_with_cache_info
    file = self._opener(*self._args, **kwargs)
  File "src/netCDF4/_netCDF4.pyx", line 2463, in netCDF4._netCDF4.Dataset.__init__
  File "src/netCDF4/_netCDF4.pyx", line 2026, in netCDF4._netCDF4._ensure_nc_success
PermissionError: [Errno 13] Permission denied: b'/p/oldscratch/cesmtst/patakchiyousefi1/FORECASTLEAD_CESMTST_SCRATCH/STATS/ADAPTER_DE05.day10_HRES_stats.nc'
srun: error: jwb0027: task 0: Exited with exit code 1
Traceback (most recent call last):
  File "/p/software/juwelsbooster/stages/2023/software/xarray/2022.9.0-gcccoremkl-11.3.0-2022.1.0/lib/python3.10/site-packages/xarray/backends/file_manager.py", line 201, in _acquire_with_cache_info
    file = self._cache[self._key]
  File "/p/software/juwelsbooster/stages/2023/software/xarray/2022.9.0-gcccoremkl-11.3.0-2022.1.0/lib/python3.10/site-packages/xarray/backends/lru_cache.py", line 55, in __getitem__
    value = self._cache[key]
KeyError: [<class 'netCDF4._netCDF4.Dataset'>, ('/p/oldscratch/cesmtst/patakchiyousefi1/FORECASTLEAD_CESMTST_SCRATCH/STATS/ADAPTER_DE05.day05_HRES_stats.nc',), 'a', (('clobber', True), ('diskless', False), ('format', 'NETCDF4'), ('persist', False))]

During handling of the above exception, another exception occurred:

Traceback (most recent call last):
  File "/p/project1/cesmtst/patakchiyousefi1/CODES-MS3/FORECASTLEAD/STATS.py", line 43, in <module>
    xr.Dataset(MOD_METRICS).to_netcdf(MOD_OUT)
  File "/p/software/juwelsbooster/stages/2023/software/xarray/2022.9.0-gcccoremkl-11.3.0-2022.1.0/lib/python3.10/site-packages/xarray/core/dataset.py", line 1890, in to_netcdf
    return to_netcdf(  # type: ignore  # mypy cannot resolve the overloads:(
  File "/p/software/juwelsbooster/stages/2023/software/xarray/2022.9.0-gcccoremkl-11.3.0-2022.1.0/lib/python3.10/site-packages/xarray/backends/api.py", line 1209, in to_netcdf
    store = store_open(target, mode, format, group, **kwargs)
  File "/p/software/juwelsbooster/stages/2023/software/xarray/2022.9.0-gcccoremkl-11.3.0-2022.1.0/lib/python3.10/site-packages/xarray/backends/netCDF4_.py", line 384, in open
    return cls(manager, group=group, mode=mode, lock=lock, autoclose=autoclose)
  File "/p/software/juwelsbooster/stages/2023/software/xarray/2022.9.0-gcccoremkl-11.3.0-2022.1.0/lib/python3.10/site-packages/xarray/backends/netCDF4_.py", line 332, in __init__
    self.format = self.ds.data_model
  File "/p/software/juwelsbooster/stages/2023/software/xarray/2022.9.0-gcccoremkl-11.3.0-2022.1.0/lib/python3.10/site-packages/xarray/backends/netCDF4_.py", line 393, in ds
    return self._acquire()
  File "/p/software/juwelsbooster/stages/2023/software/xarray/2022.9.0-gcccoremkl-11.3.0-2022.1.0/lib/python3.10/site-packages/xarray/backends/netCDF4_.py", line 387, in _acquire
    with self._manager.acquire_context(needs_lock) as root:
  File "/p/software/juwelsbooster/stages/2023/software/Python/3.10.4-GCCcore-11.3.0/lib/python3.10/contextlib.py", line 135, in __enter__
    return next(self.gen)
  File "/p/software/juwelsbooster/stages/2023/software/xarray/2022.9.0-gcccoremkl-11.3.0-2022.1.0/lib/python3.10/site-packages/xarray/backends/file_manager.py", line 189, in acquire_context
    file, cached = self._acquire_with_cache_info(needs_lock)
  File "/p/software/juwelsbooster/stages/2023/software/xarray/2022.9.0-gcccoremkl-11.3.0-2022.1.0/lib/python3.10/site-packages/xarray/backends/file_manager.py", line 207, in _acquire_with_cache_info
    file = self._opener(*self._args, **kwargs)
  File "src/netCDF4/_netCDF4.pyx", line 2463, in netCDF4._netCDF4.Dataset.__init__
  File "src/netCDF4/_netCDF4.pyx", line 2026, in netCDF4._netCDF4._ensure_nc_success
PermissionError: [Errno 13] Permission denied: b'/p/oldscratch/cesmtst/patakchiyousefi1/FORECASTLEAD_CESMTST_SCRATCH/STATS/ADAPTER_DE05.day05_HRES_stats.nc'
srun: error: jwb0008: task 0: Exited with exit code 1
Traceback (most recent call last):
  File "/p/software/juwelsbooster/stages/2023/software/xarray/2022.9.0-gcccoremkl-11.3.0-2022.1.0/lib/python3.10/site-packages/xarray/backends/file_manager.py", line 201, in _acquire_with_cache_info
    file = self._cache[self._key]
  File "/p/software/juwelsbooster/stages/2023/software/xarray/2022.9.0-gcccoremkl-11.3.0-2022.1.0/lib/python3.10/site-packages/xarray/backends/lru_cache.py", line 55, in __getitem__
    value = self._cache[key]
KeyError: [<class 'netCDF4._netCDF4.Dataset'>, ('/p/oldscratch/cesmtst/patakchiyousefi1/FORECASTLEAD_CESMTST_SCRATCH/STATS/ADAPTER_DE05.day06_HRES_stats.nc',), 'a', (('clobber', True), ('diskless', False), ('format', 'NETCDF4'), ('persist', False))]

During handling of the above exception, another exception occurred:

Traceback (most recent call last):
  File "/p/project1/cesmtst/patakchiyousefi1/CODES-MS3/FORECASTLEAD/STATS.py", line 43, in <module>
    xr.Dataset(MOD_METRICS).to_netcdf(MOD_OUT)
  File "/p/software/juwelsbooster/stages/2023/software/xarray/2022.9.0-gcccoremkl-11.3.0-2022.1.0/lib/python3.10/site-packages/xarray/core/dataset.py", line 1890, in to_netcdf
    return to_netcdf(  # type: ignore  # mypy cannot resolve the overloads:(
  File "/p/software/juwelsbooster/stages/2023/software/xarray/2022.9.0-gcccoremkl-11.3.0-2022.1.0/lib/python3.10/site-packages/xarray/backends/api.py", line 1209, in to_netcdf
    store = store_open(target, mode, format, group, **kwargs)
  File "/p/software/juwelsbooster/stages/2023/software/xarray/2022.9.0-gcccoremkl-11.3.0-2022.1.0/lib/python3.10/site-packages/xarray/backends/netCDF4_.py", line 384, in open
    return cls(manager, group=group, mode=mode, lock=lock, autoclose=autoclose)
  File "/p/software/juwelsbooster/stages/2023/software/xarray/2022.9.0-gcccoremkl-11.3.0-2022.1.0/lib/python3.10/site-packages/xarray/backends/netCDF4_.py", line 332, in __init__
    self.format = self.ds.data_model
  File "/p/software/juwelsbooster/stages/2023/software/xarray/2022.9.0-gcccoremkl-11.3.0-2022.1.0/lib/python3.10/site-packages/xarray/backends/netCDF4_.py", line 393, in ds
    return self._acquire()
  File "/p/software/juwelsbooster/stages/2023/software/xarray/2022.9.0-gcccoremkl-11.3.0-2022.1.0/lib/python3.10/site-packages/xarray/backends/netCDF4_.py", line 387, in _acquire
    with self._manager.acquire_context(needs_lock) as root:
  File "/p/software/juwelsbooster/stages/2023/software/Python/3.10.4-GCCcore-11.3.0/lib/python3.10/contextlib.py", line 135, in __enter__
    return next(self.gen)
  File "/p/software/juwelsbooster/stages/2023/software/xarray/2022.9.0-gcccoremkl-11.3.0-2022.1.0/lib/python3.10/site-packages/xarray/backends/file_manager.py", line 189, in acquire_context
    file, cached = self._acquire_with_cache_info(needs_lock)
  File "/p/software/juwelsbooster/stages/2023/software/xarray/2022.9.0-gcccoremkl-11.3.0-2022.1.0/lib/python3.10/site-packages/xarray/backends/file_manager.py", line 207, in _acquire_with_cache_info
    file = self._opener(*self._args, **kwargs)
  File "src/netCDF4/_netCDF4.pyx", line 2463, in netCDF4._netCDF4.Dataset.__init__
  File "src/netCDF4/_netCDF4.pyx", line 2026, in netCDF4._netCDF4._ensure_nc_success
PermissionError: [Errno 13] Permission denied: b'/p/oldscratch/cesmtst/patakchiyousefi1/FORECASTLEAD_CESMTST_SCRATCH/STATS/ADAPTER_DE05.day06_HRES_stats.nc'
srun: error: jwb0010: task 0: Exited with exit code 1
